2023-05-17 14:02:59,830 ERROR frappe New Exception collected with id: 2023-05-17 14:02:59.771717-127.0.0.1-895
Site: MyTrialERP1.com
Form Dict: {}
2023-05-17 14:02:59,832 ERROR frappe Failed to run after request hook
Site: MyTrialERP1.com
Form Dict: {}
Traceback (most recent call last):
  File "/home/my_tag/myfrappe-bench/apps/frappe/frappe/app.py", line 55, in application
    init_request(request)
  File "/home/my_tag/myfrappe-bench/apps/frappe/frappe/app.py", line 141, in init_request
    frappe.local.http_request = frappe.auth.HTTPRequest()
  File "/home/my_tag/myfrappe-bench/apps/frappe/frappe/auth.py", line 36, in __init__
    self.set_session()
  File "/home/my_tag/myfrappe-bench/apps/frappe/frappe/auth.py", line 70, in set_session
    frappe.local.login_manager = LoginManager()
  File "/home/my_tag/myfrappe-bench/apps/frappe/frappe/auth.py", line 126, in __init__
    self.make_session(resume=True)
  File "/home/my_tag/myfrappe-bench/apps/frappe/frappe/auth.py", line 212, in make_session
    frappe.local.session_obj = Session(
  File "/home/my_tag/myfrappe-bench/apps/frappe/frappe/sessions.py", line 215, in __init__
    self.resume()
  File "/home/my_tag/myfrappe-bench/apps/frappe/frappe/sessions.py", line 287, in resume
    validate_ip_address(self.user)
  File "/home/my_tag/myfrappe-bench/apps/frappe/frappe/auth.py", line 417, in validate_ip_address
    frappe.get_cached_doc("User", user) if not frappe.flags.in_test else frappe.get_doc("User", user)
  File "/home/my_tag/myfrappe-bench/apps/frappe/frappe/__init__.py", line 1025, in get_cached_doc
    doc = get_doc(*args, **kwargs)
  File "/home/my_tag/myfrappe-bench/apps/frappe/frappe/__init__.py", line 1079, in get_doc
    doc = frappe.model.document.get_doc(*args, **kwargs)
  File "/home/my_tag/myfrappe-bench/apps/frappe/frappe/model/document.py", line 77, in get_doc
    controller = get_controller(doctype)
  File "/home/my_tag/myfrappe-bench/apps/frappe/frappe/model/base_document.py", line 78, in get_controller
    return _get_controller()
  File "/home/my_tag/myfrappe-bench/apps/frappe/frappe/model/base_document.py", line 43, in _get_controller
    module_name, custom = frappe.db.get_value(
  File "/home/my_tag/myfrappe-bench/apps/frappe/frappe/database/database.py", line 472, in get_value
    ret = self.get_values(
  File "/home/my_tag/myfrappe-bench/apps/frappe/frappe/database/database.py", line 544, in get_values
    out = self._get_values_from_table(
  File "/home/my_tag/myfrappe-bench/apps/frappe/frappe/database/database.py", line 739, in _get_values_from_table
    r = self.sql(
  File "/home/my_tag/myfrappe-bench/apps/frappe/frappe/database/database.py", line 161, in sql
    self.connect()
  File "/home/my_tag/myfrappe-bench/apps/frappe/frappe/database/database.py", line 85, in connect
    self._conn = self.get_connection()
  File "/home/my_tag/myfrappe-bench/apps/frappe/frappe/database/mariadb/database.py", line 76, in get_connection
    conn = pymysql.connect(
  File "/home/my_tag/myfrappe-bench/env/lib/python3.8/site-packages/pymysql/connections.py", line 353, in __init__
    self.connect()
  File "/home/my_tag/myfrappe-bench/env/lib/python3.8/site-packages/pymysql/connections.py", line 633, in connect
    self._request_authentication()
  File "/home/my_tag/myfrappe-bench/env/lib/python3.8/site-packages/pymysql/connections.py", line 907, in _request_authentication
    auth_packet = self._read_packet()
  File "/home/my_tag/myfrappe-bench/env/lib/python3.8/site-packages/pymysql/connections.py", line 725, in _read_packet
    packet.raise_for_error()
  File "/home/my_tag/myfrappe-bench/env/lib/python3.8/site-packages/pymysql/protocol.py", line 221, in raise_for_error
    err.raise_mysql_exception(self._data)
  File "/home/my_tag/myfrappe-bench/env/lib/python3.8/site-packages/pymysql/err.py", line 143, in raise_mysql_exception
    raise errorclass(errno, errval)
pymysql.err.OperationalError: (1045, "Access denied for user '_04f7908592de3be4'@'localhost' (using password: YES)")

During handling of the above exception, another exception occurred:

Traceback (most recent call last):
  File "/home/my_tag/myfrappe-bench/apps/frappe/frappe/app.py", line 87, in application
    response = handle_exception(e)
  File "/home/my_tag/myfrappe-bench/apps/frappe/frappe/app.py", line 304, in handle_exception
    response = frappe.website.render.render("message", http_status_code=http_status_code)
  File "/home/my_tag/myfrappe-bench/apps/frappe/frappe/website/render.py", line 45, in render
    raise_if_disabled(path)
  File "/home/my_tag/myfrappe-bench/apps/frappe/frappe/website/render.py", line 413, in raise_if_disabled
    routes = frappe.db.get_all(
  File "/home/my_tag/myfrappe-bench/apps/frappe/frappe/database/database.py", line 646, in get_all
    return frappe.get_all(*args, **kwargs)
  File "/home/my_tag/myfrappe-bench/apps/frappe/frappe/__init__.py", line 1757, in get_all
    return get_list(doctype, *args, **kwargs)
  File "/home/my_tag/myfrappe-bench/apps/frappe/frappe/__init__.py", line 1729, in get_list
    return frappe.model.db_query.DatabaseQuery(doctype).execute(*args, **kwargs)
  File "/home/my_tag/myfrappe-bench/apps/frappe/frappe/model/db_query.py", line 167, in execute
    self.columns = self.get_table_columns()
  File "/home/my_tag/myfrappe-bench/apps/frappe/frappe/model/db_query.py", line 440, in get_table_columns
    return get_table_columns(self.doctype)
  File "/home/my_tag/myfrappe-bench/apps/frappe/frappe/model/meta.py", line 63, in get_table_columns
    return frappe.db.get_table_columns(doctype)
  File "/home/my_tag/myfrappe-bench/apps/frappe/frappe/database/database.py", line 1091, in get_table_columns
    columns = self.get_db_table_columns("tab" + doctype)
  File "/home/my_tag/myfrappe-bench/apps/frappe/frappe/database/database.py", line 1075, in get_db_table_columns
    for r in self.sql(
  File "/home/my_tag/myfrappe-bench/apps/frappe/frappe/database/database.py", line 161, in sql
    self.connect()
  File "/home/my_tag/myfrappe-bench/apps/frappe/frappe/database/database.py", line 85, in connect
    self._conn = self.get_connection()
  File "/home/my_tag/myfrappe-bench/apps/frappe/frappe/database/mariadb/database.py", line 76, in get_connection
    conn = pymysql.connect(
  File "/home/my_tag/myfrappe-bench/env/lib/python3.8/site-packages/pymysql/connections.py", line 353, in __init__
    self.connect()
  File "/home/my_tag/myfrappe-bench/env/lib/python3.8/site-packages/pymysql/connections.py", line 633, in connect
    self._request_authentication()
  File "/home/my_tag/myfrappe-bench/env/lib/python3.8/site-packages/pymysql/connections.py", line 907, in _request_authentication
    auth_packet = self._read_packet()
  File "/home/my_tag/myfrappe-bench/env/lib/python3.8/site-packages/pymysql/connections.py", line 725, in _read_packet
    packet.raise_for_error()
  File "/home/my_tag/myfrappe-bench/env/lib/python3.8/site-packages/pymysql/protocol.py", line 221, in raise_for_error
    err.raise_mysql_exception(self._data)
  File "/home/my_tag/myfrappe-bench/env/lib/python3.8/site-packages/pymysql/err.py", line 143, in raise_mysql_exception
    raise errorclass(errno, errval)
pymysql.err.OperationalError: (1045, "Access denied for user '_04f7908592de3be4'@'localhost' (using password: YES)")

During handling of the above exception, another exception occurred:

Traceback (most recent call last):
  File "/home/my_tag/myfrappe-bench/apps/frappe/frappe/app.py", line 101, in application
    run_after_request_hooks(request, response)
  File "/home/my_tag/myfrappe-bench/apps/frappe/frappe/app.py", line 117, in run_after_request_hooks
    for after_request_task in frappe.get_hooks("after_request"):
  File "/home/my_tag/myfrappe-bench/apps/frappe/frappe/__init__.py", line 1361, in get_hooks
    hooks = _dict(load_app_hooks())
  File "/home/my_tag/myfrappe-bench/apps/frappe/frappe/__init__.py", line 1337, in load_app_hooks
    for app in [app_name] if app_name else get_installed_apps(_ensure_on_bench=True):
  File "/home/my_tag/myfrappe-bench/apps/frappe/frappe/__init__.py", line 1291, in get_installed_apps
    installed = json.loads(db.get_global("installed_apps") or "[]")
  File "/home/my_tag/myfrappe-bench/apps/frappe/frappe/database/database.py", line 884, in get_global
    return self.get_default(key, user)
  File "/home/my_tag/myfrappe-bench/apps/frappe/frappe/database/database.py", line 888, in get_default
    d = self.get_defaults(key, parent)
  File "/home/my_tag/myfrappe-bench/apps/frappe/frappe/database/database.py", line 905, in get_defaults
    defaults = frappe.defaults.get_defaults(parent)
  File "/home/my_tag/myfrappe-bench/apps/frappe/frappe/defaults.py", line 89, in get_defaults
    globald = get_defaults_for()
  File "/home/my_tag/myfrappe-bench/apps/frappe/frappe/defaults.py", line 234, in get_defaults_for
    res = frappe.db.sql(
  File "/home/my_tag/myfrappe-bench/apps/frappe/frappe/database/database.py", line 161, in sql
    self.connect()
  File "/home/my_tag/myfrappe-bench/apps/frappe/frappe/database/database.py", line 85, in connect
    self._conn = self.get_connection()
  File "/home/my_tag/myfrappe-bench/apps/frappe/frappe/database/mariadb/database.py", line 76, in get_connection
    conn = pymysql.connect(
  File "/home/my_tag/myfrappe-bench/env/lib/python3.8/site-packages/pymysql/connections.py", line 353, in __init__
    self.connect()
  File "/home/my_tag/myfrappe-bench/env/lib/python3.8/site-packages/pymysql/connections.py", line 633, in connect
    self._request_authentication()
  File "/home/my_tag/myfrappe-bench/env/lib/python3.8/site-packages/pymysql/connections.py", line 907, in _request_authentication
    auth_packet = self._read_packet()
  File "/home/my_tag/myfrappe-bench/env/lib/python3.8/site-packages/pymysql/connections.py", line 725, in _read_packet
    packet.raise_for_error()
  File "/home/my_tag/myfrappe-bench/env/lib/python3.8/site-packages/pymysql/protocol.py", line 221, in raise_for_error
    err.raise_mysql_exception(self._data)
  File "/home/my_tag/myfrappe-bench/env/lib/python3.8/site-packages/pymysql/err.py", line 143, in raise_mysql_exception
    raise errorclass(errno, errval)
pymysql.err.OperationalError: (1045, "Access denied for user '_04f7908592de3be4'@'localhost' (using password: YES)")
