2023-05-22 10:29:23,503 ERROR scheduler Exception in Enqueue Events for Site MyTrialERP.com
Traceback (most recent call last):
  File "apps/frappe/frappe/utils/scheduler.py", line 70, in enqueue_events_for_site
    if is_scheduler_inactive():
  File "apps/frappe/frappe/utils/scheduler.py", line 105, in is_scheduler_inactive
    if is_scheduler_disabled():
  File "apps/frappe/frappe/utils/scheduler.py", line 115, in is_scheduler_disabled
    return not frappe.utils.cint(frappe.db.get_single_value("System Settings", "enable_scheduler"))
  File "apps/frappe/frappe/database/database.py", line 684, in get_single_value
    val = self.sql(
  File "apps/frappe/frappe/database/database.py", line 161, in sql
    self.connect()
  File "apps/frappe/frappe/database/database.py", line 85, in connect
    self._conn = self.get_connection()
  File "apps/frappe/frappe/database/mariadb/database.py", line 92, in get_connection
    conn.select_db(self.user)
  File "env/lib/python3.8/site-packages/pymysql/connections.py", line 496, in select_db
    self._read_ok_packet()
  File "env/lib/python3.8/site-packages/pymysql/connections.py", line 443, in _read_ok_packet
    pkt = self._read_packet()
  File "env/lib/python3.8/site-packages/pymysql/connections.py", line 725, in _read_packet
    packet.raise_for_error()
  File "env/lib/python3.8/site-packages/pymysql/protocol.py", line 221, in raise_for_error
    err.raise_mysql_exception(self._data)
  File "env/lib/python3.8/site-packages/pymysql/err.py", line 143, in raise_mysql_exception
    raise errorclass(errno, errval)
pymysql.err.OperationalError: (1049, "Unknown database '_c296b757cb15d301'")

2023-05-22 10:30:23,751 ERROR scheduler Exception in Enqueue Events for Site MyTrialERP.com
Traceback (most recent call last):
  File "apps/frappe/frappe/utils/scheduler.py", line 70, in enqueue_events_for_site
    if is_scheduler_inactive():
  File "apps/frappe/frappe/utils/scheduler.py", line 105, in is_scheduler_inactive
    if is_scheduler_disabled():
  File "apps/frappe/frappe/utils/scheduler.py", line 115, in is_scheduler_disabled
    return not frappe.utils.cint(frappe.db.get_single_value("System Settings", "enable_scheduler"))
  File "apps/frappe/frappe/database/database.py", line 684, in get_single_value
    val = self.sql(
  File "apps/frappe/frappe/database/database.py", line 161, in sql
    self.connect()
  File "apps/frappe/frappe/database/database.py", line 85, in connect
    self._conn = self.get_connection()
  File "apps/frappe/frappe/database/mariadb/database.py", line 92, in get_connection
    conn.select_db(self.user)
  File "env/lib/python3.8/site-packages/pymysql/connections.py", line 496, in select_db
    self._read_ok_packet()
  File "env/lib/python3.8/site-packages/pymysql/connections.py", line 443, in _read_ok_packet
    pkt = self._read_packet()
  File "env/lib/python3.8/site-packages/pymysql/connections.py", line 725, in _read_packet
    packet.raise_for_error()
  File "env/lib/python3.8/site-packages/pymysql/protocol.py", line 221, in raise_for_error
    err.raise_mysql_exception(self._data)
  File "env/lib/python3.8/site-packages/pymysql/err.py", line 143, in raise_mysql_exception
    raise errorclass(errno, errval)
pymysql.err.OperationalError: (1049, "Unknown database '_c296b757cb15d301'")

2023-05-22 10:30:23,932 INFO scheduler Scheduled Job Start: erpnext.accounts.doctype.gl_entry.gl_entry.rename_gle_sle_docs for erpnext.ap.com
2023-05-22 10:30:24,164 INFO scheduler Scheduled Job Complete: erpnext.accounts.doctype.gl_entry.gl_entry.rename_gle_sle_docs for erpnext.ap.com
2023-05-22 10:31:24,034 ERROR scheduler Exception in Enqueue Events for Site MyTrialERP.com
Traceback (most recent call last):
  File "apps/frappe/frappe/utils/scheduler.py", line 70, in enqueue_events_for_site
    if is_scheduler_inactive():
  File "apps/frappe/frappe/utils/scheduler.py", line 105, in is_scheduler_inactive
    if is_scheduler_disabled():
  File "apps/frappe/frappe/utils/scheduler.py", line 115, in is_scheduler_disabled
    return not frappe.utils.cint(frappe.db.get_single_value("System Settings", "enable_scheduler"))
  File "apps/frappe/frappe/database/database.py", line 684, in get_single_value
    val = self.sql(
  File "apps/frappe/frappe/database/database.py", line 161, in sql
    self.connect()
  File "apps/frappe/frappe/database/database.py", line 85, in connect
    self._conn = self.get_connection()
  File "apps/frappe/frappe/database/mariadb/database.py", line 92, in get_connection
    conn.select_db(self.user)
  File "env/lib/python3.8/site-packages/pymysql/connections.py", line 496, in select_db
    self._read_ok_packet()
  File "env/lib/python3.8/site-packages/pymysql/connections.py", line 443, in _read_ok_packet
    pkt = self._read_packet()
  File "env/lib/python3.8/site-packages/pymysql/connections.py", line 725, in _read_packet
    packet.raise_for_error()
  File "env/lib/python3.8/site-packages/pymysql/protocol.py", line 221, in raise_for_error
    err.raise_mysql_exception(self._data)
  File "env/lib/python3.8/site-packages/pymysql/err.py", line 143, in raise_mysql_exception
    raise errorclass(errno, errval)
pymysql.err.OperationalError: (1049, "Unknown database '_c296b757cb15d301'")

2023-05-22 10:32:24,297 ERROR scheduler Exception in Enqueue Events for Site MyTrialERP.com
Traceback (most recent call last):
  File "apps/frappe/frappe/utils/scheduler.py", line 70, in enqueue_events_for_site
    if is_scheduler_inactive():
  File "apps/frappe/frappe/utils/scheduler.py", line 105, in is_scheduler_inactive
    if is_scheduler_disabled():
  File "apps/frappe/frappe/utils/scheduler.py", line 115, in is_scheduler_disabled
    return not frappe.utils.cint(frappe.db.get_single_value("System Settings", "enable_scheduler"))
  File "apps/frappe/frappe/database/database.py", line 684, in get_single_value
    val = self.sql(
  File "apps/frappe/frappe/database/database.py", line 161, in sql
    self.connect()
  File "apps/frappe/frappe/database/database.py", line 85, in connect
    self._conn = self.get_connection()
  File "apps/frappe/frappe/database/mariadb/database.py", line 92, in get_connection
    conn.select_db(self.user)
  File "env/lib/python3.8/site-packages/pymysql/connections.py", line 496, in select_db
    self._read_ok_packet()
  File "env/lib/python3.8/site-packages/pymysql/connections.py", line 443, in _read_ok_packet
    pkt = self._read_packet()
  File "env/lib/python3.8/site-packages/pymysql/connections.py", line 725, in _read_packet
    packet.raise_for_error()
  File "env/lib/python3.8/site-packages/pymysql/protocol.py", line 221, in raise_for_error
    err.raise_mysql_exception(self._data)
  File "env/lib/python3.8/site-packages/pymysql/err.py", line 143, in raise_mysql_exception
    raise errorclass(errno, errval)
pymysql.err.OperationalError: (1049, "Unknown database '_c296b757cb15d301'")

2023-05-22 10:33:24,563 ERROR scheduler Exception in Enqueue Events for Site MyTrialERP.com
Traceback (most recent call last):
  File "apps/frappe/frappe/utils/scheduler.py", line 70, in enqueue_events_for_site
    if is_scheduler_inactive():
  File "apps/frappe/frappe/utils/scheduler.py", line 105, in is_scheduler_inactive
    if is_scheduler_disabled():
  File "apps/frappe/frappe/utils/scheduler.py", line 115, in is_scheduler_disabled
    return not frappe.utils.cint(frappe.db.get_single_value("System Settings", "enable_scheduler"))
  File "apps/frappe/frappe/database/database.py", line 684, in get_single_value
    val = self.sql(
  File "apps/frappe/frappe/database/database.py", line 161, in sql
    self.connect()
  File "apps/frappe/frappe/database/database.py", line 85, in connect
    self._conn = self.get_connection()
  File "apps/frappe/frappe/database/mariadb/database.py", line 92, in get_connection
    conn.select_db(self.user)
  File "env/lib/python3.8/site-packages/pymysql/connections.py", line 496, in select_db
    self._read_ok_packet()
  File "env/lib/python3.8/site-packages/pymysql/connections.py", line 443, in _read_ok_packet
    pkt = self._read_packet()
  File "env/lib/python3.8/site-packages/pymysql/connections.py", line 725, in _read_packet
    packet.raise_for_error()
  File "env/lib/python3.8/site-packages/pymysql/protocol.py", line 221, in raise_for_error
    err.raise_mysql_exception(self._data)
  File "env/lib/python3.8/site-packages/pymysql/err.py", line 143, in raise_mysql_exception
    raise errorclass(errno, errval)
pymysql.err.OperationalError: (1049, "Unknown database '_c296b757cb15d301'")

2023-05-22 10:34:24,816 ERROR scheduler Exception in Enqueue Events for Site MyTrialERP.com
Traceback (most recent call last):
  File "apps/frappe/frappe/utils/scheduler.py", line 70, in enqueue_events_for_site
    if is_scheduler_inactive():
  File "apps/frappe/frappe/utils/scheduler.py", line 105, in is_scheduler_inactive
    if is_scheduler_disabled():
  File "apps/frappe/frappe/utils/scheduler.py", line 115, in is_scheduler_disabled
    return not frappe.utils.cint(frappe.db.get_single_value("System Settings", "enable_scheduler"))
  File "apps/frappe/frappe/database/database.py", line 684, in get_single_value
    val = self.sql(
  File "apps/frappe/frappe/database/database.py", line 161, in sql
    self.connect()
  File "apps/frappe/frappe/database/database.py", line 85, in connect
    self._conn = self.get_connection()
  File "apps/frappe/frappe/database/mariadb/database.py", line 92, in get_connection
    conn.select_db(self.user)
  File "env/lib/python3.8/site-packages/pymysql/connections.py", line 496, in select_db
    self._read_ok_packet()
  File "env/lib/python3.8/site-packages/pymysql/connections.py", line 443, in _read_ok_packet
    pkt = self._read_packet()
  File "env/lib/python3.8/site-packages/pymysql/connections.py", line 725, in _read_packet
    packet.raise_for_error()
  File "env/lib/python3.8/site-packages/pymysql/protocol.py", line 221, in raise_for_error
    err.raise_mysql_exception(self._data)
  File "env/lib/python3.8/site-packages/pymysql/err.py", line 143, in raise_mysql_exception
    raise errorclass(errno, errval)
pymysql.err.OperationalError: (1049, "Unknown database '_c296b757cb15d301'")

2023-05-22 10:35:25,056 ERROR scheduler Exception in Enqueue Events for Site MyTrialERP.com
Traceback (most recent call last):
  File "apps/frappe/frappe/utils/scheduler.py", line 70, in enqueue_events_for_site
    if is_scheduler_inactive():
  File "apps/frappe/frappe/utils/scheduler.py", line 105, in is_scheduler_inactive
    if is_scheduler_disabled():
  File "apps/frappe/frappe/utils/scheduler.py", line 115, in is_scheduler_disabled
    return not frappe.utils.cint(frappe.db.get_single_value("System Settings", "enable_scheduler"))
  File "apps/frappe/frappe/database/database.py", line 684, in get_single_value
    val = self.sql(
  File "apps/frappe/frappe/database/database.py", line 161, in sql
    self.connect()
  File "apps/frappe/frappe/database/database.py", line 85, in connect
    self._conn = self.get_connection()
  File "apps/frappe/frappe/database/mariadb/database.py", line 92, in get_connection
    conn.select_db(self.user)
  File "env/lib/python3.8/site-packages/pymysql/connections.py", line 496, in select_db
    self._read_ok_packet()
  File "env/lib/python3.8/site-packages/pymysql/connections.py", line 443, in _read_ok_packet
    pkt = self._read_packet()
  File "env/lib/python3.8/site-packages/pymysql/connections.py", line 725, in _read_packet
    packet.raise_for_error()
  File "env/lib/python3.8/site-packages/pymysql/protocol.py", line 221, in raise_for_error
    err.raise_mysql_exception(self._data)
  File "env/lib/python3.8/site-packages/pymysql/err.py", line 143, in raise_mysql_exception
    raise errorclass(errno, errval)
pymysql.err.OperationalError: (1049, "Unknown database '_c296b757cb15d301'")

2023-05-22 10:36:25,295 ERROR scheduler Exception in Enqueue Events for Site MyTrialERP.com
Traceback (most recent call last):
  File "apps/frappe/frappe/utils/scheduler.py", line 70, in enqueue_events_for_site
    if is_scheduler_inactive():
  File "apps/frappe/frappe/utils/scheduler.py", line 105, in is_scheduler_inactive
    if is_scheduler_disabled():
  File "apps/frappe/frappe/utils/scheduler.py", line 115, in is_scheduler_disabled
    return not frappe.utils.cint(frappe.db.get_single_value("System Settings", "enable_scheduler"))
  File "apps/frappe/frappe/database/database.py", line 684, in get_single_value
    val = self.sql(
  File "apps/frappe/frappe/database/database.py", line 161, in sql
    self.connect()
  File "apps/frappe/frappe/database/database.py", line 85, in connect
    self._conn = self.get_connection()
  File "apps/frappe/frappe/database/mariadb/database.py", line 92, in get_connection
    conn.select_db(self.user)
  File "env/lib/python3.8/site-packages/pymysql/connections.py", line 496, in select_db
    self._read_ok_packet()
  File "env/lib/python3.8/site-packages/pymysql/connections.py", line 443, in _read_ok_packet
    pkt = self._read_packet()
  File "env/lib/python3.8/site-packages/pymysql/connections.py", line 725, in _read_packet
    packet.raise_for_error()
  File "env/lib/python3.8/site-packages/pymysql/protocol.py", line 221, in raise_for_error
    err.raise_mysql_exception(self._data)
  File "env/lib/python3.8/site-packages/pymysql/err.py", line 143, in raise_mysql_exception
    raise errorclass(errno, errval)
pymysql.err.OperationalError: (1049, "Unknown database '_c296b757cb15d301'")

2023-05-22 10:37:25,563 ERROR scheduler Exception in Enqueue Events for Site MyTrialERP.com
Traceback (most recent call last):
  File "apps/frappe/frappe/utils/scheduler.py", line 70, in enqueue_events_for_site
    if is_scheduler_inactive():
  File "apps/frappe/frappe/utils/scheduler.py", line 105, in is_scheduler_inactive
    if is_scheduler_disabled():
  File "apps/frappe/frappe/utils/scheduler.py", line 115, in is_scheduler_disabled
    return not frappe.utils.cint(frappe.db.get_single_value("System Settings", "enable_scheduler"))
  File "apps/frappe/frappe/database/database.py", line 684, in get_single_value
    val = self.sql(
  File "apps/frappe/frappe/database/database.py", line 161, in sql
    self.connect()
  File "apps/frappe/frappe/database/database.py", line 85, in connect
    self._conn = self.get_connection()
  File "apps/frappe/frappe/database/mariadb/database.py", line 92, in get_connection
    conn.select_db(self.user)
  File "env/lib/python3.8/site-packages/pymysql/connections.py", line 496, in select_db
    self._read_ok_packet()
  File "env/lib/python3.8/site-packages/pymysql/connections.py", line 443, in _read_ok_packet
    pkt = self._read_packet()
  File "env/lib/python3.8/site-packages/pymysql/connections.py", line 725, in _read_packet
    packet.raise_for_error()
  File "env/lib/python3.8/site-packages/pymysql/protocol.py", line 221, in raise_for_error
    err.raise_mysql_exception(self._data)
  File "env/lib/python3.8/site-packages/pymysql/err.py", line 143, in raise_mysql_exception
    raise errorclass(errno, errval)
pymysql.err.OperationalError: (1049, "Unknown database '_c296b757cb15d301'")

2023-05-22 10:38:25,848 ERROR scheduler Exception in Enqueue Events for Site MyTrialERP.com
Traceback (most recent call last):
  File "apps/frappe/frappe/utils/scheduler.py", line 70, in enqueue_events_for_site
    if is_scheduler_inactive():
  File "apps/frappe/frappe/utils/scheduler.py", line 105, in is_scheduler_inactive
    if is_scheduler_disabled():
  File "apps/frappe/frappe/utils/scheduler.py", line 115, in is_scheduler_disabled
    return not frappe.utils.cint(frappe.db.get_single_value("System Settings", "enable_scheduler"))
  File "apps/frappe/frappe/database/database.py", line 684, in get_single_value
    val = self.sql(
  File "apps/frappe/frappe/database/database.py", line 161, in sql
    self.connect()
  File "apps/frappe/frappe/database/database.py", line 85, in connect
    self._conn = self.get_connection()
  File "apps/frappe/frappe/database/mariadb/database.py", line 92, in get_connection
    conn.select_db(self.user)
  File "env/lib/python3.8/site-packages/pymysql/connections.py", line 496, in select_db
    self._read_ok_packet()
  File "env/lib/python3.8/site-packages/pymysql/connections.py", line 443, in _read_ok_packet
    pkt = self._read_packet()
  File "env/lib/python3.8/site-packages/pymysql/connections.py", line 725, in _read_packet
    packet.raise_for_error()
  File "env/lib/python3.8/site-packages/pymysql/protocol.py", line 221, in raise_for_error
    err.raise_mysql_exception(self._data)
  File "env/lib/python3.8/site-packages/pymysql/err.py", line 143, in raise_mysql_exception
    raise errorclass(errno, errval)
pymysql.err.OperationalError: (1049, "Unknown database '_c296b757cb15d301'")

2023-05-22 10:39:26,161 ERROR scheduler Exception in Enqueue Events for Site MyTrialERP.com
Traceback (most recent call last):
  File "apps/frappe/frappe/utils/scheduler.py", line 70, in enqueue_events_for_site
    if is_scheduler_inactive():
  File "apps/frappe/frappe/utils/scheduler.py", line 105, in is_scheduler_inactive
    if is_scheduler_disabled():
  File "apps/frappe/frappe/utils/scheduler.py", line 115, in is_scheduler_disabled
    return not frappe.utils.cint(frappe.db.get_single_value("System Settings", "enable_scheduler"))
  File "apps/frappe/frappe/database/database.py", line 684, in get_single_value
    val = self.sql(
  File "apps/frappe/frappe/database/database.py", line 161, in sql
    self.connect()
  File "apps/frappe/frappe/database/database.py", line 85, in connect
    self._conn = self.get_connection()
  File "apps/frappe/frappe/database/mariadb/database.py", line 92, in get_connection
    conn.select_db(self.user)
  File "env/lib/python3.8/site-packages/pymysql/connections.py", line 496, in select_db
    self._read_ok_packet()
  File "env/lib/python3.8/site-packages/pymysql/connections.py", line 443, in _read_ok_packet
    pkt = self._read_packet()
  File "env/lib/python3.8/site-packages/pymysql/connections.py", line 725, in _read_packet
    packet.raise_for_error()
  File "env/lib/python3.8/site-packages/pymysql/protocol.py", line 221, in raise_for_error
    err.raise_mysql_exception(self._data)
  File "env/lib/python3.8/site-packages/pymysql/err.py", line 143, in raise_mysql_exception
    raise errorclass(errno, errval)
pymysql.err.OperationalError: (1049, "Unknown database '_c296b757cb15d301'")

2023-05-22 10:40:26,380 ERROR scheduler Exception in Enqueue Events for Site MyTrialERP.com
Traceback (most recent call last):
  File "apps/frappe/frappe/utils/scheduler.py", line 70, in enqueue_events_for_site
    if is_scheduler_inactive():
  File "apps/frappe/frappe/utils/scheduler.py", line 105, in is_scheduler_inactive
    if is_scheduler_disabled():
  File "apps/frappe/frappe/utils/scheduler.py", line 115, in is_scheduler_disabled
    return not frappe.utils.cint(frappe.db.get_single_value("System Settings", "enable_scheduler"))
  File "apps/frappe/frappe/database/database.py", line 684, in get_single_value
    val = self.sql(
  File "apps/frappe/frappe/database/database.py", line 161, in sql
    self.connect()
  File "apps/frappe/frappe/database/database.py", line 85, in connect
    self._conn = self.get_connection()
  File "apps/frappe/frappe/database/mariadb/database.py", line 92, in get_connection
    conn.select_db(self.user)
  File "env/lib/python3.8/site-packages/pymysql/connections.py", line 496, in select_db
    self._read_ok_packet()
  File "env/lib/python3.8/site-packages/pymysql/connections.py", line 443, in _read_ok_packet
    pkt = self._read_packet()
  File "env/lib/python3.8/site-packages/pymysql/connections.py", line 725, in _read_packet
    packet.raise_for_error()
  File "env/lib/python3.8/site-packages/pymysql/protocol.py", line 221, in raise_for_error
    err.raise_mysql_exception(self._data)
  File "env/lib/python3.8/site-packages/pymysql/err.py", line 143, in raise_mysql_exception
    raise errorclass(errno, errval)
pymysql.err.OperationalError: (1049, "Unknown database '_c296b757cb15d301'")

2023-05-22 10:41:26,649 ERROR scheduler Exception in Enqueue Events for Site MyTrialERP.com
Traceback (most recent call last):
  File "apps/frappe/frappe/utils/scheduler.py", line 70, in enqueue_events_for_site
    if is_scheduler_inactive():
  File "apps/frappe/frappe/utils/scheduler.py", line 105, in is_scheduler_inactive
    if is_scheduler_disabled():
  File "apps/frappe/frappe/utils/scheduler.py", line 115, in is_scheduler_disabled
    return not frappe.utils.cint(frappe.db.get_single_value("System Settings", "enable_scheduler"))
  File "apps/frappe/frappe/database/database.py", line 684, in get_single_value
    val = self.sql(
  File "apps/frappe/frappe/database/database.py", line 161, in sql
    self.connect()
  File "apps/frappe/frappe/database/database.py", line 85, in connect
    self._conn = self.get_connection()
  File "apps/frappe/frappe/database/mariadb/database.py", line 92, in get_connection
    conn.select_db(self.user)
  File "env/lib/python3.8/site-packages/pymysql/connections.py", line 496, in select_db
    self._read_ok_packet()
  File "env/lib/python3.8/site-packages/pymysql/connections.py", line 443, in _read_ok_packet
    pkt = self._read_packet()
  File "env/lib/python3.8/site-packages/pymysql/connections.py", line 725, in _read_packet
    packet.raise_for_error()
  File "env/lib/python3.8/site-packages/pymysql/protocol.py", line 221, in raise_for_error
    err.raise_mysql_exception(self._data)
  File "env/lib/python3.8/site-packages/pymysql/err.py", line 143, in raise_mysql_exception
    raise errorclass(errno, errval)
pymysql.err.OperationalError: (1049, "Unknown database '_c296b757cb15d301'")

2023-05-22 10:42:26,866 ERROR scheduler Exception in Enqueue Events for Site MyTrialERP.com
Traceback (most recent call last):
  File "apps/frappe/frappe/utils/scheduler.py", line 70, in enqueue_events_for_site
    if is_scheduler_inactive():
  File "apps/frappe/frappe/utils/scheduler.py", line 105, in is_scheduler_inactive
    if is_scheduler_disabled():
  File "apps/frappe/frappe/utils/scheduler.py", line 115, in is_scheduler_disabled
    return not frappe.utils.cint(frappe.db.get_single_value("System Settings", "enable_scheduler"))
  File "apps/frappe/frappe/database/database.py", line 684, in get_single_value
    val = self.sql(
  File "apps/frappe/frappe/database/database.py", line 161, in sql
    self.connect()
  File "apps/frappe/frappe/database/database.py", line 85, in connect
    self._conn = self.get_connection()
  File "apps/frappe/frappe/database/mariadb/database.py", line 92, in get_connection
    conn.select_db(self.user)
  File "env/lib/python3.8/site-packages/pymysql/connections.py", line 496, in select_db
    self._read_ok_packet()
  File "env/lib/python3.8/site-packages/pymysql/connections.py", line 443, in _read_ok_packet
    pkt = self._read_packet()
  File "env/lib/python3.8/site-packages/pymysql/connections.py", line 725, in _read_packet
    packet.raise_for_error()
  File "env/lib/python3.8/site-packages/pymysql/protocol.py", line 221, in raise_for_error
    err.raise_mysql_exception(self._data)
  File "env/lib/python3.8/site-packages/pymysql/err.py", line 143, in raise_mysql_exception
    raise errorclass(errno, errval)
pymysql.err.OperationalError: (1049, "Unknown database '_c296b757cb15d301'")

2023-05-22 11:27:01,542 ERROR scheduler Exception in Enqueue Events for Site MyTrialERP.com
Traceback (most recent call last):
  File "apps/frappe/frappe/utils/scheduler.py", line 70, in enqueue_events_for_site
    if is_scheduler_inactive():
  File "apps/frappe/frappe/utils/scheduler.py", line 105, in is_scheduler_inactive
    if is_scheduler_disabled():
  File "apps/frappe/frappe/utils/scheduler.py", line 115, in is_scheduler_disabled
    return not frappe.utils.cint(frappe.db.get_single_value("System Settings", "enable_scheduler"))
  File "apps/frappe/frappe/database/database.py", line 684, in get_single_value
    val = self.sql(
  File "apps/frappe/frappe/database/database.py", line 161, in sql
    self.connect()
  File "apps/frappe/frappe/database/database.py", line 85, in connect
    self._conn = self.get_connection()
  File "apps/frappe/frappe/database/mariadb/database.py", line 92, in get_connection
    conn.select_db(self.user)
  File "env/lib/python3.8/site-packages/pymysql/connections.py", line 496, in select_db
    self._read_ok_packet()
  File "env/lib/python3.8/site-packages/pymysql/connections.py", line 443, in _read_ok_packet
    pkt = self._read_packet()
  File "env/lib/python3.8/site-packages/pymysql/connections.py", line 725, in _read_packet
    packet.raise_for_error()
  File "env/lib/python3.8/site-packages/pymysql/protocol.py", line 221, in raise_for_error
    err.raise_mysql_exception(self._data)
  File "env/lib/python3.8/site-packages/pymysql/err.py", line 143, in raise_mysql_exception
    raise errorclass(errno, errval)
pymysql.err.OperationalError: (1049, "Unknown database '_c296b757cb15d301'")

2023-05-22 11:28:01,976 ERROR scheduler Exception in Enqueue Events for Site MyTrialERP.com
Traceback (most recent call last):
  File "apps/frappe/frappe/utils/scheduler.py", line 70, in enqueue_events_for_site
    if is_scheduler_inactive():
  File "apps/frappe/frappe/utils/scheduler.py", line 105, in is_scheduler_inactive
    if is_scheduler_disabled():
  File "apps/frappe/frappe/utils/scheduler.py", line 115, in is_scheduler_disabled
    return not frappe.utils.cint(frappe.db.get_single_value("System Settings", "enable_scheduler"))
  File "apps/frappe/frappe/database/database.py", line 684, in get_single_value
    val = self.sql(
  File "apps/frappe/frappe/database/database.py", line 161, in sql
    self.connect()
  File "apps/frappe/frappe/database/database.py", line 85, in connect
    self._conn = self.get_connection()
  File "apps/frappe/frappe/database/mariadb/database.py", line 92, in get_connection
    conn.select_db(self.user)
  File "env/lib/python3.8/site-packages/pymysql/connections.py", line 496, in select_db
    self._read_ok_packet()
  File "env/lib/python3.8/site-packages/pymysql/connections.py", line 443, in _read_ok_packet
    pkt = self._read_packet()
  File "env/lib/python3.8/site-packages/pymysql/connections.py", line 725, in _read_packet
    packet.raise_for_error()
  File "env/lib/python3.8/site-packages/pymysql/protocol.py", line 221, in raise_for_error
    err.raise_mysql_exception(self._data)
  File "env/lib/python3.8/site-packages/pymysql/err.py", line 143, in raise_mysql_exception
    raise errorclass(errno, errval)
pymysql.err.OperationalError: (1049, "Unknown database '_c296b757cb15d301'")

2023-05-22 11:29:02,288 ERROR scheduler Exception in Enqueue Events for Site MyTrialERP.com
Traceback (most recent call last):
  File "apps/frappe/frappe/utils/scheduler.py", line 70, in enqueue_events_for_site
    if is_scheduler_inactive():
  File "apps/frappe/frappe/utils/scheduler.py", line 105, in is_scheduler_inactive
    if is_scheduler_disabled():
  File "apps/frappe/frappe/utils/scheduler.py", line 115, in is_scheduler_disabled
    return not frappe.utils.cint(frappe.db.get_single_value("System Settings", "enable_scheduler"))
  File "apps/frappe/frappe/database/database.py", line 684, in get_single_value
    val = self.sql(
  File "apps/frappe/frappe/database/database.py", line 161, in sql
    self.connect()
  File "apps/frappe/frappe/database/database.py", line 85, in connect
    self._conn = self.get_connection()
  File "apps/frappe/frappe/database/mariadb/database.py", line 92, in get_connection
    conn.select_db(self.user)
  File "env/lib/python3.8/site-packages/pymysql/connections.py", line 496, in select_db
    self._read_ok_packet()
  File "env/lib/python3.8/site-packages/pymysql/connections.py", line 443, in _read_ok_packet
    pkt = self._read_packet()
  File "env/lib/python3.8/site-packages/pymysql/connections.py", line 725, in _read_packet
    packet.raise_for_error()
  File "env/lib/python3.8/site-packages/pymysql/protocol.py", line 221, in raise_for_error
    err.raise_mysql_exception(self._data)
  File "env/lib/python3.8/site-packages/pymysql/err.py", line 143, in raise_mysql_exception
    raise errorclass(errno, errval)
pymysql.err.OperationalError: (1049, "Unknown database '_c296b757cb15d301'")

2023-05-22 11:30:02,547 ERROR scheduler Exception in Enqueue Events for Site MyTrialERP.com
Traceback (most recent call last):
  File "apps/frappe/frappe/utils/scheduler.py", line 70, in enqueue_events_for_site
    if is_scheduler_inactive():
  File "apps/frappe/frappe/utils/scheduler.py", line 105, in is_scheduler_inactive
    if is_scheduler_disabled():
  File "apps/frappe/frappe/utils/scheduler.py", line 115, in is_scheduler_disabled
    return not frappe.utils.cint(frappe.db.get_single_value("System Settings", "enable_scheduler"))
  File "apps/frappe/frappe/database/database.py", line 684, in get_single_value
    val = self.sql(
  File "apps/frappe/frappe/database/database.py", line 161, in sql
    self.connect()
  File "apps/frappe/frappe/database/database.py", line 85, in connect
    self._conn = self.get_connection()
  File "apps/frappe/frappe/database/mariadb/database.py", line 92, in get_connection
    conn.select_db(self.user)
  File "env/lib/python3.8/site-packages/pymysql/connections.py", line 496, in select_db
    self._read_ok_packet()
  File "env/lib/python3.8/site-packages/pymysql/connections.py", line 443, in _read_ok_packet
    pkt = self._read_packet()
  File "env/lib/python3.8/site-packages/pymysql/connections.py", line 725, in _read_packet
    packet.raise_for_error()
  File "env/lib/python3.8/site-packages/pymysql/protocol.py", line 221, in raise_for_error
    err.raise_mysql_exception(self._data)
  File "env/lib/python3.8/site-packages/pymysql/err.py", line 143, in raise_mysql_exception
    raise errorclass(errno, errval)
pymysql.err.OperationalError: (1049, "Unknown database '_c296b757cb15d301'")

2023-05-22 11:31:02,797 ERROR scheduler Exception in Enqueue Events for Site MyTrialERP.com
Traceback (most recent call last):
  File "apps/frappe/frappe/utils/scheduler.py", line 70, in enqueue_events_for_site
    if is_scheduler_inactive():
  File "apps/frappe/frappe/utils/scheduler.py", line 105, in is_scheduler_inactive
    if is_scheduler_disabled():
  File "apps/frappe/frappe/utils/scheduler.py", line 115, in is_scheduler_disabled
    return not frappe.utils.cint(frappe.db.get_single_value("System Settings", "enable_scheduler"))
  File "apps/frappe/frappe/database/database.py", line 684, in get_single_value
    val = self.sql(
  File "apps/frappe/frappe/database/database.py", line 161, in sql
    self.connect()
  File "apps/frappe/frappe/database/database.py", line 85, in connect
    self._conn = self.get_connection()
  File "apps/frappe/frappe/database/mariadb/database.py", line 92, in get_connection
    conn.select_db(self.user)
  File "env/lib/python3.8/site-packages/pymysql/connections.py", line 496, in select_db
    self._read_ok_packet()
  File "env/lib/python3.8/site-packages/pymysql/connections.py", line 443, in _read_ok_packet
    pkt = self._read_packet()
  File "env/lib/python3.8/site-packages/pymysql/connections.py", line 725, in _read_packet
    packet.raise_for_error()
  File "env/lib/python3.8/site-packages/pymysql/protocol.py", line 221, in raise_for_error
    err.raise_mysql_exception(self._data)
  File "env/lib/python3.8/site-packages/pymysql/err.py", line 143, in raise_mysql_exception
    raise errorclass(errno, errval)
pymysql.err.OperationalError: (1049, "Unknown database '_c296b757cb15d301'")

2023-05-22 11:32:03,053 ERROR scheduler Exception in Enqueue Events for Site MyTrialERP.com
Traceback (most recent call last):
  File "apps/frappe/frappe/utils/scheduler.py", line 70, in enqueue_events_for_site
    if is_scheduler_inactive():
  File "apps/frappe/frappe/utils/scheduler.py", line 105, in is_scheduler_inactive
    if is_scheduler_disabled():
  File "apps/frappe/frappe/utils/scheduler.py", line 115, in is_scheduler_disabled
    return not frappe.utils.cint(frappe.db.get_single_value("System Settings", "enable_scheduler"))
  File "apps/frappe/frappe/database/database.py", line 684, in get_single_value
    val = self.sql(
  File "apps/frappe/frappe/database/database.py", line 161, in sql
    self.connect()
  File "apps/frappe/frappe/database/database.py", line 85, in connect
    self._conn = self.get_connection()
  File "apps/frappe/frappe/database/mariadb/database.py", line 92, in get_connection
    conn.select_db(self.user)
  File "env/lib/python3.8/site-packages/pymysql/connections.py", line 496, in select_db
    self._read_ok_packet()
  File "env/lib/python3.8/site-packages/pymysql/connections.py", line 443, in _read_ok_packet
    pkt = self._read_packet()
  File "env/lib/python3.8/site-packages/pymysql/connections.py", line 725, in _read_packet
    packet.raise_for_error()
  File "env/lib/python3.8/site-packages/pymysql/protocol.py", line 221, in raise_for_error
    err.raise_mysql_exception(self._data)
  File "env/lib/python3.8/site-packages/pymysql/err.py", line 143, in raise_mysql_exception
    raise errorclass(errno, errval)
pymysql.err.OperationalError: (1049, "Unknown database '_c296b757cb15d301'")

2023-05-22 11:33:03,330 ERROR scheduler Exception in Enqueue Events for Site MyTrialERP.com
Traceback (most recent call last):
  File "apps/frappe/frappe/utils/scheduler.py", line 70, in enqueue_events_for_site
    if is_scheduler_inactive():
  File "apps/frappe/frappe/utils/scheduler.py", line 105, in is_scheduler_inactive
    if is_scheduler_disabled():
  File "apps/frappe/frappe/utils/scheduler.py", line 115, in is_scheduler_disabled
    return not frappe.utils.cint(frappe.db.get_single_value("System Settings", "enable_scheduler"))
  File "apps/frappe/frappe/database/database.py", line 684, in get_single_value
    val = self.sql(
  File "apps/frappe/frappe/database/database.py", line 161, in sql
    self.connect()
  File "apps/frappe/frappe/database/database.py", line 85, in connect
    self._conn = self.get_connection()
  File "apps/frappe/frappe/database/mariadb/database.py", line 92, in get_connection
    conn.select_db(self.user)
  File "env/lib/python3.8/site-packages/pymysql/connections.py", line 496, in select_db
    self._read_ok_packet()
  File "env/lib/python3.8/site-packages/pymysql/connections.py", line 443, in _read_ok_packet
    pkt = self._read_packet()
  File "env/lib/python3.8/site-packages/pymysql/connections.py", line 725, in _read_packet
    packet.raise_for_error()
  File "env/lib/python3.8/site-packages/pymysql/protocol.py", line 221, in raise_for_error
    err.raise_mysql_exception(self._data)
  File "env/lib/python3.8/site-packages/pymysql/err.py", line 143, in raise_mysql_exception
    raise errorclass(errno, errval)
pymysql.err.OperationalError: (1049, "Unknown database '_c296b757cb15d301'")

2023-05-22 11:34:03,588 ERROR scheduler Exception in Enqueue Events for Site MyTrialERP.com
Traceback (most recent call last):
  File "apps/frappe/frappe/utils/scheduler.py", line 70, in enqueue_events_for_site
    if is_scheduler_inactive():
  File "apps/frappe/frappe/utils/scheduler.py", line 105, in is_scheduler_inactive
    if is_scheduler_disabled():
  File "apps/frappe/frappe/utils/scheduler.py", line 115, in is_scheduler_disabled
    return not frappe.utils.cint(frappe.db.get_single_value("System Settings", "enable_scheduler"))
  File "apps/frappe/frappe/database/database.py", line 684, in get_single_value
    val = self.sql(
  File "apps/frappe/frappe/database/database.py", line 161, in sql
    self.connect()
  File "apps/frappe/frappe/database/database.py", line 85, in connect
    self._conn = self.get_connection()
  File "apps/frappe/frappe/database/mariadb/database.py", line 92, in get_connection
    conn.select_db(self.user)
  File "env/lib/python3.8/site-packages/pymysql/connections.py", line 496, in select_db
    self._read_ok_packet()
  File "env/lib/python3.8/site-packages/pymysql/connections.py", line 443, in _read_ok_packet
    pkt = self._read_packet()
  File "env/lib/python3.8/site-packages/pymysql/connections.py", line 725, in _read_packet
    packet.raise_for_error()
  File "env/lib/python3.8/site-packages/pymysql/protocol.py", line 221, in raise_for_error
    err.raise_mysql_exception(self._data)
  File "env/lib/python3.8/site-packages/pymysql/err.py", line 143, in raise_mysql_exception
    raise errorclass(errno, errval)
pymysql.err.OperationalError: (1049, "Unknown database '_c296b757cb15d301'")

2023-05-22 11:35:03,868 ERROR scheduler Exception in Enqueue Events for Site MyTrialERP.com
Traceback (most recent call last):
  File "apps/frappe/frappe/utils/scheduler.py", line 70, in enqueue_events_for_site
    if is_scheduler_inactive():
  File "apps/frappe/frappe/utils/scheduler.py", line 105, in is_scheduler_inactive
    if is_scheduler_disabled():
  File "apps/frappe/frappe/utils/scheduler.py", line 115, in is_scheduler_disabled
    return not frappe.utils.cint(frappe.db.get_single_value("System Settings", "enable_scheduler"))
  File "apps/frappe/frappe/database/database.py", line 684, in get_single_value
    val = self.sql(
  File "apps/frappe/frappe/database/database.py", line 161, in sql
    self.connect()
  File "apps/frappe/frappe/database/database.py", line 85, in connect
    self._conn = self.get_connection()
  File "apps/frappe/frappe/database/mariadb/database.py", line 92, in get_connection
    conn.select_db(self.user)
  File "env/lib/python3.8/site-packages/pymysql/connections.py", line 496, in select_db
    self._read_ok_packet()
  File "env/lib/python3.8/site-packages/pymysql/connections.py", line 443, in _read_ok_packet
    pkt = self._read_packet()
  File "env/lib/python3.8/site-packages/pymysql/connections.py", line 725, in _read_packet
    packet.raise_for_error()
  File "env/lib/python3.8/site-packages/pymysql/protocol.py", line 221, in raise_for_error
    err.raise_mysql_exception(self._data)
  File "env/lib/python3.8/site-packages/pymysql/err.py", line 143, in raise_mysql_exception
    raise errorclass(errno, errval)
pymysql.err.OperationalError: (1049, "Unknown database '_c296b757cb15d301'")

2023-05-22 11:36:04,111 ERROR scheduler Exception in Enqueue Events for Site MyTrialERP.com
Traceback (most recent call last):
  File "apps/frappe/frappe/utils/scheduler.py", line 70, in enqueue_events_for_site
    if is_scheduler_inactive():
  File "apps/frappe/frappe/utils/scheduler.py", line 105, in is_scheduler_inactive
    if is_scheduler_disabled():
  File "apps/frappe/frappe/utils/scheduler.py", line 115, in is_scheduler_disabled
    return not frappe.utils.cint(frappe.db.get_single_value("System Settings", "enable_scheduler"))
  File "apps/frappe/frappe/database/database.py", line 684, in get_single_value
    val = self.sql(
  File "apps/frappe/frappe/database/database.py", line 161, in sql
    self.connect()
  File "apps/frappe/frappe/database/database.py", line 85, in connect
    self._conn = self.get_connection()
  File "apps/frappe/frappe/database/mariadb/database.py", line 92, in get_connection
    conn.select_db(self.user)
  File "env/lib/python3.8/site-packages/pymysql/connections.py", line 496, in select_db
    self._read_ok_packet()
  File "env/lib/python3.8/site-packages/pymysql/connections.py", line 443, in _read_ok_packet
    pkt = self._read_packet()
  File "env/lib/python3.8/site-packages/pymysql/connections.py", line 725, in _read_packet
    packet.raise_for_error()
  File "env/lib/python3.8/site-packages/pymysql/protocol.py", line 221, in raise_for_error
    err.raise_mysql_exception(self._data)
  File "env/lib/python3.8/site-packages/pymysql/err.py", line 143, in raise_mysql_exception
    raise errorclass(errno, errval)
pymysql.err.OperationalError: (1049, "Unknown database '_c296b757cb15d301'")

2023-05-22 11:37:04,427 ERROR scheduler Exception in Enqueue Events for Site MyTrialERP.com
Traceback (most recent call last):
  File "apps/frappe/frappe/utils/scheduler.py", line 70, in enqueue_events_for_site
    if is_scheduler_inactive():
  File "apps/frappe/frappe/utils/scheduler.py", line 105, in is_scheduler_inactive
    if is_scheduler_disabled():
  File "apps/frappe/frappe/utils/scheduler.py", line 115, in is_scheduler_disabled
    return not frappe.utils.cint(frappe.db.get_single_value("System Settings", "enable_scheduler"))
  File "apps/frappe/frappe/database/database.py", line 684, in get_single_value
    val = self.sql(
  File "apps/frappe/frappe/database/database.py", line 161, in sql
    self.connect()
  File "apps/frappe/frappe/database/database.py", line 85, in connect
    self._conn = self.get_connection()
  File "apps/frappe/frappe/database/mariadb/database.py", line 92, in get_connection
    conn.select_db(self.user)
  File "env/lib/python3.8/site-packages/pymysql/connections.py", line 496, in select_db
    self._read_ok_packet()
  File "env/lib/python3.8/site-packages/pymysql/connections.py", line 443, in _read_ok_packet
    pkt = self._read_packet()
  File "env/lib/python3.8/site-packages/pymysql/connections.py", line 725, in _read_packet
    packet.raise_for_error()
  File "env/lib/python3.8/site-packages/pymysql/protocol.py", line 221, in raise_for_error
    err.raise_mysql_exception(self._data)
  File "env/lib/python3.8/site-packages/pymysql/err.py", line 143, in raise_mysql_exception
    raise errorclass(errno, errval)
pymysql.err.OperationalError: (1049, "Unknown database '_c296b757cb15d301'")

2023-05-22 11:38:04,835 ERROR scheduler Exception in Enqueue Events for Site MyTrialERP.com
Traceback (most recent call last):
  File "apps/frappe/frappe/utils/scheduler.py", line 70, in enqueue_events_for_site
    if is_scheduler_inactive():
  File "apps/frappe/frappe/utils/scheduler.py", line 105, in is_scheduler_inactive
    if is_scheduler_disabled():
  File "apps/frappe/frappe/utils/scheduler.py", line 115, in is_scheduler_disabled
    return not frappe.utils.cint(frappe.db.get_single_value("System Settings", "enable_scheduler"))
  File "apps/frappe/frappe/database/database.py", line 684, in get_single_value
    val = self.sql(
  File "apps/frappe/frappe/database/database.py", line 161, in sql
    self.connect()
  File "apps/frappe/frappe/database/database.py", line 85, in connect
    self._conn = self.get_connection()
  File "apps/frappe/frappe/database/mariadb/database.py", line 92, in get_connection
    conn.select_db(self.user)
  File "env/lib/python3.8/site-packages/pymysql/connections.py", line 496, in select_db
    self._read_ok_packet()
  File "env/lib/python3.8/site-packages/pymysql/connections.py", line 443, in _read_ok_packet
    pkt = self._read_packet()
  File "env/lib/python3.8/site-packages/pymysql/connections.py", line 725, in _read_packet
    packet.raise_for_error()
  File "env/lib/python3.8/site-packages/pymysql/protocol.py", line 221, in raise_for_error
    err.raise_mysql_exception(self._data)
  File "env/lib/python3.8/site-packages/pymysql/err.py", line 143, in raise_mysql_exception
    raise errorclass(errno, errval)
pymysql.err.OperationalError: (1049, "Unknown database '_c296b757cb15d301'")

2023-05-22 11:39:05,114 ERROR scheduler Exception in Enqueue Events for Site MyTrialERP.com
Traceback (most recent call last):
  File "apps/frappe/frappe/utils/scheduler.py", line 70, in enqueue_events_for_site
    if is_scheduler_inactive():
  File "apps/frappe/frappe/utils/scheduler.py", line 105, in is_scheduler_inactive
    if is_scheduler_disabled():
  File "apps/frappe/frappe/utils/scheduler.py", line 115, in is_scheduler_disabled
    return not frappe.utils.cint(frappe.db.get_single_value("System Settings", "enable_scheduler"))
  File "apps/frappe/frappe/database/database.py", line 684, in get_single_value
    val = self.sql(
  File "apps/frappe/frappe/database/database.py", line 161, in sql
    self.connect()
  File "apps/frappe/frappe/database/database.py", line 85, in connect
    self._conn = self.get_connection()
  File "apps/frappe/frappe/database/mariadb/database.py", line 92, in get_connection
    conn.select_db(self.user)
  File "env/lib/python3.8/site-packages/pymysql/connections.py", line 496, in select_db
    self._read_ok_packet()
  File "env/lib/python3.8/site-packages/pymysql/connections.py", line 443, in _read_ok_packet
    pkt = self._read_packet()
  File "env/lib/python3.8/site-packages/pymysql/connections.py", line 725, in _read_packet
    packet.raise_for_error()
  File "env/lib/python3.8/site-packages/pymysql/protocol.py", line 221, in raise_for_error
    err.raise_mysql_exception(self._data)
  File "env/lib/python3.8/site-packages/pymysql/err.py", line 143, in raise_mysql_exception
    raise errorclass(errno, errval)
pymysql.err.OperationalError: (1049, "Unknown database '_c296b757cb15d301'")

2023-05-22 11:40:05,359 ERROR scheduler Exception in Enqueue Events for Site MyTrialERP.com
Traceback (most recent call last):
  File "apps/frappe/frappe/utils/scheduler.py", line 70, in enqueue_events_for_site
    if is_scheduler_inactive():
  File "apps/frappe/frappe/utils/scheduler.py", line 105, in is_scheduler_inactive
    if is_scheduler_disabled():
  File "apps/frappe/frappe/utils/scheduler.py", line 115, in is_scheduler_disabled
    return not frappe.utils.cint(frappe.db.get_single_value("System Settings", "enable_scheduler"))
  File "apps/frappe/frappe/database/database.py", line 684, in get_single_value
    val = self.sql(
  File "apps/frappe/frappe/database/database.py", line 161, in sql
    self.connect()
  File "apps/frappe/frappe/database/database.py", line 85, in connect
    self._conn = self.get_connection()
  File "apps/frappe/frappe/database/mariadb/database.py", line 92, in get_connection
    conn.select_db(self.user)
  File "env/lib/python3.8/site-packages/pymysql/connections.py", line 496, in select_db
    self._read_ok_packet()
  File "env/lib/python3.8/site-packages/pymysql/connections.py", line 443, in _read_ok_packet
    pkt = self._read_packet()
  File "env/lib/python3.8/site-packages/pymysql/connections.py", line 725, in _read_packet
    packet.raise_for_error()
  File "env/lib/python3.8/site-packages/pymysql/protocol.py", line 221, in raise_for_error
    err.raise_mysql_exception(self._data)
  File "env/lib/python3.8/site-packages/pymysql/err.py", line 143, in raise_mysql_exception
    raise errorclass(errno, errval)
pymysql.err.OperationalError: (1049, "Unknown database '_c296b757cb15d301'")

2023-05-22 11:41:05,705 ERROR scheduler Exception in Enqueue Events for Site MyTrialERP.com
Traceback (most recent call last):
  File "apps/frappe/frappe/utils/scheduler.py", line 70, in enqueue_events_for_site
    if is_scheduler_inactive():
  File "apps/frappe/frappe/utils/scheduler.py", line 105, in is_scheduler_inactive
    if is_scheduler_disabled():
  File "apps/frappe/frappe/utils/scheduler.py", line 115, in is_scheduler_disabled
    return not frappe.utils.cint(frappe.db.get_single_value("System Settings", "enable_scheduler"))
  File "apps/frappe/frappe/database/database.py", line 684, in get_single_value
    val = self.sql(
  File "apps/frappe/frappe/database/database.py", line 161, in sql
    self.connect()
  File "apps/frappe/frappe/database/database.py", line 85, in connect
    self._conn = self.get_connection()
  File "apps/frappe/frappe/database/mariadb/database.py", line 92, in get_connection
    conn.select_db(self.user)
  File "env/lib/python3.8/site-packages/pymysql/connections.py", line 496, in select_db
    self._read_ok_packet()
  File "env/lib/python3.8/site-packages/pymysql/connections.py", line 443, in _read_ok_packet
    pkt = self._read_packet()
  File "env/lib/python3.8/site-packages/pymysql/connections.py", line 725, in _read_packet
    packet.raise_for_error()
  File "env/lib/python3.8/site-packages/pymysql/protocol.py", line 221, in raise_for_error
    err.raise_mysql_exception(self._data)
  File "env/lib/python3.8/site-packages/pymysql/err.py", line 143, in raise_mysql_exception
    raise errorclass(errno, errval)
pymysql.err.OperationalError: (1049, "Unknown database '_c296b757cb15d301'")

2023-05-22 11:42:05,946 ERROR scheduler Exception in Enqueue Events for Site MyTrialERP.com
Traceback (most recent call last):
  File "apps/frappe/frappe/utils/scheduler.py", line 70, in enqueue_events_for_site
    if is_scheduler_inactive():
  File "apps/frappe/frappe/utils/scheduler.py", line 105, in is_scheduler_inactive
    if is_scheduler_disabled():
  File "apps/frappe/frappe/utils/scheduler.py", line 115, in is_scheduler_disabled
    return not frappe.utils.cint(frappe.db.get_single_value("System Settings", "enable_scheduler"))
  File "apps/frappe/frappe/database/database.py", line 684, in get_single_value
    val = self.sql(
  File "apps/frappe/frappe/database/database.py", line 161, in sql
    self.connect()
  File "apps/frappe/frappe/database/database.py", line 85, in connect
    self._conn = self.get_connection()
  File "apps/frappe/frappe/database/mariadb/database.py", line 92, in get_connection
    conn.select_db(self.user)
  File "env/lib/python3.8/site-packages/pymysql/connections.py", line 496, in select_db
    self._read_ok_packet()
  File "env/lib/python3.8/site-packages/pymysql/connections.py", line 443, in _read_ok_packet
    pkt = self._read_packet()
  File "env/lib/python3.8/site-packages/pymysql/connections.py", line 725, in _read_packet
    packet.raise_for_error()
  File "env/lib/python3.8/site-packages/pymysql/protocol.py", line 221, in raise_for_error
    err.raise_mysql_exception(self._data)
  File "env/lib/python3.8/site-packages/pymysql/err.py", line 143, in raise_mysql_exception
    raise errorclass(errno, errval)
pymysql.err.OperationalError: (1049, "Unknown database '_c296b757cb15d301'")

2023-05-22 11:43:06,160 ERROR scheduler Exception in Enqueue Events for Site MyTrialERP.com
Traceback (most recent call last):
  File "apps/frappe/frappe/utils/scheduler.py", line 70, in enqueue_events_for_site
    if is_scheduler_inactive():
  File "apps/frappe/frappe/utils/scheduler.py", line 105, in is_scheduler_inactive
    if is_scheduler_disabled():
  File "apps/frappe/frappe/utils/scheduler.py", line 115, in is_scheduler_disabled
    return not frappe.utils.cint(frappe.db.get_single_value("System Settings", "enable_scheduler"))
  File "apps/frappe/frappe/database/database.py", line 684, in get_single_value
    val = self.sql(
  File "apps/frappe/frappe/database/database.py", line 161, in sql
    self.connect()
  File "apps/frappe/frappe/database/database.py", line 85, in connect
    self._conn = self.get_connection()
  File "apps/frappe/frappe/database/mariadb/database.py", line 92, in get_connection
    conn.select_db(self.user)
  File "env/lib/python3.8/site-packages/pymysql/connections.py", line 496, in select_db
    self._read_ok_packet()
  File "env/lib/python3.8/site-packages/pymysql/connections.py", line 443, in _read_ok_packet
    pkt = self._read_packet()
  File "env/lib/python3.8/site-packages/pymysql/connections.py", line 725, in _read_packet
    packet.raise_for_error()
  File "env/lib/python3.8/site-packages/pymysql/protocol.py", line 221, in raise_for_error
    err.raise_mysql_exception(self._data)
  File "env/lib/python3.8/site-packages/pymysql/err.py", line 143, in raise_mysql_exception
    raise errorclass(errno, errval)
pymysql.err.OperationalError: (1049, "Unknown database '_c296b757cb15d301'")

2023-05-22 11:44:06,479 ERROR scheduler Exception in Enqueue Events for Site MyTrialERP.com
Traceback (most recent call last):
  File "apps/frappe/frappe/utils/scheduler.py", line 70, in enqueue_events_for_site
    if is_scheduler_inactive():
  File "apps/frappe/frappe/utils/scheduler.py", line 105, in is_scheduler_inactive
    if is_scheduler_disabled():
  File "apps/frappe/frappe/utils/scheduler.py", line 115, in is_scheduler_disabled
    return not frappe.utils.cint(frappe.db.get_single_value("System Settings", "enable_scheduler"))
  File "apps/frappe/frappe/database/database.py", line 684, in get_single_value
    val = self.sql(
  File "apps/frappe/frappe/database/database.py", line 161, in sql
    self.connect()
  File "apps/frappe/frappe/database/database.py", line 85, in connect
    self._conn = self.get_connection()
  File "apps/frappe/frappe/database/mariadb/database.py", line 92, in get_connection
    conn.select_db(self.user)
  File "env/lib/python3.8/site-packages/pymysql/connections.py", line 496, in select_db
    self._read_ok_packet()
  File "env/lib/python3.8/site-packages/pymysql/connections.py", line 443, in _read_ok_packet
    pkt = self._read_packet()
  File "env/lib/python3.8/site-packages/pymysql/connections.py", line 725, in _read_packet
    packet.raise_for_error()
  File "env/lib/python3.8/site-packages/pymysql/protocol.py", line 221, in raise_for_error
    err.raise_mysql_exception(self._data)
  File "env/lib/python3.8/site-packages/pymysql/err.py", line 143, in raise_mysql_exception
    raise errorclass(errno, errval)
pymysql.err.OperationalError: (1049, "Unknown database '_c296b757cb15d301'")

2023-05-22 11:45:06,796 ERROR scheduler Exception in Enqueue Events for Site MyTrialERP.com
Traceback (most recent call last):
  File "apps/frappe/frappe/utils/scheduler.py", line 70, in enqueue_events_for_site
    if is_scheduler_inactive():
  File "apps/frappe/frappe/utils/scheduler.py", line 105, in is_scheduler_inactive
    if is_scheduler_disabled():
  File "apps/frappe/frappe/utils/scheduler.py", line 115, in is_scheduler_disabled
    return not frappe.utils.cint(frappe.db.get_single_value("System Settings", "enable_scheduler"))
  File "apps/frappe/frappe/database/database.py", line 684, in get_single_value
    val = self.sql(
  File "apps/frappe/frappe/database/database.py", line 161, in sql
    self.connect()
  File "apps/frappe/frappe/database/database.py", line 85, in connect
    self._conn = self.get_connection()
  File "apps/frappe/frappe/database/mariadb/database.py", line 92, in get_connection
    conn.select_db(self.user)
  File "env/lib/python3.8/site-packages/pymysql/connections.py", line 496, in select_db
    self._read_ok_packet()
  File "env/lib/python3.8/site-packages/pymysql/connections.py", line 443, in _read_ok_packet
    pkt = self._read_packet()
  File "env/lib/python3.8/site-packages/pymysql/connections.py", line 725, in _read_packet
    packet.raise_for_error()
  File "env/lib/python3.8/site-packages/pymysql/protocol.py", line 221, in raise_for_error
    err.raise_mysql_exception(self._data)
  File "env/lib/python3.8/site-packages/pymysql/err.py", line 143, in raise_mysql_exception
    raise errorclass(errno, errval)
pymysql.err.OperationalError: (1049, "Unknown database '_c296b757cb15d301'")

2023-05-22 11:46:07,091 ERROR scheduler Exception in Enqueue Events for Site MyTrialERP.com
Traceback (most recent call last):
  File "apps/frappe/frappe/utils/scheduler.py", line 70, in enqueue_events_for_site
    if is_scheduler_inactive():
  File "apps/frappe/frappe/utils/scheduler.py", line 105, in is_scheduler_inactive
    if is_scheduler_disabled():
  File "apps/frappe/frappe/utils/scheduler.py", line 115, in is_scheduler_disabled
    return not frappe.utils.cint(frappe.db.get_single_value("System Settings", "enable_scheduler"))
  File "apps/frappe/frappe/database/database.py", line 684, in get_single_value
    val = self.sql(
  File "apps/frappe/frappe/database/database.py", line 161, in sql
    self.connect()
  File "apps/frappe/frappe/database/database.py", line 85, in connect
    self._conn = self.get_connection()
  File "apps/frappe/frappe/database/mariadb/database.py", line 92, in get_connection
    conn.select_db(self.user)
  File "env/lib/python3.8/site-packages/pymysql/connections.py", line 496, in select_db
    self._read_ok_packet()
  File "env/lib/python3.8/site-packages/pymysql/connections.py", line 443, in _read_ok_packet
    pkt = self._read_packet()
  File "env/lib/python3.8/site-packages/pymysql/connections.py", line 725, in _read_packet
    packet.raise_for_error()
  File "env/lib/python3.8/site-packages/pymysql/protocol.py", line 221, in raise_for_error
    err.raise_mysql_exception(self._data)
  File "env/lib/python3.8/site-packages/pymysql/err.py", line 143, in raise_mysql_exception
    raise errorclass(errno, errval)
pymysql.err.OperationalError: (1049, "Unknown database '_c296b757cb15d301'")

2023-05-22 11:47:07,333 ERROR scheduler Exception in Enqueue Events for Site MyTrialERP.com
Traceback (most recent call last):
  File "apps/frappe/frappe/utils/scheduler.py", line 70, in enqueue_events_for_site
    if is_scheduler_inactive():
  File "apps/frappe/frappe/utils/scheduler.py", line 105, in is_scheduler_inactive
    if is_scheduler_disabled():
  File "apps/frappe/frappe/utils/scheduler.py", line 115, in is_scheduler_disabled
    return not frappe.utils.cint(frappe.db.get_single_value("System Settings", "enable_scheduler"))
  File "apps/frappe/frappe/database/database.py", line 684, in get_single_value
    val = self.sql(
  File "apps/frappe/frappe/database/database.py", line 161, in sql
    self.connect()
  File "apps/frappe/frappe/database/database.py", line 85, in connect
    self._conn = self.get_connection()
  File "apps/frappe/frappe/database/mariadb/database.py", line 92, in get_connection
    conn.select_db(self.user)
  File "env/lib/python3.8/site-packages/pymysql/connections.py", line 496, in select_db
    self._read_ok_packet()
  File "env/lib/python3.8/site-packages/pymysql/connections.py", line 443, in _read_ok_packet
    pkt = self._read_packet()
  File "env/lib/python3.8/site-packages/pymysql/connections.py", line 725, in _read_packet
    packet.raise_for_error()
  File "env/lib/python3.8/site-packages/pymysql/protocol.py", line 221, in raise_for_error
    err.raise_mysql_exception(self._data)
  File "env/lib/python3.8/site-packages/pymysql/err.py", line 143, in raise_mysql_exception
    raise errorclass(errno, errval)
pymysql.err.OperationalError: (1049, "Unknown database '_c296b757cb15d301'")

2023-05-22 11:48:07,578 ERROR scheduler Exception in Enqueue Events for Site MyTrialERP.com
Traceback (most recent call last):
  File "apps/frappe/frappe/utils/scheduler.py", line 70, in enqueue_events_for_site
    if is_scheduler_inactive():
  File "apps/frappe/frappe/utils/scheduler.py", line 105, in is_scheduler_inactive
    if is_scheduler_disabled():
  File "apps/frappe/frappe/utils/scheduler.py", line 115, in is_scheduler_disabled
    return not frappe.utils.cint(frappe.db.get_single_value("System Settings", "enable_scheduler"))
  File "apps/frappe/frappe/database/database.py", line 684, in get_single_value
    val = self.sql(
  File "apps/frappe/frappe/database/database.py", line 161, in sql
    self.connect()
  File "apps/frappe/frappe/database/database.py", line 85, in connect
    self._conn = self.get_connection()
  File "apps/frappe/frappe/database/mariadb/database.py", line 92, in get_connection
    conn.select_db(self.user)
  File "env/lib/python3.8/site-packages/pymysql/connections.py", line 496, in select_db
    self._read_ok_packet()
  File "env/lib/python3.8/site-packages/pymysql/connections.py", line 443, in _read_ok_packet
    pkt = self._read_packet()
  File "env/lib/python3.8/site-packages/pymysql/connections.py", line 725, in _read_packet
    packet.raise_for_error()
  File "env/lib/python3.8/site-packages/pymysql/protocol.py", line 221, in raise_for_error
    err.raise_mysql_exception(self._data)
  File "env/lib/python3.8/site-packages/pymysql/err.py", line 143, in raise_mysql_exception
    raise errorclass(errno, errval)
pymysql.err.OperationalError: (1049, "Unknown database '_c296b757cb15d301'")

2023-05-22 11:49:07,853 ERROR scheduler Exception in Enqueue Events for Site MyTrialERP.com
Traceback (most recent call last):
  File "apps/frappe/frappe/utils/scheduler.py", line 70, in enqueue_events_for_site
    if is_scheduler_inactive():
  File "apps/frappe/frappe/utils/scheduler.py", line 105, in is_scheduler_inactive
    if is_scheduler_disabled():
  File "apps/frappe/frappe/utils/scheduler.py", line 115, in is_scheduler_disabled
    return not frappe.utils.cint(frappe.db.get_single_value("System Settings", "enable_scheduler"))
  File "apps/frappe/frappe/database/database.py", line 684, in get_single_value
    val = self.sql(
  File "apps/frappe/frappe/database/database.py", line 161, in sql
    self.connect()
  File "apps/frappe/frappe/database/database.py", line 85, in connect
    self._conn = self.get_connection()
  File "apps/frappe/frappe/database/mariadb/database.py", line 92, in get_connection
    conn.select_db(self.user)
  File "env/lib/python3.8/site-packages/pymysql/connections.py", line 496, in select_db
    self._read_ok_packet()
  File "env/lib/python3.8/site-packages/pymysql/connections.py", line 443, in _read_ok_packet
    pkt = self._read_packet()
  File "env/lib/python3.8/site-packages/pymysql/connections.py", line 725, in _read_packet
    packet.raise_for_error()
  File "env/lib/python3.8/site-packages/pymysql/protocol.py", line 221, in raise_for_error
    err.raise_mysql_exception(self._data)
  File "env/lib/python3.8/site-packages/pymysql/err.py", line 143, in raise_mysql_exception
    raise errorclass(errno, errval)
pymysql.err.OperationalError: (1049, "Unknown database '_c296b757cb15d301'")

2023-05-22 11:50:08,096 ERROR scheduler Exception in Enqueue Events for Site MyTrialERP.com
Traceback (most recent call last):
  File "apps/frappe/frappe/utils/scheduler.py", line 70, in enqueue_events_for_site
    if is_scheduler_inactive():
  File "apps/frappe/frappe/utils/scheduler.py", line 105, in is_scheduler_inactive
    if is_scheduler_disabled():
  File "apps/frappe/frappe/utils/scheduler.py", line 115, in is_scheduler_disabled
    return not frappe.utils.cint(frappe.db.get_single_value("System Settings", "enable_scheduler"))
  File "apps/frappe/frappe/database/database.py", line 684, in get_single_value
    val = self.sql(
  File "apps/frappe/frappe/database/database.py", line 161, in sql
    self.connect()
  File "apps/frappe/frappe/database/database.py", line 85, in connect
    self._conn = self.get_connection()
  File "apps/frappe/frappe/database/mariadb/database.py", line 92, in get_connection
    conn.select_db(self.user)
  File "env/lib/python3.8/site-packages/pymysql/connections.py", line 496, in select_db
    self._read_ok_packet()
  File "env/lib/python3.8/site-packages/pymysql/connections.py", line 443, in _read_ok_packet
    pkt = self._read_packet()
  File "env/lib/python3.8/site-packages/pymysql/connections.py", line 725, in _read_packet
    packet.raise_for_error()
  File "env/lib/python3.8/site-packages/pymysql/protocol.py", line 221, in raise_for_error
    err.raise_mysql_exception(self._data)
  File "env/lib/python3.8/site-packages/pymysql/err.py", line 143, in raise_mysql_exception
    raise errorclass(errno, errval)
pymysql.err.OperationalError: (1049, "Unknown database '_c296b757cb15d301'")

2023-05-22 11:51:08,335 ERROR scheduler Exception in Enqueue Events for Site MyTrialERP.com
Traceback (most recent call last):
  File "apps/frappe/frappe/utils/scheduler.py", line 70, in enqueue_events_for_site
    if is_scheduler_inactive():
  File "apps/frappe/frappe/utils/scheduler.py", line 105, in is_scheduler_inactive
    if is_scheduler_disabled():
  File "apps/frappe/frappe/utils/scheduler.py", line 115, in is_scheduler_disabled
    return not frappe.utils.cint(frappe.db.get_single_value("System Settings", "enable_scheduler"))
  File "apps/frappe/frappe/database/database.py", line 684, in get_single_value
    val = self.sql(
  File "apps/frappe/frappe/database/database.py", line 161, in sql
    self.connect()
  File "apps/frappe/frappe/database/database.py", line 85, in connect
    self._conn = self.get_connection()
  File "apps/frappe/frappe/database/mariadb/database.py", line 92, in get_connection
    conn.select_db(self.user)
  File "env/lib/python3.8/site-packages/pymysql/connections.py", line 496, in select_db
    self._read_ok_packet()
  File "env/lib/python3.8/site-packages/pymysql/connections.py", line 443, in _read_ok_packet
    pkt = self._read_packet()
  File "env/lib/python3.8/site-packages/pymysql/connections.py", line 725, in _read_packet
    packet.raise_for_error()
  File "env/lib/python3.8/site-packages/pymysql/protocol.py", line 221, in raise_for_error
    err.raise_mysql_exception(self._data)
  File "env/lib/python3.8/site-packages/pymysql/err.py", line 143, in raise_mysql_exception
    raise errorclass(errno, errval)
pymysql.err.OperationalError: (1049, "Unknown database '_c296b757cb15d301'")

2023-05-22 11:52:08,668 ERROR scheduler Exception in Enqueue Events for Site MyTrialERP.com
Traceback (most recent call last):
  File "apps/frappe/frappe/utils/scheduler.py", line 70, in enqueue_events_for_site
    if is_scheduler_inactive():
  File "apps/frappe/frappe/utils/scheduler.py", line 105, in is_scheduler_inactive
    if is_scheduler_disabled():
  File "apps/frappe/frappe/utils/scheduler.py", line 115, in is_scheduler_disabled
    return not frappe.utils.cint(frappe.db.get_single_value("System Settings", "enable_scheduler"))
  File "apps/frappe/frappe/database/database.py", line 684, in get_single_value
    val = self.sql(
  File "apps/frappe/frappe/database/database.py", line 161, in sql
    self.connect()
  File "apps/frappe/frappe/database/database.py", line 85, in connect
    self._conn = self.get_connection()
  File "apps/frappe/frappe/database/mariadb/database.py", line 92, in get_connection
    conn.select_db(self.user)
  File "env/lib/python3.8/site-packages/pymysql/connections.py", line 496, in select_db
    self._read_ok_packet()
  File "env/lib/python3.8/site-packages/pymysql/connections.py", line 443, in _read_ok_packet
    pkt = self._read_packet()
  File "env/lib/python3.8/site-packages/pymysql/connections.py", line 725, in _read_packet
    packet.raise_for_error()
  File "env/lib/python3.8/site-packages/pymysql/protocol.py", line 221, in raise_for_error
    err.raise_mysql_exception(self._data)
  File "env/lib/python3.8/site-packages/pymysql/err.py", line 143, in raise_mysql_exception
    raise errorclass(errno, errval)
pymysql.err.OperationalError: (1049, "Unknown database '_c296b757cb15d301'")

2023-05-22 11:53:08,988 ERROR scheduler Exception in Enqueue Events for Site MyTrialERP.com
Traceback (most recent call last):
  File "apps/frappe/frappe/utils/scheduler.py", line 70, in enqueue_events_for_site
    if is_scheduler_inactive():
  File "apps/frappe/frappe/utils/scheduler.py", line 105, in is_scheduler_inactive
    if is_scheduler_disabled():
  File "apps/frappe/frappe/utils/scheduler.py", line 115, in is_scheduler_disabled
    return not frappe.utils.cint(frappe.db.get_single_value("System Settings", "enable_scheduler"))
  File "apps/frappe/frappe/database/database.py", line 684, in get_single_value
    val = self.sql(
  File "apps/frappe/frappe/database/database.py", line 161, in sql
    self.connect()
  File "apps/frappe/frappe/database/database.py", line 85, in connect
    self._conn = self.get_connection()
  File "apps/frappe/frappe/database/mariadb/database.py", line 92, in get_connection
    conn.select_db(self.user)
  File "env/lib/python3.8/site-packages/pymysql/connections.py", line 496, in select_db
    self._read_ok_packet()
  File "env/lib/python3.8/site-packages/pymysql/connections.py", line 443, in _read_ok_packet
    pkt = self._read_packet()
  File "env/lib/python3.8/site-packages/pymysql/connections.py", line 725, in _read_packet
    packet.raise_for_error()
  File "env/lib/python3.8/site-packages/pymysql/protocol.py", line 221, in raise_for_error
    err.raise_mysql_exception(self._data)
  File "env/lib/python3.8/site-packages/pymysql/err.py", line 143, in raise_mysql_exception
    raise errorclass(errno, errval)
pymysql.err.OperationalError: (1049, "Unknown database '_c296b757cb15d301'")

2023-05-22 11:54:09,377 ERROR scheduler Exception in Enqueue Events for Site MyTrialERP.com
Traceback (most recent call last):
  File "apps/frappe/frappe/utils/scheduler.py", line 70, in enqueue_events_for_site
    if is_scheduler_inactive():
  File "apps/frappe/frappe/utils/scheduler.py", line 105, in is_scheduler_inactive
    if is_scheduler_disabled():
  File "apps/frappe/frappe/utils/scheduler.py", line 115, in is_scheduler_disabled
    return not frappe.utils.cint(frappe.db.get_single_value("System Settings", "enable_scheduler"))
  File "apps/frappe/frappe/database/database.py", line 684, in get_single_value
    val = self.sql(
  File "apps/frappe/frappe/database/database.py", line 161, in sql
    self.connect()
  File "apps/frappe/frappe/database/database.py", line 85, in connect
    self._conn = self.get_connection()
  File "apps/frappe/frappe/database/mariadb/database.py", line 92, in get_connection
    conn.select_db(self.user)
  File "env/lib/python3.8/site-packages/pymysql/connections.py", line 496, in select_db
    self._read_ok_packet()
  File "env/lib/python3.8/site-packages/pymysql/connections.py", line 443, in _read_ok_packet
    pkt = self._read_packet()
  File "env/lib/python3.8/site-packages/pymysql/connections.py", line 725, in _read_packet
    packet.raise_for_error()
  File "env/lib/python3.8/site-packages/pymysql/protocol.py", line 221, in raise_for_error
    err.raise_mysql_exception(self._data)
  File "env/lib/python3.8/site-packages/pymysql/err.py", line 143, in raise_mysql_exception
    raise errorclass(errno, errval)
pymysql.err.OperationalError: (1049, "Unknown database '_c296b757cb15d301'")

2023-05-22 11:55:09,623 ERROR scheduler Exception in Enqueue Events for Site MyTrialERP.com
Traceback (most recent call last):
  File "apps/frappe/frappe/utils/scheduler.py", line 70, in enqueue_events_for_site
    if is_scheduler_inactive():
  File "apps/frappe/frappe/utils/scheduler.py", line 105, in is_scheduler_inactive
    if is_scheduler_disabled():
  File "apps/frappe/frappe/utils/scheduler.py", line 115, in is_scheduler_disabled
    return not frappe.utils.cint(frappe.db.get_single_value("System Settings", "enable_scheduler"))
  File "apps/frappe/frappe/database/database.py", line 684, in get_single_value
    val = self.sql(
  File "apps/frappe/frappe/database/database.py", line 161, in sql
    self.connect()
  File "apps/frappe/frappe/database/database.py", line 85, in connect
    self._conn = self.get_connection()
  File "apps/frappe/frappe/database/mariadb/database.py", line 92, in get_connection
    conn.select_db(self.user)
  File "env/lib/python3.8/site-packages/pymysql/connections.py", line 496, in select_db
    self._read_ok_packet()
  File "env/lib/python3.8/site-packages/pymysql/connections.py", line 443, in _read_ok_packet
    pkt = self._read_packet()
  File "env/lib/python3.8/site-packages/pymysql/connections.py", line 725, in _read_packet
    packet.raise_for_error()
  File "env/lib/python3.8/site-packages/pymysql/protocol.py", line 221, in raise_for_error
    err.raise_mysql_exception(self._data)
  File "env/lib/python3.8/site-packages/pymysql/err.py", line 143, in raise_mysql_exception
    raise errorclass(errno, errval)
pymysql.err.OperationalError: (1049, "Unknown database '_c296b757cb15d301'")

2023-05-22 11:56:09,869 ERROR scheduler Exception in Enqueue Events for Site MyTrialERP.com
Traceback (most recent call last):
  File "apps/frappe/frappe/utils/scheduler.py", line 70, in enqueue_events_for_site
    if is_scheduler_inactive():
  File "apps/frappe/frappe/utils/scheduler.py", line 105, in is_scheduler_inactive
    if is_scheduler_disabled():
  File "apps/frappe/frappe/utils/scheduler.py", line 115, in is_scheduler_disabled
    return not frappe.utils.cint(frappe.db.get_single_value("System Settings", "enable_scheduler"))
  File "apps/frappe/frappe/database/database.py", line 684, in get_single_value
    val = self.sql(
  File "apps/frappe/frappe/database/database.py", line 161, in sql
    self.connect()
  File "apps/frappe/frappe/database/database.py", line 85, in connect
    self._conn = self.get_connection()
  File "apps/frappe/frappe/database/mariadb/database.py", line 92, in get_connection
    conn.select_db(self.user)
  File "env/lib/python3.8/site-packages/pymysql/connections.py", line 496, in select_db
    self._read_ok_packet()
  File "env/lib/python3.8/site-packages/pymysql/connections.py", line 443, in _read_ok_packet
    pkt = self._read_packet()
  File "env/lib/python3.8/site-packages/pymysql/connections.py", line 725, in _read_packet
    packet.raise_for_error()
  File "env/lib/python3.8/site-packages/pymysql/protocol.py", line 221, in raise_for_error
    err.raise_mysql_exception(self._data)
  File "env/lib/python3.8/site-packages/pymysql/err.py", line 143, in raise_mysql_exception
    raise errorclass(errno, errval)
pymysql.err.OperationalError: (1049, "Unknown database '_c296b757cb15d301'")

2023-05-22 11:57:10,217 ERROR scheduler Exception in Enqueue Events for Site MyTrialERP.com
Traceback (most recent call last):
  File "apps/frappe/frappe/utils/scheduler.py", line 70, in enqueue_events_for_site
    if is_scheduler_inactive():
  File "apps/frappe/frappe/utils/scheduler.py", line 105, in is_scheduler_inactive
    if is_scheduler_disabled():
  File "apps/frappe/frappe/utils/scheduler.py", line 115, in is_scheduler_disabled
    return not frappe.utils.cint(frappe.db.get_single_value("System Settings", "enable_scheduler"))
  File "apps/frappe/frappe/database/database.py", line 684, in get_single_value
    val = self.sql(
  File "apps/frappe/frappe/database/database.py", line 161, in sql
    self.connect()
  File "apps/frappe/frappe/database/database.py", line 85, in connect
    self._conn = self.get_connection()
  File "apps/frappe/frappe/database/mariadb/database.py", line 92, in get_connection
    conn.select_db(self.user)
  File "env/lib/python3.8/site-packages/pymysql/connections.py", line 496, in select_db
    self._read_ok_packet()
  File "env/lib/python3.8/site-packages/pymysql/connections.py", line 443, in _read_ok_packet
    pkt = self._read_packet()
  File "env/lib/python3.8/site-packages/pymysql/connections.py", line 725, in _read_packet
    packet.raise_for_error()
  File "env/lib/python3.8/site-packages/pymysql/protocol.py", line 221, in raise_for_error
    err.raise_mysql_exception(self._data)
  File "env/lib/python3.8/site-packages/pymysql/err.py", line 143, in raise_mysql_exception
    raise errorclass(errno, errval)
pymysql.err.OperationalError: (1049, "Unknown database '_c296b757cb15d301'")

2023-05-22 11:58:10,580 ERROR scheduler Exception in Enqueue Events for Site MyTrialERP.com
Traceback (most recent call last):
  File "apps/frappe/frappe/utils/scheduler.py", line 70, in enqueue_events_for_site
    if is_scheduler_inactive():
  File "apps/frappe/frappe/utils/scheduler.py", line 105, in is_scheduler_inactive
    if is_scheduler_disabled():
  File "apps/frappe/frappe/utils/scheduler.py", line 115, in is_scheduler_disabled
    return not frappe.utils.cint(frappe.db.get_single_value("System Settings", "enable_scheduler"))
  File "apps/frappe/frappe/database/database.py", line 684, in get_single_value
    val = self.sql(
  File "apps/frappe/frappe/database/database.py", line 161, in sql
    self.connect()
  File "apps/frappe/frappe/database/database.py", line 85, in connect
    self._conn = self.get_connection()
  File "apps/frappe/frappe/database/mariadb/database.py", line 92, in get_connection
    conn.select_db(self.user)
  File "env/lib/python3.8/site-packages/pymysql/connections.py", line 496, in select_db
    self._read_ok_packet()
  File "env/lib/python3.8/site-packages/pymysql/connections.py", line 443, in _read_ok_packet
    pkt = self._read_packet()
  File "env/lib/python3.8/site-packages/pymysql/connections.py", line 725, in _read_packet
    packet.raise_for_error()
  File "env/lib/python3.8/site-packages/pymysql/protocol.py", line 221, in raise_for_error
    err.raise_mysql_exception(self._data)
  File "env/lib/python3.8/site-packages/pymysql/err.py", line 143, in raise_mysql_exception
    raise errorclass(errno, errval)
pymysql.err.OperationalError: (1049, "Unknown database '_c296b757cb15d301'")

2023-05-22 11:59:10,846 ERROR scheduler Exception in Enqueue Events for Site MyTrialERP.com
Traceback (most recent call last):
  File "apps/frappe/frappe/utils/scheduler.py", line 70, in enqueue_events_for_site
    if is_scheduler_inactive():
  File "apps/frappe/frappe/utils/scheduler.py", line 105, in is_scheduler_inactive
    if is_scheduler_disabled():
  File "apps/frappe/frappe/utils/scheduler.py", line 115, in is_scheduler_disabled
    return not frappe.utils.cint(frappe.db.get_single_value("System Settings", "enable_scheduler"))
  File "apps/frappe/frappe/database/database.py", line 684, in get_single_value
    val = self.sql(
  File "apps/frappe/frappe/database/database.py", line 161, in sql
    self.connect()
  File "apps/frappe/frappe/database/database.py", line 85, in connect
    self._conn = self.get_connection()
  File "apps/frappe/frappe/database/mariadb/database.py", line 92, in get_connection
    conn.select_db(self.user)
  File "env/lib/python3.8/site-packages/pymysql/connections.py", line 496, in select_db
    self._read_ok_packet()
  File "env/lib/python3.8/site-packages/pymysql/connections.py", line 443, in _read_ok_packet
    pkt = self._read_packet()
  File "env/lib/python3.8/site-packages/pymysql/connections.py", line 725, in _read_packet
    packet.raise_for_error()
  File "env/lib/python3.8/site-packages/pymysql/protocol.py", line 221, in raise_for_error
    err.raise_mysql_exception(self._data)
  File "env/lib/python3.8/site-packages/pymysql/err.py", line 143, in raise_mysql_exception
    raise errorclass(errno, errval)
pymysql.err.OperationalError: (1049, "Unknown database '_c296b757cb15d301'")

2023-05-22 12:00:11,089 ERROR scheduler Exception in Enqueue Events for Site MyTrialERP.com
Traceback (most recent call last):
  File "apps/frappe/frappe/utils/scheduler.py", line 70, in enqueue_events_for_site
    if is_scheduler_inactive():
  File "apps/frappe/frappe/utils/scheduler.py", line 105, in is_scheduler_inactive
    if is_scheduler_disabled():
  File "apps/frappe/frappe/utils/scheduler.py", line 115, in is_scheduler_disabled
    return not frappe.utils.cint(frappe.db.get_single_value("System Settings", "enable_scheduler"))
  File "apps/frappe/frappe/database/database.py", line 684, in get_single_value
    val = self.sql(
  File "apps/frappe/frappe/database/database.py", line 161, in sql
    self.connect()
  File "apps/frappe/frappe/database/database.py", line 85, in connect
    self._conn = self.get_connection()
  File "apps/frappe/frappe/database/mariadb/database.py", line 92, in get_connection
    conn.select_db(self.user)
  File "env/lib/python3.8/site-packages/pymysql/connections.py", line 496, in select_db
    self._read_ok_packet()
  File "env/lib/python3.8/site-packages/pymysql/connections.py", line 443, in _read_ok_packet
    pkt = self._read_packet()
  File "env/lib/python3.8/site-packages/pymysql/connections.py", line 725, in _read_packet
    packet.raise_for_error()
  File "env/lib/python3.8/site-packages/pymysql/protocol.py", line 221, in raise_for_error
    err.raise_mysql_exception(self._data)
  File "env/lib/python3.8/site-packages/pymysql/err.py", line 143, in raise_mysql_exception
    raise errorclass(errno, errval)
pymysql.err.OperationalError: (1049, "Unknown database '_c296b757cb15d301'")

2023-05-22 12:01:11,535 ERROR scheduler Exception in Enqueue Events for Site MyTrialERP.com
Traceback (most recent call last):
  File "apps/frappe/frappe/utils/scheduler.py", line 70, in enqueue_events_for_site
    if is_scheduler_inactive():
  File "apps/frappe/frappe/utils/scheduler.py", line 105, in is_scheduler_inactive
    if is_scheduler_disabled():
  File "apps/frappe/frappe/utils/scheduler.py", line 115, in is_scheduler_disabled
    return not frappe.utils.cint(frappe.db.get_single_value("System Settings", "enable_scheduler"))
  File "apps/frappe/frappe/database/database.py", line 684, in get_single_value
    val = self.sql(
  File "apps/frappe/frappe/database/database.py", line 161, in sql
    self.connect()
  File "apps/frappe/frappe/database/database.py", line 85, in connect
    self._conn = self.get_connection()
  File "apps/frappe/frappe/database/mariadb/database.py", line 92, in get_connection
    conn.select_db(self.user)
  File "env/lib/python3.8/site-packages/pymysql/connections.py", line 496, in select_db
    self._read_ok_packet()
  File "env/lib/python3.8/site-packages/pymysql/connections.py", line 443, in _read_ok_packet
    pkt = self._read_packet()
  File "env/lib/python3.8/site-packages/pymysql/connections.py", line 725, in _read_packet
    packet.raise_for_error()
  File "env/lib/python3.8/site-packages/pymysql/protocol.py", line 221, in raise_for_error
    err.raise_mysql_exception(self._data)
  File "env/lib/python3.8/site-packages/pymysql/err.py", line 143, in raise_mysql_exception
    raise errorclass(errno, errval)
pymysql.err.OperationalError: (1049, "Unknown database '_c296b757cb15d301'")

2023-05-22 12:02:11,797 ERROR scheduler Exception in Enqueue Events for Site MyTrialERP.com
Traceback (most recent call last):
  File "apps/frappe/frappe/utils/scheduler.py", line 70, in enqueue_events_for_site
    if is_scheduler_inactive():
  File "apps/frappe/frappe/utils/scheduler.py", line 105, in is_scheduler_inactive
    if is_scheduler_disabled():
  File "apps/frappe/frappe/utils/scheduler.py", line 115, in is_scheduler_disabled
    return not frappe.utils.cint(frappe.db.get_single_value("System Settings", "enable_scheduler"))
  File "apps/frappe/frappe/database/database.py", line 684, in get_single_value
    val = self.sql(
  File "apps/frappe/frappe/database/database.py", line 161, in sql
    self.connect()
  File "apps/frappe/frappe/database/database.py", line 85, in connect
    self._conn = self.get_connection()
  File "apps/frappe/frappe/database/mariadb/database.py", line 92, in get_connection
    conn.select_db(self.user)
  File "env/lib/python3.8/site-packages/pymysql/connections.py", line 496, in select_db
    self._read_ok_packet()
  File "env/lib/python3.8/site-packages/pymysql/connections.py", line 443, in _read_ok_packet
    pkt = self._read_packet()
  File "env/lib/python3.8/site-packages/pymysql/connections.py", line 725, in _read_packet
    packet.raise_for_error()
  File "env/lib/python3.8/site-packages/pymysql/protocol.py", line 221, in raise_for_error
    err.raise_mysql_exception(self._data)
  File "env/lib/python3.8/site-packages/pymysql/err.py", line 143, in raise_mysql_exception
    raise errorclass(errno, errval)
pymysql.err.OperationalError: (1049, "Unknown database '_c296b757cb15d301'")

2023-05-22 12:03:12,032 ERROR scheduler Exception in Enqueue Events for Site MyTrialERP.com
Traceback (most recent call last):
  File "apps/frappe/frappe/utils/scheduler.py", line 70, in enqueue_events_for_site
    if is_scheduler_inactive():
  File "apps/frappe/frappe/utils/scheduler.py", line 105, in is_scheduler_inactive
    if is_scheduler_disabled():
  File "apps/frappe/frappe/utils/scheduler.py", line 115, in is_scheduler_disabled
    return not frappe.utils.cint(frappe.db.get_single_value("System Settings", "enable_scheduler"))
  File "apps/frappe/frappe/database/database.py", line 684, in get_single_value
    val = self.sql(
  File "apps/frappe/frappe/database/database.py", line 161, in sql
    self.connect()
  File "apps/frappe/frappe/database/database.py", line 85, in connect
    self._conn = self.get_connection()
  File "apps/frappe/frappe/database/mariadb/database.py", line 92, in get_connection
    conn.select_db(self.user)
  File "env/lib/python3.8/site-packages/pymysql/connections.py", line 496, in select_db
    self._read_ok_packet()
  File "env/lib/python3.8/site-packages/pymysql/connections.py", line 443, in _read_ok_packet
    pkt = self._read_packet()
  File "env/lib/python3.8/site-packages/pymysql/connections.py", line 725, in _read_packet
    packet.raise_for_error()
  File "env/lib/python3.8/site-packages/pymysql/protocol.py", line 221, in raise_for_error
    err.raise_mysql_exception(self._data)
  File "env/lib/python3.8/site-packages/pymysql/err.py", line 143, in raise_mysql_exception
    raise errorclass(errno, errval)
pymysql.err.OperationalError: (1049, "Unknown database '_c296b757cb15d301'")

2023-05-22 12:04:12,311 ERROR scheduler Exception in Enqueue Events for Site MyTrialERP.com
Traceback (most recent call last):
  File "apps/frappe/frappe/utils/scheduler.py", line 70, in enqueue_events_for_site
    if is_scheduler_inactive():
  File "apps/frappe/frappe/utils/scheduler.py", line 105, in is_scheduler_inactive
    if is_scheduler_disabled():
  File "apps/frappe/frappe/utils/scheduler.py", line 115, in is_scheduler_disabled
    return not frappe.utils.cint(frappe.db.get_single_value("System Settings", "enable_scheduler"))
  File "apps/frappe/frappe/database/database.py", line 684, in get_single_value
    val = self.sql(
  File "apps/frappe/frappe/database/database.py", line 161, in sql
    self.connect()
  File "apps/frappe/frappe/database/database.py", line 85, in connect
    self._conn = self.get_connection()
  File "apps/frappe/frappe/database/mariadb/database.py", line 92, in get_connection
    conn.select_db(self.user)
  File "env/lib/python3.8/site-packages/pymysql/connections.py", line 496, in select_db
    self._read_ok_packet()
  File "env/lib/python3.8/site-packages/pymysql/connections.py", line 443, in _read_ok_packet
    pkt = self._read_packet()
  File "env/lib/python3.8/site-packages/pymysql/connections.py", line 725, in _read_packet
    packet.raise_for_error()
  File "env/lib/python3.8/site-packages/pymysql/protocol.py", line 221, in raise_for_error
    err.raise_mysql_exception(self._data)
  File "env/lib/python3.8/site-packages/pymysql/err.py", line 143, in raise_mysql_exception
    raise errorclass(errno, errval)
pymysql.err.OperationalError: (1049, "Unknown database '_c296b757cb15d301'")

2023-05-22 12:05:12,602 ERROR scheduler Exception in Enqueue Events for Site MyTrialERP.com
Traceback (most recent call last):
  File "apps/frappe/frappe/utils/scheduler.py", line 70, in enqueue_events_for_site
    if is_scheduler_inactive():
  File "apps/frappe/frappe/utils/scheduler.py", line 105, in is_scheduler_inactive
    if is_scheduler_disabled():
  File "apps/frappe/frappe/utils/scheduler.py", line 115, in is_scheduler_disabled
    return not frappe.utils.cint(frappe.db.get_single_value("System Settings", "enable_scheduler"))
  File "apps/frappe/frappe/database/database.py", line 684, in get_single_value
    val = self.sql(
  File "apps/frappe/frappe/database/database.py", line 161, in sql
    self.connect()
  File "apps/frappe/frappe/database/database.py", line 85, in connect
    self._conn = self.get_connection()
  File "apps/frappe/frappe/database/mariadb/database.py", line 92, in get_connection
    conn.select_db(self.user)
  File "env/lib/python3.8/site-packages/pymysql/connections.py", line 496, in select_db
    self._read_ok_packet()
  File "env/lib/python3.8/site-packages/pymysql/connections.py", line 443, in _read_ok_packet
    pkt = self._read_packet()
  File "env/lib/python3.8/site-packages/pymysql/connections.py", line 725, in _read_packet
    packet.raise_for_error()
  File "env/lib/python3.8/site-packages/pymysql/protocol.py", line 221, in raise_for_error
    err.raise_mysql_exception(self._data)
  File "env/lib/python3.8/site-packages/pymysql/err.py", line 143, in raise_mysql_exception
    raise errorclass(errno, errval)
pymysql.err.OperationalError: (1049, "Unknown database '_c296b757cb15d301'")

2023-05-22 12:06:12,859 ERROR scheduler Exception in Enqueue Events for Site MyTrialERP.com
Traceback (most recent call last):
  File "apps/frappe/frappe/utils/scheduler.py", line 70, in enqueue_events_for_site
    if is_scheduler_inactive():
  File "apps/frappe/frappe/utils/scheduler.py", line 105, in is_scheduler_inactive
    if is_scheduler_disabled():
  File "apps/frappe/frappe/utils/scheduler.py", line 115, in is_scheduler_disabled
    return not frappe.utils.cint(frappe.db.get_single_value("System Settings", "enable_scheduler"))
  File "apps/frappe/frappe/database/database.py", line 684, in get_single_value
    val = self.sql(
  File "apps/frappe/frappe/database/database.py", line 161, in sql
    self.connect()
  File "apps/frappe/frappe/database/database.py", line 85, in connect
    self._conn = self.get_connection()
  File "apps/frappe/frappe/database/mariadb/database.py", line 92, in get_connection
    conn.select_db(self.user)
  File "env/lib/python3.8/site-packages/pymysql/connections.py", line 496, in select_db
    self._read_ok_packet()
  File "env/lib/python3.8/site-packages/pymysql/connections.py", line 443, in _read_ok_packet
    pkt = self._read_packet()
  File "env/lib/python3.8/site-packages/pymysql/connections.py", line 725, in _read_packet
    packet.raise_for_error()
  File "env/lib/python3.8/site-packages/pymysql/protocol.py", line 221, in raise_for_error
    err.raise_mysql_exception(self._data)
  File "env/lib/python3.8/site-packages/pymysql/err.py", line 143, in raise_mysql_exception
    raise errorclass(errno, errval)
pymysql.err.OperationalError: (1049, "Unknown database '_c296b757cb15d301'")

2023-05-22 12:07:13,098 ERROR scheduler Exception in Enqueue Events for Site MyTrialERP.com
Traceback (most recent call last):
  File "apps/frappe/frappe/utils/scheduler.py", line 70, in enqueue_events_for_site
    if is_scheduler_inactive():
  File "apps/frappe/frappe/utils/scheduler.py", line 105, in is_scheduler_inactive
    if is_scheduler_disabled():
  File "apps/frappe/frappe/utils/scheduler.py", line 115, in is_scheduler_disabled
    return not frappe.utils.cint(frappe.db.get_single_value("System Settings", "enable_scheduler"))
  File "apps/frappe/frappe/database/database.py", line 684, in get_single_value
    val = self.sql(
  File "apps/frappe/frappe/database/database.py", line 161, in sql
    self.connect()
  File "apps/frappe/frappe/database/database.py", line 85, in connect
    self._conn = self.get_connection()
  File "apps/frappe/frappe/database/mariadb/database.py", line 92, in get_connection
    conn.select_db(self.user)
  File "env/lib/python3.8/site-packages/pymysql/connections.py", line 496, in select_db
    self._read_ok_packet()
  File "env/lib/python3.8/site-packages/pymysql/connections.py", line 443, in _read_ok_packet
    pkt = self._read_packet()
  File "env/lib/python3.8/site-packages/pymysql/connections.py", line 725, in _read_packet
    packet.raise_for_error()
  File "env/lib/python3.8/site-packages/pymysql/protocol.py", line 221, in raise_for_error
    err.raise_mysql_exception(self._data)
  File "env/lib/python3.8/site-packages/pymysql/err.py", line 143, in raise_mysql_exception
    raise errorclass(errno, errval)
pymysql.err.OperationalError: (1049, "Unknown database '_c296b757cb15d301'")

2023-05-22 12:08:13,324 ERROR scheduler Exception in Enqueue Events for Site MyTrialERP.com
Traceback (most recent call last):
  File "apps/frappe/frappe/utils/scheduler.py", line 70, in enqueue_events_for_site
    if is_scheduler_inactive():
  File "apps/frappe/frappe/utils/scheduler.py", line 105, in is_scheduler_inactive
    if is_scheduler_disabled():
  File "apps/frappe/frappe/utils/scheduler.py", line 115, in is_scheduler_disabled
    return not frappe.utils.cint(frappe.db.get_single_value("System Settings", "enable_scheduler"))
  File "apps/frappe/frappe/database/database.py", line 684, in get_single_value
    val = self.sql(
  File "apps/frappe/frappe/database/database.py", line 161, in sql
    self.connect()
  File "apps/frappe/frappe/database/database.py", line 85, in connect
    self._conn = self.get_connection()
  File "apps/frappe/frappe/database/mariadb/database.py", line 92, in get_connection
    conn.select_db(self.user)
  File "env/lib/python3.8/site-packages/pymysql/connections.py", line 496, in select_db
    self._read_ok_packet()
  File "env/lib/python3.8/site-packages/pymysql/connections.py", line 443, in _read_ok_packet
    pkt = self._read_packet()
  File "env/lib/python3.8/site-packages/pymysql/connections.py", line 725, in _read_packet
    packet.raise_for_error()
  File "env/lib/python3.8/site-packages/pymysql/protocol.py", line 221, in raise_for_error
    err.raise_mysql_exception(self._data)
  File "env/lib/python3.8/site-packages/pymysql/err.py", line 143, in raise_mysql_exception
    raise errorclass(errno, errval)
pymysql.err.OperationalError: (1049, "Unknown database '_c296b757cb15d301'")

2023-05-22 12:09:13,608 ERROR scheduler Exception in Enqueue Events for Site MyTrialERP.com
Traceback (most recent call last):
  File "apps/frappe/frappe/utils/scheduler.py", line 70, in enqueue_events_for_site
    if is_scheduler_inactive():
  File "apps/frappe/frappe/utils/scheduler.py", line 105, in is_scheduler_inactive
    if is_scheduler_disabled():
  File "apps/frappe/frappe/utils/scheduler.py", line 115, in is_scheduler_disabled
    return not frappe.utils.cint(frappe.db.get_single_value("System Settings", "enable_scheduler"))
  File "apps/frappe/frappe/database/database.py", line 684, in get_single_value
    val = self.sql(
  File "apps/frappe/frappe/database/database.py", line 161, in sql
    self.connect()
  File "apps/frappe/frappe/database/database.py", line 85, in connect
    self._conn = self.get_connection()
  File "apps/frappe/frappe/database/mariadb/database.py", line 92, in get_connection
    conn.select_db(self.user)
  File "env/lib/python3.8/site-packages/pymysql/connections.py", line 496, in select_db
    self._read_ok_packet()
  File "env/lib/python3.8/site-packages/pymysql/connections.py", line 443, in _read_ok_packet
    pkt = self._read_packet()
  File "env/lib/python3.8/site-packages/pymysql/connections.py", line 725, in _read_packet
    packet.raise_for_error()
  File "env/lib/python3.8/site-packages/pymysql/protocol.py", line 221, in raise_for_error
    err.raise_mysql_exception(self._data)
  File "env/lib/python3.8/site-packages/pymysql/err.py", line 143, in raise_mysql_exception
    raise errorclass(errno, errval)
pymysql.err.OperationalError: (1049, "Unknown database '_c296b757cb15d301'")

2023-05-22 12:10:13,895 ERROR scheduler Exception in Enqueue Events for Site MyTrialERP.com
Traceback (most recent call last):
  File "apps/frappe/frappe/utils/scheduler.py", line 70, in enqueue_events_for_site
    if is_scheduler_inactive():
  File "apps/frappe/frappe/utils/scheduler.py", line 105, in is_scheduler_inactive
    if is_scheduler_disabled():
  File "apps/frappe/frappe/utils/scheduler.py", line 115, in is_scheduler_disabled
    return not frappe.utils.cint(frappe.db.get_single_value("System Settings", "enable_scheduler"))
  File "apps/frappe/frappe/database/database.py", line 684, in get_single_value
    val = self.sql(
  File "apps/frappe/frappe/database/database.py", line 161, in sql
    self.connect()
  File "apps/frappe/frappe/database/database.py", line 85, in connect
    self._conn = self.get_connection()
  File "apps/frappe/frappe/database/mariadb/database.py", line 92, in get_connection
    conn.select_db(self.user)
  File "env/lib/python3.8/site-packages/pymysql/connections.py", line 496, in select_db
    self._read_ok_packet()
  File "env/lib/python3.8/site-packages/pymysql/connections.py", line 443, in _read_ok_packet
    pkt = self._read_packet()
  File "env/lib/python3.8/site-packages/pymysql/connections.py", line 725, in _read_packet
    packet.raise_for_error()
  File "env/lib/python3.8/site-packages/pymysql/protocol.py", line 221, in raise_for_error
    err.raise_mysql_exception(self._data)
  File "env/lib/python3.8/site-packages/pymysql/err.py", line 143, in raise_mysql_exception
    raise errorclass(errno, errval)
pymysql.err.OperationalError: (1049, "Unknown database '_c296b757cb15d301'")

2023-05-22 12:11:14,158 ERROR scheduler Exception in Enqueue Events for Site MyTrialERP.com
Traceback (most recent call last):
  File "apps/frappe/frappe/utils/scheduler.py", line 70, in enqueue_events_for_site
    if is_scheduler_inactive():
  File "apps/frappe/frappe/utils/scheduler.py", line 105, in is_scheduler_inactive
    if is_scheduler_disabled():
  File "apps/frappe/frappe/utils/scheduler.py", line 115, in is_scheduler_disabled
    return not frappe.utils.cint(frappe.db.get_single_value("System Settings", "enable_scheduler"))
  File "apps/frappe/frappe/database/database.py", line 684, in get_single_value
    val = self.sql(
  File "apps/frappe/frappe/database/database.py", line 161, in sql
    self.connect()
  File "apps/frappe/frappe/database/database.py", line 85, in connect
    self._conn = self.get_connection()
  File "apps/frappe/frappe/database/mariadb/database.py", line 92, in get_connection
    conn.select_db(self.user)
  File "env/lib/python3.8/site-packages/pymysql/connections.py", line 496, in select_db
    self._read_ok_packet()
  File "env/lib/python3.8/site-packages/pymysql/connections.py", line 443, in _read_ok_packet
    pkt = self._read_packet()
  File "env/lib/python3.8/site-packages/pymysql/connections.py", line 725, in _read_packet
    packet.raise_for_error()
  File "env/lib/python3.8/site-packages/pymysql/protocol.py", line 221, in raise_for_error
    err.raise_mysql_exception(self._data)
  File "env/lib/python3.8/site-packages/pymysql/err.py", line 143, in raise_mysql_exception
    raise errorclass(errno, errval)
pymysql.err.OperationalError: (1049, "Unknown database '_c296b757cb15d301'")

2023-05-22 12:12:14,389 ERROR scheduler Exception in Enqueue Events for Site MyTrialERP.com
Traceback (most recent call last):
  File "apps/frappe/frappe/utils/scheduler.py", line 70, in enqueue_events_for_site
    if is_scheduler_inactive():
  File "apps/frappe/frappe/utils/scheduler.py", line 105, in is_scheduler_inactive
    if is_scheduler_disabled():
  File "apps/frappe/frappe/utils/scheduler.py", line 115, in is_scheduler_disabled
    return not frappe.utils.cint(frappe.db.get_single_value("System Settings", "enable_scheduler"))
  File "apps/frappe/frappe/database/database.py", line 684, in get_single_value
    val = self.sql(
  File "apps/frappe/frappe/database/database.py", line 161, in sql
    self.connect()
  File "apps/frappe/frappe/database/database.py", line 85, in connect
    self._conn = self.get_connection()
  File "apps/frappe/frappe/database/mariadb/database.py", line 92, in get_connection
    conn.select_db(self.user)
  File "env/lib/python3.8/site-packages/pymysql/connections.py", line 496, in select_db
    self._read_ok_packet()
  File "env/lib/python3.8/site-packages/pymysql/connections.py", line 443, in _read_ok_packet
    pkt = self._read_packet()
  File "env/lib/python3.8/site-packages/pymysql/connections.py", line 725, in _read_packet
    packet.raise_for_error()
  File "env/lib/python3.8/site-packages/pymysql/protocol.py", line 221, in raise_for_error
    err.raise_mysql_exception(self._data)
  File "env/lib/python3.8/site-packages/pymysql/err.py", line 143, in raise_mysql_exception
    raise errorclass(errno, errval)
pymysql.err.OperationalError: (1049, "Unknown database '_c296b757cb15d301'")

