2023-05-21 10:47:32,053 ERROR scheduler Exception in Enqueue Events for Site MyTrialERP.com
Traceback (most recent call last):
  File "apps/frappe/frappe/utils/scheduler.py", line 70, in enqueue_events_for_site
    if is_scheduler_inactive():
  File "apps/frappe/frappe/utils/scheduler.py", line 105, in is_scheduler_inactive
    if is_scheduler_disabled():
  File "apps/frappe/frappe/utils/scheduler.py", line 115, in is_scheduler_disabled
    return not frappe.utils.cint(frappe.db.get_single_value("System Settings", "enable_scheduler"))
  File "apps/frappe/frappe/database/database.py", line 684, in get_single_value
    val = self.sql(
  File "apps/frappe/frappe/database/database.py", line 161, in sql
    self.connect()
  File "apps/frappe/frappe/database/database.py", line 85, in connect
    self._conn = self.get_connection()
  File "apps/frappe/frappe/database/mariadb/database.py", line 92, in get_connection
    conn.select_db(self.user)
  File "env/lib/python3.8/site-packages/pymysql/connections.py", line 496, in select_db
    self._read_ok_packet()
  File "env/lib/python3.8/site-packages/pymysql/connections.py", line 443, in _read_ok_packet
    pkt = self._read_packet()
  File "env/lib/python3.8/site-packages/pymysql/connections.py", line 725, in _read_packet
    packet.raise_for_error()
  File "env/lib/python3.8/site-packages/pymysql/protocol.py", line 221, in raise_for_error
    err.raise_mysql_exception(self._data)
  File "env/lib/python3.8/site-packages/pymysql/err.py", line 143, in raise_mysql_exception
    raise errorclass(errno, errval)
pymysql.err.OperationalError: (1049, "Unknown database '_c296b757cb15d301'")

