2023-05-20 10:01:17,554 ERROR scheduler Exception in Enqueue Events for Site MyTrialERP.com
Traceback (most recent call last):
  File "apps/frappe/frappe/utils/scheduler.py", line 70, in enqueue_events_for_site
    if is_scheduler_inactive():
  File "apps/frappe/frappe/utils/scheduler.py", line 105, in is_scheduler_inactive
    if is_scheduler_disabled():
  File "apps/frappe/frappe/utils/scheduler.py", line 115, in is_scheduler_disabled
    return not frappe.utils.cint(frappe.db.get_single_value("System Settings", "enable_scheduler"))
  File "apps/frappe/frappe/database/database.py", line 684, in get_single_value
    val = self.sql(
  File "apps/frappe/frappe/database/database.py", line 161, in sql
    self.connect()
  File "apps/frappe/frappe/database/database.py", line 85, in connect
    self._conn = self.get_connection()
  File "apps/frappe/frappe/database/mariadb/database.py", line 92, in get_connection
    conn.select_db(self.user)
  File "env/lib/python3.8/site-packages/pymysql/connections.py", line 496, in select_db
    self._read_ok_packet()
  File "env/lib/python3.8/site-packages/pymysql/connections.py", line 443, in _read_ok_packet
    pkt = self._read_packet()
  File "env/lib/python3.8/site-packages/pymysql/connections.py", line 725, in _read_packet
    packet.raise_for_error()
  File "env/lib/python3.8/site-packages/pymysql/protocol.py", line 221, in raise_for_error
    err.raise_mysql_exception(self._data)
  File "env/lib/python3.8/site-packages/pymysql/err.py", line 143, in raise_mysql_exception
    raise errorclass(errno, errval)
pymysql.err.OperationalError: (1049, "Unknown database '_c296b757cb15d301'")

2023-05-20 10:02:18,467 ERROR scheduler Exception in Enqueue Events for Site MyTrialERP.com
Traceback (most recent call last):
  File "apps/frappe/frappe/utils/scheduler.py", line 70, in enqueue_events_for_site
    if is_scheduler_inactive():
  File "apps/frappe/frappe/utils/scheduler.py", line 105, in is_scheduler_inactive
    if is_scheduler_disabled():
  File "apps/frappe/frappe/utils/scheduler.py", line 115, in is_scheduler_disabled
    return not frappe.utils.cint(frappe.db.get_single_value("System Settings", "enable_scheduler"))
  File "apps/frappe/frappe/database/database.py", line 684, in get_single_value
    val = self.sql(
  File "apps/frappe/frappe/database/database.py", line 161, in sql
    self.connect()
  File "apps/frappe/frappe/database/database.py", line 85, in connect
    self._conn = self.get_connection()
  File "apps/frappe/frappe/database/mariadb/database.py", line 92, in get_connection
    conn.select_db(self.user)
  File "env/lib/python3.8/site-packages/pymysql/connections.py", line 496, in select_db
    self._read_ok_packet()
  File "env/lib/python3.8/site-packages/pymysql/connections.py", line 443, in _read_ok_packet
    pkt = self._read_packet()
  File "env/lib/python3.8/site-packages/pymysql/connections.py", line 725, in _read_packet
    packet.raise_for_error()
  File "env/lib/python3.8/site-packages/pymysql/protocol.py", line 221, in raise_for_error
    err.raise_mysql_exception(self._data)
  File "env/lib/python3.8/site-packages/pymysql/err.py", line 143, in raise_mysql_exception
    raise errorclass(errno, errval)
pymysql.err.OperationalError: (1049, "Unknown database '_c296b757cb15d301'")

2023-05-20 10:03:18,735 ERROR scheduler Exception in Enqueue Events for Site MyTrialERP.com
Traceback (most recent call last):
  File "apps/frappe/frappe/utils/scheduler.py", line 70, in enqueue_events_for_site
    if is_scheduler_inactive():
  File "apps/frappe/frappe/utils/scheduler.py", line 105, in is_scheduler_inactive
    if is_scheduler_disabled():
  File "apps/frappe/frappe/utils/scheduler.py", line 115, in is_scheduler_disabled
    return not frappe.utils.cint(frappe.db.get_single_value("System Settings", "enable_scheduler"))
  File "apps/frappe/frappe/database/database.py", line 684, in get_single_value
    val = self.sql(
  File "apps/frappe/frappe/database/database.py", line 161, in sql
    self.connect()
  File "apps/frappe/frappe/database/database.py", line 85, in connect
    self._conn = self.get_connection()
  File "apps/frappe/frappe/database/mariadb/database.py", line 92, in get_connection
    conn.select_db(self.user)
  File "env/lib/python3.8/site-packages/pymysql/connections.py", line 496, in select_db
    self._read_ok_packet()
  File "env/lib/python3.8/site-packages/pymysql/connections.py", line 443, in _read_ok_packet
    pkt = self._read_packet()
  File "env/lib/python3.8/site-packages/pymysql/connections.py", line 725, in _read_packet
    packet.raise_for_error()
  File "env/lib/python3.8/site-packages/pymysql/protocol.py", line 221, in raise_for_error
    err.raise_mysql_exception(self._data)
  File "env/lib/python3.8/site-packages/pymysql/err.py", line 143, in raise_mysql_exception
    raise errorclass(errno, errval)
pymysql.err.OperationalError: (1049, "Unknown database '_c296b757cb15d301'")

2023-05-20 10:04:18,990 ERROR scheduler Exception in Enqueue Events for Site MyTrialERP.com
Traceback (most recent call last):
  File "apps/frappe/frappe/utils/scheduler.py", line 70, in enqueue_events_for_site
    if is_scheduler_inactive():
  File "apps/frappe/frappe/utils/scheduler.py", line 105, in is_scheduler_inactive
    if is_scheduler_disabled():
  File "apps/frappe/frappe/utils/scheduler.py", line 115, in is_scheduler_disabled
    return not frappe.utils.cint(frappe.db.get_single_value("System Settings", "enable_scheduler"))
  File "apps/frappe/frappe/database/database.py", line 684, in get_single_value
    val = self.sql(
  File "apps/frappe/frappe/database/database.py", line 161, in sql
    self.connect()
  File "apps/frappe/frappe/database/database.py", line 85, in connect
    self._conn = self.get_connection()
  File "apps/frappe/frappe/database/mariadb/database.py", line 92, in get_connection
    conn.select_db(self.user)
  File "env/lib/python3.8/site-packages/pymysql/connections.py", line 496, in select_db
    self._read_ok_packet()
  File "env/lib/python3.8/site-packages/pymysql/connections.py", line 443, in _read_ok_packet
    pkt = self._read_packet()
  File "env/lib/python3.8/site-packages/pymysql/connections.py", line 725, in _read_packet
    packet.raise_for_error()
  File "env/lib/python3.8/site-packages/pymysql/protocol.py", line 221, in raise_for_error
    err.raise_mysql_exception(self._data)
  File "env/lib/python3.8/site-packages/pymysql/err.py", line 143, in raise_mysql_exception
    raise errorclass(errno, errval)
pymysql.err.OperationalError: (1049, "Unknown database '_c296b757cb15d301'")

2023-05-20 10:05:19,296 ERROR scheduler Exception in Enqueue Events for Site MyTrialERP.com
Traceback (most recent call last):
  File "apps/frappe/frappe/utils/scheduler.py", line 70, in enqueue_events_for_site
    if is_scheduler_inactive():
  File "apps/frappe/frappe/utils/scheduler.py", line 105, in is_scheduler_inactive
    if is_scheduler_disabled():
  File "apps/frappe/frappe/utils/scheduler.py", line 115, in is_scheduler_disabled
    return not frappe.utils.cint(frappe.db.get_single_value("System Settings", "enable_scheduler"))
  File "apps/frappe/frappe/database/database.py", line 684, in get_single_value
    val = self.sql(
  File "apps/frappe/frappe/database/database.py", line 161, in sql
    self.connect()
  File "apps/frappe/frappe/database/database.py", line 85, in connect
    self._conn = self.get_connection()
  File "apps/frappe/frappe/database/mariadb/database.py", line 92, in get_connection
    conn.select_db(self.user)
  File "env/lib/python3.8/site-packages/pymysql/connections.py", line 496, in select_db
    self._read_ok_packet()
  File "env/lib/python3.8/site-packages/pymysql/connections.py", line 443, in _read_ok_packet
    pkt = self._read_packet()
  File "env/lib/python3.8/site-packages/pymysql/connections.py", line 725, in _read_packet
    packet.raise_for_error()
  File "env/lib/python3.8/site-packages/pymysql/protocol.py", line 221, in raise_for_error
    err.raise_mysql_exception(self._data)
  File "env/lib/python3.8/site-packages/pymysql/err.py", line 143, in raise_mysql_exception
    raise errorclass(errno, errval)
pymysql.err.OperationalError: (1049, "Unknown database '_c296b757cb15d301'")

2023-05-20 10:06:19,626 ERROR scheduler Exception in Enqueue Events for Site MyTrialERP.com
Traceback (most recent call last):
  File "apps/frappe/frappe/utils/scheduler.py", line 70, in enqueue_events_for_site
    if is_scheduler_inactive():
  File "apps/frappe/frappe/utils/scheduler.py", line 105, in is_scheduler_inactive
    if is_scheduler_disabled():
  File "apps/frappe/frappe/utils/scheduler.py", line 115, in is_scheduler_disabled
    return not frappe.utils.cint(frappe.db.get_single_value("System Settings", "enable_scheduler"))
  File "apps/frappe/frappe/database/database.py", line 684, in get_single_value
    val = self.sql(
  File "apps/frappe/frappe/database/database.py", line 161, in sql
    self.connect()
  File "apps/frappe/frappe/database/database.py", line 85, in connect
    self._conn = self.get_connection()
  File "apps/frappe/frappe/database/mariadb/database.py", line 92, in get_connection
    conn.select_db(self.user)
  File "env/lib/python3.8/site-packages/pymysql/connections.py", line 496, in select_db
    self._read_ok_packet()
  File "env/lib/python3.8/site-packages/pymysql/connections.py", line 443, in _read_ok_packet
    pkt = self._read_packet()
  File "env/lib/python3.8/site-packages/pymysql/connections.py", line 725, in _read_packet
    packet.raise_for_error()
  File "env/lib/python3.8/site-packages/pymysql/protocol.py", line 221, in raise_for_error
    err.raise_mysql_exception(self._data)
  File "env/lib/python3.8/site-packages/pymysql/err.py", line 143, in raise_mysql_exception
    raise errorclass(errno, errval)
pymysql.err.OperationalError: (1049, "Unknown database '_c296b757cb15d301'")

2023-05-20 10:07:19,894 ERROR scheduler Exception in Enqueue Events for Site MyTrialERP.com
Traceback (most recent call last):
  File "apps/frappe/frappe/utils/scheduler.py", line 70, in enqueue_events_for_site
    if is_scheduler_inactive():
  File "apps/frappe/frappe/utils/scheduler.py", line 105, in is_scheduler_inactive
    if is_scheduler_disabled():
  File "apps/frappe/frappe/utils/scheduler.py", line 115, in is_scheduler_disabled
    return not frappe.utils.cint(frappe.db.get_single_value("System Settings", "enable_scheduler"))
  File "apps/frappe/frappe/database/database.py", line 684, in get_single_value
    val = self.sql(
  File "apps/frappe/frappe/database/database.py", line 161, in sql
    self.connect()
  File "apps/frappe/frappe/database/database.py", line 85, in connect
    self._conn = self.get_connection()
  File "apps/frappe/frappe/database/mariadb/database.py", line 92, in get_connection
    conn.select_db(self.user)
  File "env/lib/python3.8/site-packages/pymysql/connections.py", line 496, in select_db
    self._read_ok_packet()
  File "env/lib/python3.8/site-packages/pymysql/connections.py", line 443, in _read_ok_packet
    pkt = self._read_packet()
  File "env/lib/python3.8/site-packages/pymysql/connections.py", line 725, in _read_packet
    packet.raise_for_error()
  File "env/lib/python3.8/site-packages/pymysql/protocol.py", line 221, in raise_for_error
    err.raise_mysql_exception(self._data)
  File "env/lib/python3.8/site-packages/pymysql/err.py", line 143, in raise_mysql_exception
    raise errorclass(errno, errval)
pymysql.err.OperationalError: (1049, "Unknown database '_c296b757cb15d301'")

2023-05-20 10:08:20,167 ERROR scheduler Exception in Enqueue Events for Site MyTrialERP.com
Traceback (most recent call last):
  File "apps/frappe/frappe/utils/scheduler.py", line 70, in enqueue_events_for_site
    if is_scheduler_inactive():
  File "apps/frappe/frappe/utils/scheduler.py", line 105, in is_scheduler_inactive
    if is_scheduler_disabled():
  File "apps/frappe/frappe/utils/scheduler.py", line 115, in is_scheduler_disabled
    return not frappe.utils.cint(frappe.db.get_single_value("System Settings", "enable_scheduler"))
  File "apps/frappe/frappe/database/database.py", line 684, in get_single_value
    val = self.sql(
  File "apps/frappe/frappe/database/database.py", line 161, in sql
    self.connect()
  File "apps/frappe/frappe/database/database.py", line 85, in connect
    self._conn = self.get_connection()
  File "apps/frappe/frappe/database/mariadb/database.py", line 92, in get_connection
    conn.select_db(self.user)
  File "env/lib/python3.8/site-packages/pymysql/connections.py", line 496, in select_db
    self._read_ok_packet()
  File "env/lib/python3.8/site-packages/pymysql/connections.py", line 443, in _read_ok_packet
    pkt = self._read_packet()
  File "env/lib/python3.8/site-packages/pymysql/connections.py", line 725, in _read_packet
    packet.raise_for_error()
  File "env/lib/python3.8/site-packages/pymysql/protocol.py", line 221, in raise_for_error
    err.raise_mysql_exception(self._data)
  File "env/lib/python3.8/site-packages/pymysql/err.py", line 143, in raise_mysql_exception
    raise errorclass(errno, errval)
pymysql.err.OperationalError: (1049, "Unknown database '_c296b757cb15d301'")

2023-05-20 10:09:20,570 ERROR scheduler Exception in Enqueue Events for Site MyTrialERP.com
Traceback (most recent call last):
  File "apps/frappe/frappe/utils/scheduler.py", line 70, in enqueue_events_for_site
    if is_scheduler_inactive():
  File "apps/frappe/frappe/utils/scheduler.py", line 105, in is_scheduler_inactive
    if is_scheduler_disabled():
  File "apps/frappe/frappe/utils/scheduler.py", line 115, in is_scheduler_disabled
    return not frappe.utils.cint(frappe.db.get_single_value("System Settings", "enable_scheduler"))
  File "apps/frappe/frappe/database/database.py", line 684, in get_single_value
    val = self.sql(
  File "apps/frappe/frappe/database/database.py", line 161, in sql
    self.connect()
  File "apps/frappe/frappe/database/database.py", line 85, in connect
    self._conn = self.get_connection()
  File "apps/frappe/frappe/database/mariadb/database.py", line 92, in get_connection
    conn.select_db(self.user)
  File "env/lib/python3.8/site-packages/pymysql/connections.py", line 496, in select_db
    self._read_ok_packet()
  File "env/lib/python3.8/site-packages/pymysql/connections.py", line 443, in _read_ok_packet
    pkt = self._read_packet()
  File "env/lib/python3.8/site-packages/pymysql/connections.py", line 725, in _read_packet
    packet.raise_for_error()
  File "env/lib/python3.8/site-packages/pymysql/protocol.py", line 221, in raise_for_error
    err.raise_mysql_exception(self._data)
  File "env/lib/python3.8/site-packages/pymysql/err.py", line 143, in raise_mysql_exception
    raise errorclass(errno, errval)
pymysql.err.OperationalError: (1049, "Unknown database '_c296b757cb15d301'")

2023-05-20 10:10:20,882 ERROR scheduler Exception in Enqueue Events for Site MyTrialERP.com
Traceback (most recent call last):
  File "apps/frappe/frappe/utils/scheduler.py", line 70, in enqueue_events_for_site
    if is_scheduler_inactive():
  File "apps/frappe/frappe/utils/scheduler.py", line 105, in is_scheduler_inactive
    if is_scheduler_disabled():
  File "apps/frappe/frappe/utils/scheduler.py", line 115, in is_scheduler_disabled
    return not frappe.utils.cint(frappe.db.get_single_value("System Settings", "enable_scheduler"))
  File "apps/frappe/frappe/database/database.py", line 684, in get_single_value
    val = self.sql(
  File "apps/frappe/frappe/database/database.py", line 161, in sql
    self.connect()
  File "apps/frappe/frappe/database/database.py", line 85, in connect
    self._conn = self.get_connection()
  File "apps/frappe/frappe/database/mariadb/database.py", line 92, in get_connection
    conn.select_db(self.user)
  File "env/lib/python3.8/site-packages/pymysql/connections.py", line 496, in select_db
    self._read_ok_packet()
  File "env/lib/python3.8/site-packages/pymysql/connections.py", line 443, in _read_ok_packet
    pkt = self._read_packet()
  File "env/lib/python3.8/site-packages/pymysql/connections.py", line 725, in _read_packet
    packet.raise_for_error()
  File "env/lib/python3.8/site-packages/pymysql/protocol.py", line 221, in raise_for_error
    err.raise_mysql_exception(self._data)
  File "env/lib/python3.8/site-packages/pymysql/err.py", line 143, in raise_mysql_exception
    raise errorclass(errno, errval)
pymysql.err.OperationalError: (1049, "Unknown database '_c296b757cb15d301'")

2023-05-20 10:11:21,183 ERROR scheduler Exception in Enqueue Events for Site MyTrialERP.com
Traceback (most recent call last):
  File "apps/frappe/frappe/utils/scheduler.py", line 70, in enqueue_events_for_site
    if is_scheduler_inactive():
  File "apps/frappe/frappe/utils/scheduler.py", line 105, in is_scheduler_inactive
    if is_scheduler_disabled():
  File "apps/frappe/frappe/utils/scheduler.py", line 115, in is_scheduler_disabled
    return not frappe.utils.cint(frappe.db.get_single_value("System Settings", "enable_scheduler"))
  File "apps/frappe/frappe/database/database.py", line 684, in get_single_value
    val = self.sql(
  File "apps/frappe/frappe/database/database.py", line 161, in sql
    self.connect()
  File "apps/frappe/frappe/database/database.py", line 85, in connect
    self._conn = self.get_connection()
  File "apps/frappe/frappe/database/mariadb/database.py", line 92, in get_connection
    conn.select_db(self.user)
  File "env/lib/python3.8/site-packages/pymysql/connections.py", line 496, in select_db
    self._read_ok_packet()
  File "env/lib/python3.8/site-packages/pymysql/connections.py", line 443, in _read_ok_packet
    pkt = self._read_packet()
  File "env/lib/python3.8/site-packages/pymysql/connections.py", line 725, in _read_packet
    packet.raise_for_error()
  File "env/lib/python3.8/site-packages/pymysql/protocol.py", line 221, in raise_for_error
    err.raise_mysql_exception(self._data)
  File "env/lib/python3.8/site-packages/pymysql/err.py", line 143, in raise_mysql_exception
    raise errorclass(errno, errval)
pymysql.err.OperationalError: (1049, "Unknown database '_c296b757cb15d301'")

2023-05-20 10:12:21,495 ERROR scheduler Exception in Enqueue Events for Site MyTrialERP.com
Traceback (most recent call last):
  File "apps/frappe/frappe/utils/scheduler.py", line 70, in enqueue_events_for_site
    if is_scheduler_inactive():
  File "apps/frappe/frappe/utils/scheduler.py", line 105, in is_scheduler_inactive
    if is_scheduler_disabled():
  File "apps/frappe/frappe/utils/scheduler.py", line 115, in is_scheduler_disabled
    return not frappe.utils.cint(frappe.db.get_single_value("System Settings", "enable_scheduler"))
  File "apps/frappe/frappe/database/database.py", line 684, in get_single_value
    val = self.sql(
  File "apps/frappe/frappe/database/database.py", line 161, in sql
    self.connect()
  File "apps/frappe/frappe/database/database.py", line 85, in connect
    self._conn = self.get_connection()
  File "apps/frappe/frappe/database/mariadb/database.py", line 92, in get_connection
    conn.select_db(self.user)
  File "env/lib/python3.8/site-packages/pymysql/connections.py", line 496, in select_db
    self._read_ok_packet()
  File "env/lib/python3.8/site-packages/pymysql/connections.py", line 443, in _read_ok_packet
    pkt = self._read_packet()
  File "env/lib/python3.8/site-packages/pymysql/connections.py", line 725, in _read_packet
    packet.raise_for_error()
  File "env/lib/python3.8/site-packages/pymysql/protocol.py", line 221, in raise_for_error
    err.raise_mysql_exception(self._data)
  File "env/lib/python3.8/site-packages/pymysql/err.py", line 143, in raise_mysql_exception
    raise errorclass(errno, errval)
pymysql.err.OperationalError: (1049, "Unknown database '_c296b757cb15d301'")

2023-05-20 10:13:21,885 ERROR scheduler Exception in Enqueue Events for Site MyTrialERP.com
Traceback (most recent call last):
  File "apps/frappe/frappe/utils/scheduler.py", line 70, in enqueue_events_for_site
    if is_scheduler_inactive():
  File "apps/frappe/frappe/utils/scheduler.py", line 105, in is_scheduler_inactive
    if is_scheduler_disabled():
  File "apps/frappe/frappe/utils/scheduler.py", line 115, in is_scheduler_disabled
    return not frappe.utils.cint(frappe.db.get_single_value("System Settings", "enable_scheduler"))
  File "apps/frappe/frappe/database/database.py", line 684, in get_single_value
    val = self.sql(
  File "apps/frappe/frappe/database/database.py", line 161, in sql
    self.connect()
  File "apps/frappe/frappe/database/database.py", line 85, in connect
    self._conn = self.get_connection()
  File "apps/frappe/frappe/database/mariadb/database.py", line 92, in get_connection
    conn.select_db(self.user)
  File "env/lib/python3.8/site-packages/pymysql/connections.py", line 496, in select_db
    self._read_ok_packet()
  File "env/lib/python3.8/site-packages/pymysql/connections.py", line 443, in _read_ok_packet
    pkt = self._read_packet()
  File "env/lib/python3.8/site-packages/pymysql/connections.py", line 725, in _read_packet
    packet.raise_for_error()
  File "env/lib/python3.8/site-packages/pymysql/protocol.py", line 221, in raise_for_error
    err.raise_mysql_exception(self._data)
  File "env/lib/python3.8/site-packages/pymysql/err.py", line 143, in raise_mysql_exception
    raise errorclass(errno, errval)
pymysql.err.OperationalError: (1049, "Unknown database '_c296b757cb15d301'")

2023-05-20 10:14:22,130 ERROR scheduler Exception in Enqueue Events for Site MyTrialERP.com
Traceback (most recent call last):
  File "apps/frappe/frappe/utils/scheduler.py", line 70, in enqueue_events_for_site
    if is_scheduler_inactive():
  File "apps/frappe/frappe/utils/scheduler.py", line 105, in is_scheduler_inactive
    if is_scheduler_disabled():
  File "apps/frappe/frappe/utils/scheduler.py", line 115, in is_scheduler_disabled
    return not frappe.utils.cint(frappe.db.get_single_value("System Settings", "enable_scheduler"))
  File "apps/frappe/frappe/database/database.py", line 684, in get_single_value
    val = self.sql(
  File "apps/frappe/frappe/database/database.py", line 161, in sql
    self.connect()
  File "apps/frappe/frappe/database/database.py", line 85, in connect
    self._conn = self.get_connection()
  File "apps/frappe/frappe/database/mariadb/database.py", line 92, in get_connection
    conn.select_db(self.user)
  File "env/lib/python3.8/site-packages/pymysql/connections.py", line 496, in select_db
    self._read_ok_packet()
  File "env/lib/python3.8/site-packages/pymysql/connections.py", line 443, in _read_ok_packet
    pkt = self._read_packet()
  File "env/lib/python3.8/site-packages/pymysql/connections.py", line 725, in _read_packet
    packet.raise_for_error()
  File "env/lib/python3.8/site-packages/pymysql/protocol.py", line 221, in raise_for_error
    err.raise_mysql_exception(self._data)
  File "env/lib/python3.8/site-packages/pymysql/err.py", line 143, in raise_mysql_exception
    raise errorclass(errno, errval)
pymysql.err.OperationalError: (1049, "Unknown database '_c296b757cb15d301'")

2023-05-20 10:15:22,412 ERROR scheduler Exception in Enqueue Events for Site MyTrialERP.com
Traceback (most recent call last):
  File "apps/frappe/frappe/utils/scheduler.py", line 70, in enqueue_events_for_site
    if is_scheduler_inactive():
  File "apps/frappe/frappe/utils/scheduler.py", line 105, in is_scheduler_inactive
    if is_scheduler_disabled():
  File "apps/frappe/frappe/utils/scheduler.py", line 115, in is_scheduler_disabled
    return not frappe.utils.cint(frappe.db.get_single_value("System Settings", "enable_scheduler"))
  File "apps/frappe/frappe/database/database.py", line 684, in get_single_value
    val = self.sql(
  File "apps/frappe/frappe/database/database.py", line 161, in sql
    self.connect()
  File "apps/frappe/frappe/database/database.py", line 85, in connect
    self._conn = self.get_connection()
  File "apps/frappe/frappe/database/mariadb/database.py", line 92, in get_connection
    conn.select_db(self.user)
  File "env/lib/python3.8/site-packages/pymysql/connections.py", line 496, in select_db
    self._read_ok_packet()
  File "env/lib/python3.8/site-packages/pymysql/connections.py", line 443, in _read_ok_packet
    pkt = self._read_packet()
  File "env/lib/python3.8/site-packages/pymysql/connections.py", line 725, in _read_packet
    packet.raise_for_error()
  File "env/lib/python3.8/site-packages/pymysql/protocol.py", line 221, in raise_for_error
    err.raise_mysql_exception(self._data)
  File "env/lib/python3.8/site-packages/pymysql/err.py", line 143, in raise_mysql_exception
    raise errorclass(errno, errval)
pymysql.err.OperationalError: (1049, "Unknown database '_c296b757cb15d301'")

2023-05-20 10:16:22,737 ERROR scheduler Exception in Enqueue Events for Site MyTrialERP.com
Traceback (most recent call last):
  File "apps/frappe/frappe/utils/scheduler.py", line 70, in enqueue_events_for_site
    if is_scheduler_inactive():
  File "apps/frappe/frappe/utils/scheduler.py", line 105, in is_scheduler_inactive
    if is_scheduler_disabled():
  File "apps/frappe/frappe/utils/scheduler.py", line 115, in is_scheduler_disabled
    return not frappe.utils.cint(frappe.db.get_single_value("System Settings", "enable_scheduler"))
  File "apps/frappe/frappe/database/database.py", line 684, in get_single_value
    val = self.sql(
  File "apps/frappe/frappe/database/database.py", line 161, in sql
    self.connect()
  File "apps/frappe/frappe/database/database.py", line 85, in connect
    self._conn = self.get_connection()
  File "apps/frappe/frappe/database/mariadb/database.py", line 92, in get_connection
    conn.select_db(self.user)
  File "env/lib/python3.8/site-packages/pymysql/connections.py", line 496, in select_db
    self._read_ok_packet()
  File "env/lib/python3.8/site-packages/pymysql/connections.py", line 443, in _read_ok_packet
    pkt = self._read_packet()
  File "env/lib/python3.8/site-packages/pymysql/connections.py", line 725, in _read_packet
    packet.raise_for_error()
  File "env/lib/python3.8/site-packages/pymysql/protocol.py", line 221, in raise_for_error
    err.raise_mysql_exception(self._data)
  File "env/lib/python3.8/site-packages/pymysql/err.py", line 143, in raise_mysql_exception
    raise errorclass(errno, errval)
pymysql.err.OperationalError: (1049, "Unknown database '_c296b757cb15d301'")

2023-05-20 10:17:23,108 ERROR scheduler Exception in Enqueue Events for Site MyTrialERP.com
Traceback (most recent call last):
  File "apps/frappe/frappe/utils/scheduler.py", line 70, in enqueue_events_for_site
    if is_scheduler_inactive():
  File "apps/frappe/frappe/utils/scheduler.py", line 105, in is_scheduler_inactive
    if is_scheduler_disabled():
  File "apps/frappe/frappe/utils/scheduler.py", line 115, in is_scheduler_disabled
    return not frappe.utils.cint(frappe.db.get_single_value("System Settings", "enable_scheduler"))
  File "apps/frappe/frappe/database/database.py", line 684, in get_single_value
    val = self.sql(
  File "apps/frappe/frappe/database/database.py", line 161, in sql
    self.connect()
  File "apps/frappe/frappe/database/database.py", line 85, in connect
    self._conn = self.get_connection()
  File "apps/frappe/frappe/database/mariadb/database.py", line 92, in get_connection
    conn.select_db(self.user)
  File "env/lib/python3.8/site-packages/pymysql/connections.py", line 496, in select_db
    self._read_ok_packet()
  File "env/lib/python3.8/site-packages/pymysql/connections.py", line 443, in _read_ok_packet
    pkt = self._read_packet()
  File "env/lib/python3.8/site-packages/pymysql/connections.py", line 725, in _read_packet
    packet.raise_for_error()
  File "env/lib/python3.8/site-packages/pymysql/protocol.py", line 221, in raise_for_error
    err.raise_mysql_exception(self._data)
  File "env/lib/python3.8/site-packages/pymysql/err.py", line 143, in raise_mysql_exception
    raise errorclass(errno, errval)
pymysql.err.OperationalError: (1049, "Unknown database '_c296b757cb15d301'")

2023-05-20 10:18:23,453 ERROR scheduler Exception in Enqueue Events for Site MyTrialERP.com
Traceback (most recent call last):
  File "apps/frappe/frappe/utils/scheduler.py", line 70, in enqueue_events_for_site
    if is_scheduler_inactive():
  File "apps/frappe/frappe/utils/scheduler.py", line 105, in is_scheduler_inactive
    if is_scheduler_disabled():
  File "apps/frappe/frappe/utils/scheduler.py", line 115, in is_scheduler_disabled
    return not frappe.utils.cint(frappe.db.get_single_value("System Settings", "enable_scheduler"))
  File "apps/frappe/frappe/database/database.py", line 684, in get_single_value
    val = self.sql(
  File "apps/frappe/frappe/database/database.py", line 161, in sql
    self.connect()
  File "apps/frappe/frappe/database/database.py", line 85, in connect
    self._conn = self.get_connection()
  File "apps/frappe/frappe/database/mariadb/database.py", line 92, in get_connection
    conn.select_db(self.user)
  File "env/lib/python3.8/site-packages/pymysql/connections.py", line 496, in select_db
    self._read_ok_packet()
  File "env/lib/python3.8/site-packages/pymysql/connections.py", line 443, in _read_ok_packet
    pkt = self._read_packet()
  File "env/lib/python3.8/site-packages/pymysql/connections.py", line 725, in _read_packet
    packet.raise_for_error()
  File "env/lib/python3.8/site-packages/pymysql/protocol.py", line 221, in raise_for_error
    err.raise_mysql_exception(self._data)
  File "env/lib/python3.8/site-packages/pymysql/err.py", line 143, in raise_mysql_exception
    raise errorclass(errno, errval)
pymysql.err.OperationalError: (1049, "Unknown database '_c296b757cb15d301'")

2023-05-20 10:19:23,800 ERROR scheduler Exception in Enqueue Events for Site MyTrialERP.com
Traceback (most recent call last):
  File "apps/frappe/frappe/utils/scheduler.py", line 70, in enqueue_events_for_site
    if is_scheduler_inactive():
  File "apps/frappe/frappe/utils/scheduler.py", line 105, in is_scheduler_inactive
    if is_scheduler_disabled():
  File "apps/frappe/frappe/utils/scheduler.py", line 115, in is_scheduler_disabled
    return not frappe.utils.cint(frappe.db.get_single_value("System Settings", "enable_scheduler"))
  File "apps/frappe/frappe/database/database.py", line 684, in get_single_value
    val = self.sql(
  File "apps/frappe/frappe/database/database.py", line 161, in sql
    self.connect()
  File "apps/frappe/frappe/database/database.py", line 85, in connect
    self._conn = self.get_connection()
  File "apps/frappe/frappe/database/mariadb/database.py", line 92, in get_connection
    conn.select_db(self.user)
  File "env/lib/python3.8/site-packages/pymysql/connections.py", line 496, in select_db
    self._read_ok_packet()
  File "env/lib/python3.8/site-packages/pymysql/connections.py", line 443, in _read_ok_packet
    pkt = self._read_packet()
  File "env/lib/python3.8/site-packages/pymysql/connections.py", line 725, in _read_packet
    packet.raise_for_error()
  File "env/lib/python3.8/site-packages/pymysql/protocol.py", line 221, in raise_for_error
    err.raise_mysql_exception(self._data)
  File "env/lib/python3.8/site-packages/pymysql/err.py", line 143, in raise_mysql_exception
    raise errorclass(errno, errval)
pymysql.err.OperationalError: (1049, "Unknown database '_c296b757cb15d301'")

2023-05-20 10:20:24,040 ERROR scheduler Exception in Enqueue Events for Site MyTrialERP.com
Traceback (most recent call last):
  File "apps/frappe/frappe/utils/scheduler.py", line 70, in enqueue_events_for_site
    if is_scheduler_inactive():
  File "apps/frappe/frappe/utils/scheduler.py", line 105, in is_scheduler_inactive
    if is_scheduler_disabled():
  File "apps/frappe/frappe/utils/scheduler.py", line 115, in is_scheduler_disabled
    return not frappe.utils.cint(frappe.db.get_single_value("System Settings", "enable_scheduler"))
  File "apps/frappe/frappe/database/database.py", line 684, in get_single_value
    val = self.sql(
  File "apps/frappe/frappe/database/database.py", line 161, in sql
    self.connect()
  File "apps/frappe/frappe/database/database.py", line 85, in connect
    self._conn = self.get_connection()
  File "apps/frappe/frappe/database/mariadb/database.py", line 92, in get_connection
    conn.select_db(self.user)
  File "env/lib/python3.8/site-packages/pymysql/connections.py", line 496, in select_db
    self._read_ok_packet()
  File "env/lib/python3.8/site-packages/pymysql/connections.py", line 443, in _read_ok_packet
    pkt = self._read_packet()
  File "env/lib/python3.8/site-packages/pymysql/connections.py", line 725, in _read_packet
    packet.raise_for_error()
  File "env/lib/python3.8/site-packages/pymysql/protocol.py", line 221, in raise_for_error
    err.raise_mysql_exception(self._data)
  File "env/lib/python3.8/site-packages/pymysql/err.py", line 143, in raise_mysql_exception
    raise errorclass(errno, errval)
pymysql.err.OperationalError: (1049, "Unknown database '_c296b757cb15d301'")

2023-05-20 10:21:24,450 ERROR scheduler Exception in Enqueue Events for Site MyTrialERP.com
Traceback (most recent call last):
  File "apps/frappe/frappe/utils/scheduler.py", line 70, in enqueue_events_for_site
    if is_scheduler_inactive():
  File "apps/frappe/frappe/utils/scheduler.py", line 105, in is_scheduler_inactive
    if is_scheduler_disabled():
  File "apps/frappe/frappe/utils/scheduler.py", line 115, in is_scheduler_disabled
    return not frappe.utils.cint(frappe.db.get_single_value("System Settings", "enable_scheduler"))
  File "apps/frappe/frappe/database/database.py", line 684, in get_single_value
    val = self.sql(
  File "apps/frappe/frappe/database/database.py", line 161, in sql
    self.connect()
  File "apps/frappe/frappe/database/database.py", line 85, in connect
    self._conn = self.get_connection()
  File "apps/frappe/frappe/database/mariadb/database.py", line 92, in get_connection
    conn.select_db(self.user)
  File "env/lib/python3.8/site-packages/pymysql/connections.py", line 496, in select_db
    self._read_ok_packet()
  File "env/lib/python3.8/site-packages/pymysql/connections.py", line 443, in _read_ok_packet
    pkt = self._read_packet()
  File "env/lib/python3.8/site-packages/pymysql/connections.py", line 725, in _read_packet
    packet.raise_for_error()
  File "env/lib/python3.8/site-packages/pymysql/protocol.py", line 221, in raise_for_error
    err.raise_mysql_exception(self._data)
  File "env/lib/python3.8/site-packages/pymysql/err.py", line 143, in raise_mysql_exception
    raise errorclass(errno, errval)
pymysql.err.OperationalError: (1049, "Unknown database '_c296b757cb15d301'")

2023-05-20 10:22:24,720 ERROR scheduler Exception in Enqueue Events for Site MyTrialERP.com
Traceback (most recent call last):
  File "apps/frappe/frappe/utils/scheduler.py", line 70, in enqueue_events_for_site
    if is_scheduler_inactive():
  File "apps/frappe/frappe/utils/scheduler.py", line 105, in is_scheduler_inactive
    if is_scheduler_disabled():
  File "apps/frappe/frappe/utils/scheduler.py", line 115, in is_scheduler_disabled
    return not frappe.utils.cint(frappe.db.get_single_value("System Settings", "enable_scheduler"))
  File "apps/frappe/frappe/database/database.py", line 684, in get_single_value
    val = self.sql(
  File "apps/frappe/frappe/database/database.py", line 161, in sql
    self.connect()
  File "apps/frappe/frappe/database/database.py", line 85, in connect
    self._conn = self.get_connection()
  File "apps/frappe/frappe/database/mariadb/database.py", line 92, in get_connection
    conn.select_db(self.user)
  File "env/lib/python3.8/site-packages/pymysql/connections.py", line 496, in select_db
    self._read_ok_packet()
  File "env/lib/python3.8/site-packages/pymysql/connections.py", line 443, in _read_ok_packet
    pkt = self._read_packet()
  File "env/lib/python3.8/site-packages/pymysql/connections.py", line 725, in _read_packet
    packet.raise_for_error()
  File "env/lib/python3.8/site-packages/pymysql/protocol.py", line 221, in raise_for_error
    err.raise_mysql_exception(self._data)
  File "env/lib/python3.8/site-packages/pymysql/err.py", line 143, in raise_mysql_exception
    raise errorclass(errno, errval)
pymysql.err.OperationalError: (1049, "Unknown database '_c296b757cb15d301'")

2023-05-20 10:23:24,978 ERROR scheduler Exception in Enqueue Events for Site MyTrialERP.com
Traceback (most recent call last):
  File "apps/frappe/frappe/utils/scheduler.py", line 70, in enqueue_events_for_site
    if is_scheduler_inactive():
  File "apps/frappe/frappe/utils/scheduler.py", line 105, in is_scheduler_inactive
    if is_scheduler_disabled():
  File "apps/frappe/frappe/utils/scheduler.py", line 115, in is_scheduler_disabled
    return not frappe.utils.cint(frappe.db.get_single_value("System Settings", "enable_scheduler"))
  File "apps/frappe/frappe/database/database.py", line 684, in get_single_value
    val = self.sql(
  File "apps/frappe/frappe/database/database.py", line 161, in sql
    self.connect()
  File "apps/frappe/frappe/database/database.py", line 85, in connect
    self._conn = self.get_connection()
  File "apps/frappe/frappe/database/mariadb/database.py", line 92, in get_connection
    conn.select_db(self.user)
  File "env/lib/python3.8/site-packages/pymysql/connections.py", line 496, in select_db
    self._read_ok_packet()
  File "env/lib/python3.8/site-packages/pymysql/connections.py", line 443, in _read_ok_packet
    pkt = self._read_packet()
  File "env/lib/python3.8/site-packages/pymysql/connections.py", line 725, in _read_packet
    packet.raise_for_error()
  File "env/lib/python3.8/site-packages/pymysql/protocol.py", line 221, in raise_for_error
    err.raise_mysql_exception(self._data)
  File "env/lib/python3.8/site-packages/pymysql/err.py", line 143, in raise_mysql_exception
    raise errorclass(errno, errval)
pymysql.err.OperationalError: (1049, "Unknown database '_c296b757cb15d301'")

2023-05-20 10:24:25,224 ERROR scheduler Exception in Enqueue Events for Site MyTrialERP.com
Traceback (most recent call last):
  File "apps/frappe/frappe/utils/scheduler.py", line 70, in enqueue_events_for_site
    if is_scheduler_inactive():
  File "apps/frappe/frappe/utils/scheduler.py", line 105, in is_scheduler_inactive
    if is_scheduler_disabled():
  File "apps/frappe/frappe/utils/scheduler.py", line 115, in is_scheduler_disabled
    return not frappe.utils.cint(frappe.db.get_single_value("System Settings", "enable_scheduler"))
  File "apps/frappe/frappe/database/database.py", line 684, in get_single_value
    val = self.sql(
  File "apps/frappe/frappe/database/database.py", line 161, in sql
    self.connect()
  File "apps/frappe/frappe/database/database.py", line 85, in connect
    self._conn = self.get_connection()
  File "apps/frappe/frappe/database/mariadb/database.py", line 92, in get_connection
    conn.select_db(self.user)
  File "env/lib/python3.8/site-packages/pymysql/connections.py", line 496, in select_db
    self._read_ok_packet()
  File "env/lib/python3.8/site-packages/pymysql/connections.py", line 443, in _read_ok_packet
    pkt = self._read_packet()
  File "env/lib/python3.8/site-packages/pymysql/connections.py", line 725, in _read_packet
    packet.raise_for_error()
  File "env/lib/python3.8/site-packages/pymysql/protocol.py", line 221, in raise_for_error
    err.raise_mysql_exception(self._data)
  File "env/lib/python3.8/site-packages/pymysql/err.py", line 143, in raise_mysql_exception
    raise errorclass(errno, errval)
pymysql.err.OperationalError: (1049, "Unknown database '_c296b757cb15d301'")

2023-05-20 10:25:25,577 ERROR scheduler Exception in Enqueue Events for Site MyTrialERP.com
Traceback (most recent call last):
  File "apps/frappe/frappe/utils/scheduler.py", line 70, in enqueue_events_for_site
    if is_scheduler_inactive():
  File "apps/frappe/frappe/utils/scheduler.py", line 105, in is_scheduler_inactive
    if is_scheduler_disabled():
  File "apps/frappe/frappe/utils/scheduler.py", line 115, in is_scheduler_disabled
    return not frappe.utils.cint(frappe.db.get_single_value("System Settings", "enable_scheduler"))
  File "apps/frappe/frappe/database/database.py", line 684, in get_single_value
    val = self.sql(
  File "apps/frappe/frappe/database/database.py", line 161, in sql
    self.connect()
  File "apps/frappe/frappe/database/database.py", line 85, in connect
    self._conn = self.get_connection()
  File "apps/frappe/frappe/database/mariadb/database.py", line 92, in get_connection
    conn.select_db(self.user)
  File "env/lib/python3.8/site-packages/pymysql/connections.py", line 496, in select_db
    self._read_ok_packet()
  File "env/lib/python3.8/site-packages/pymysql/connections.py", line 443, in _read_ok_packet
    pkt = self._read_packet()
  File "env/lib/python3.8/site-packages/pymysql/connections.py", line 725, in _read_packet
    packet.raise_for_error()
  File "env/lib/python3.8/site-packages/pymysql/protocol.py", line 221, in raise_for_error
    err.raise_mysql_exception(self._data)
  File "env/lib/python3.8/site-packages/pymysql/err.py", line 143, in raise_mysql_exception
    raise errorclass(errno, errval)
pymysql.err.OperationalError: (1049, "Unknown database '_c296b757cb15d301'")

2023-05-20 10:26:25,902 ERROR scheduler Exception in Enqueue Events for Site MyTrialERP.com
Traceback (most recent call last):
  File "apps/frappe/frappe/utils/scheduler.py", line 70, in enqueue_events_for_site
    if is_scheduler_inactive():
  File "apps/frappe/frappe/utils/scheduler.py", line 105, in is_scheduler_inactive
    if is_scheduler_disabled():
  File "apps/frappe/frappe/utils/scheduler.py", line 115, in is_scheduler_disabled
    return not frappe.utils.cint(frappe.db.get_single_value("System Settings", "enable_scheduler"))
  File "apps/frappe/frappe/database/database.py", line 684, in get_single_value
    val = self.sql(
  File "apps/frappe/frappe/database/database.py", line 161, in sql
    self.connect()
  File "apps/frappe/frappe/database/database.py", line 85, in connect
    self._conn = self.get_connection()
  File "apps/frappe/frappe/database/mariadb/database.py", line 92, in get_connection
    conn.select_db(self.user)
  File "env/lib/python3.8/site-packages/pymysql/connections.py", line 496, in select_db
    self._read_ok_packet()
  File "env/lib/python3.8/site-packages/pymysql/connections.py", line 443, in _read_ok_packet
    pkt = self._read_packet()
  File "env/lib/python3.8/site-packages/pymysql/connections.py", line 725, in _read_packet
    packet.raise_for_error()
  File "env/lib/python3.8/site-packages/pymysql/protocol.py", line 221, in raise_for_error
    err.raise_mysql_exception(self._data)
  File "env/lib/python3.8/site-packages/pymysql/err.py", line 143, in raise_mysql_exception
    raise errorclass(errno, errval)
pymysql.err.OperationalError: (1049, "Unknown database '_c296b757cb15d301'")

2023-05-20 10:27:26,184 ERROR scheduler Exception in Enqueue Events for Site MyTrialERP.com
Traceback (most recent call last):
  File "apps/frappe/frappe/utils/scheduler.py", line 70, in enqueue_events_for_site
    if is_scheduler_inactive():
  File "apps/frappe/frappe/utils/scheduler.py", line 105, in is_scheduler_inactive
    if is_scheduler_disabled():
  File "apps/frappe/frappe/utils/scheduler.py", line 115, in is_scheduler_disabled
    return not frappe.utils.cint(frappe.db.get_single_value("System Settings", "enable_scheduler"))
  File "apps/frappe/frappe/database/database.py", line 684, in get_single_value
    val = self.sql(
  File "apps/frappe/frappe/database/database.py", line 161, in sql
    self.connect()
  File "apps/frappe/frappe/database/database.py", line 85, in connect
    self._conn = self.get_connection()
  File "apps/frappe/frappe/database/mariadb/database.py", line 92, in get_connection
    conn.select_db(self.user)
  File "env/lib/python3.8/site-packages/pymysql/connections.py", line 496, in select_db
    self._read_ok_packet()
  File "env/lib/python3.8/site-packages/pymysql/connections.py", line 443, in _read_ok_packet
    pkt = self._read_packet()
  File "env/lib/python3.8/site-packages/pymysql/connections.py", line 725, in _read_packet
    packet.raise_for_error()
  File "env/lib/python3.8/site-packages/pymysql/protocol.py", line 221, in raise_for_error
    err.raise_mysql_exception(self._data)
  File "env/lib/python3.8/site-packages/pymysql/err.py", line 143, in raise_mysql_exception
    raise errorclass(errno, errval)
pymysql.err.OperationalError: (1049, "Unknown database '_c296b757cb15d301'")

2023-05-20 10:28:26,447 ERROR scheduler Exception in Enqueue Events for Site MyTrialERP.com
Traceback (most recent call last):
  File "apps/frappe/frappe/utils/scheduler.py", line 70, in enqueue_events_for_site
    if is_scheduler_inactive():
  File "apps/frappe/frappe/utils/scheduler.py", line 105, in is_scheduler_inactive
    if is_scheduler_disabled():
  File "apps/frappe/frappe/utils/scheduler.py", line 115, in is_scheduler_disabled
    return not frappe.utils.cint(frappe.db.get_single_value("System Settings", "enable_scheduler"))
  File "apps/frappe/frappe/database/database.py", line 684, in get_single_value
    val = self.sql(
  File "apps/frappe/frappe/database/database.py", line 161, in sql
    self.connect()
  File "apps/frappe/frappe/database/database.py", line 85, in connect
    self._conn = self.get_connection()
  File "apps/frappe/frappe/database/mariadb/database.py", line 92, in get_connection
    conn.select_db(self.user)
  File "env/lib/python3.8/site-packages/pymysql/connections.py", line 496, in select_db
    self._read_ok_packet()
  File "env/lib/python3.8/site-packages/pymysql/connections.py", line 443, in _read_ok_packet
    pkt = self._read_packet()
  File "env/lib/python3.8/site-packages/pymysql/connections.py", line 725, in _read_packet
    packet.raise_for_error()
  File "env/lib/python3.8/site-packages/pymysql/protocol.py", line 221, in raise_for_error
    err.raise_mysql_exception(self._data)
  File "env/lib/python3.8/site-packages/pymysql/err.py", line 143, in raise_mysql_exception
    raise errorclass(errno, errval)
pymysql.err.OperationalError: (1049, "Unknown database '_c296b757cb15d301'")

2023-05-20 10:29:26,812 ERROR scheduler Exception in Enqueue Events for Site MyTrialERP.com
Traceback (most recent call last):
  File "apps/frappe/frappe/utils/scheduler.py", line 70, in enqueue_events_for_site
    if is_scheduler_inactive():
  File "apps/frappe/frappe/utils/scheduler.py", line 105, in is_scheduler_inactive
    if is_scheduler_disabled():
  File "apps/frappe/frappe/utils/scheduler.py", line 115, in is_scheduler_disabled
    return not frappe.utils.cint(frappe.db.get_single_value("System Settings", "enable_scheduler"))
  File "apps/frappe/frappe/database/database.py", line 684, in get_single_value
    val = self.sql(
  File "apps/frappe/frappe/database/database.py", line 161, in sql
    self.connect()
  File "apps/frappe/frappe/database/database.py", line 85, in connect
    self._conn = self.get_connection()
  File "apps/frappe/frappe/database/mariadb/database.py", line 92, in get_connection
    conn.select_db(self.user)
  File "env/lib/python3.8/site-packages/pymysql/connections.py", line 496, in select_db
    self._read_ok_packet()
  File "env/lib/python3.8/site-packages/pymysql/connections.py", line 443, in _read_ok_packet
    pkt = self._read_packet()
  File "env/lib/python3.8/site-packages/pymysql/connections.py", line 725, in _read_packet
    packet.raise_for_error()
  File "env/lib/python3.8/site-packages/pymysql/protocol.py", line 221, in raise_for_error
    err.raise_mysql_exception(self._data)
  File "env/lib/python3.8/site-packages/pymysql/err.py", line 143, in raise_mysql_exception
    raise errorclass(errno, errval)
pymysql.err.OperationalError: (1049, "Unknown database '_c296b757cb15d301'")

2023-05-20 10:30:27,079 ERROR scheduler Exception in Enqueue Events for Site MyTrialERP.com
Traceback (most recent call last):
  File "apps/frappe/frappe/utils/scheduler.py", line 70, in enqueue_events_for_site
    if is_scheduler_inactive():
  File "apps/frappe/frappe/utils/scheduler.py", line 105, in is_scheduler_inactive
    if is_scheduler_disabled():
  File "apps/frappe/frappe/utils/scheduler.py", line 115, in is_scheduler_disabled
    return not frappe.utils.cint(frappe.db.get_single_value("System Settings", "enable_scheduler"))
  File "apps/frappe/frappe/database/database.py", line 684, in get_single_value
    val = self.sql(
  File "apps/frappe/frappe/database/database.py", line 161, in sql
    self.connect()
  File "apps/frappe/frappe/database/database.py", line 85, in connect
    self._conn = self.get_connection()
  File "apps/frappe/frappe/database/mariadb/database.py", line 92, in get_connection
    conn.select_db(self.user)
  File "env/lib/python3.8/site-packages/pymysql/connections.py", line 496, in select_db
    self._read_ok_packet()
  File "env/lib/python3.8/site-packages/pymysql/connections.py", line 443, in _read_ok_packet
    pkt = self._read_packet()
  File "env/lib/python3.8/site-packages/pymysql/connections.py", line 725, in _read_packet
    packet.raise_for_error()
  File "env/lib/python3.8/site-packages/pymysql/protocol.py", line 221, in raise_for_error
    err.raise_mysql_exception(self._data)
  File "env/lib/python3.8/site-packages/pymysql/err.py", line 143, in raise_mysql_exception
    raise errorclass(errno, errval)
pymysql.err.OperationalError: (1049, "Unknown database '_c296b757cb15d301'")

2023-05-20 10:31:27,378 ERROR scheduler Exception in Enqueue Events for Site MyTrialERP.com
Traceback (most recent call last):
  File "apps/frappe/frappe/utils/scheduler.py", line 70, in enqueue_events_for_site
    if is_scheduler_inactive():
  File "apps/frappe/frappe/utils/scheduler.py", line 105, in is_scheduler_inactive
    if is_scheduler_disabled():
  File "apps/frappe/frappe/utils/scheduler.py", line 115, in is_scheduler_disabled
    return not frappe.utils.cint(frappe.db.get_single_value("System Settings", "enable_scheduler"))
  File "apps/frappe/frappe/database/database.py", line 684, in get_single_value
    val = self.sql(
  File "apps/frappe/frappe/database/database.py", line 161, in sql
    self.connect()
  File "apps/frappe/frappe/database/database.py", line 85, in connect
    self._conn = self.get_connection()
  File "apps/frappe/frappe/database/mariadb/database.py", line 92, in get_connection
    conn.select_db(self.user)
  File "env/lib/python3.8/site-packages/pymysql/connections.py", line 496, in select_db
    self._read_ok_packet()
  File "env/lib/python3.8/site-packages/pymysql/connections.py", line 443, in _read_ok_packet
    pkt = self._read_packet()
  File "env/lib/python3.8/site-packages/pymysql/connections.py", line 725, in _read_packet
    packet.raise_for_error()
  File "env/lib/python3.8/site-packages/pymysql/protocol.py", line 221, in raise_for_error
    err.raise_mysql_exception(self._data)
  File "env/lib/python3.8/site-packages/pymysql/err.py", line 143, in raise_mysql_exception
    raise errorclass(errno, errval)
pymysql.err.OperationalError: (1049, "Unknown database '_c296b757cb15d301'")

2023-05-20 10:32:27,663 ERROR scheduler Exception in Enqueue Events for Site MyTrialERP.com
Traceback (most recent call last):
  File "apps/frappe/frappe/utils/scheduler.py", line 70, in enqueue_events_for_site
    if is_scheduler_inactive():
  File "apps/frappe/frappe/utils/scheduler.py", line 105, in is_scheduler_inactive
    if is_scheduler_disabled():
  File "apps/frappe/frappe/utils/scheduler.py", line 115, in is_scheduler_disabled
    return not frappe.utils.cint(frappe.db.get_single_value("System Settings", "enable_scheduler"))
  File "apps/frappe/frappe/database/database.py", line 684, in get_single_value
    val = self.sql(
  File "apps/frappe/frappe/database/database.py", line 161, in sql
    self.connect()
  File "apps/frappe/frappe/database/database.py", line 85, in connect
    self._conn = self.get_connection()
  File "apps/frappe/frappe/database/mariadb/database.py", line 92, in get_connection
    conn.select_db(self.user)
  File "env/lib/python3.8/site-packages/pymysql/connections.py", line 496, in select_db
    self._read_ok_packet()
  File "env/lib/python3.8/site-packages/pymysql/connections.py", line 443, in _read_ok_packet
    pkt = self._read_packet()
  File "env/lib/python3.8/site-packages/pymysql/connections.py", line 725, in _read_packet
    packet.raise_for_error()
  File "env/lib/python3.8/site-packages/pymysql/protocol.py", line 221, in raise_for_error
    err.raise_mysql_exception(self._data)
  File "env/lib/python3.8/site-packages/pymysql/err.py", line 143, in raise_mysql_exception
    raise errorclass(errno, errval)
pymysql.err.OperationalError: (1049, "Unknown database '_c296b757cb15d301'")

2023-05-20 10:33:28,008 ERROR scheduler Exception in Enqueue Events for Site MyTrialERP.com
Traceback (most recent call last):
  File "apps/frappe/frappe/utils/scheduler.py", line 70, in enqueue_events_for_site
    if is_scheduler_inactive():
  File "apps/frappe/frappe/utils/scheduler.py", line 105, in is_scheduler_inactive
    if is_scheduler_disabled():
  File "apps/frappe/frappe/utils/scheduler.py", line 115, in is_scheduler_disabled
    return not frappe.utils.cint(frappe.db.get_single_value("System Settings", "enable_scheduler"))
  File "apps/frappe/frappe/database/database.py", line 684, in get_single_value
    val = self.sql(
  File "apps/frappe/frappe/database/database.py", line 161, in sql
    self.connect()
  File "apps/frappe/frappe/database/database.py", line 85, in connect
    self._conn = self.get_connection()
  File "apps/frappe/frappe/database/mariadb/database.py", line 92, in get_connection
    conn.select_db(self.user)
  File "env/lib/python3.8/site-packages/pymysql/connections.py", line 496, in select_db
    self._read_ok_packet()
  File "env/lib/python3.8/site-packages/pymysql/connections.py", line 443, in _read_ok_packet
    pkt = self._read_packet()
  File "env/lib/python3.8/site-packages/pymysql/connections.py", line 725, in _read_packet
    packet.raise_for_error()
  File "env/lib/python3.8/site-packages/pymysql/protocol.py", line 221, in raise_for_error
    err.raise_mysql_exception(self._data)
  File "env/lib/python3.8/site-packages/pymysql/err.py", line 143, in raise_mysql_exception
    raise errorclass(errno, errval)
pymysql.err.OperationalError: (1049, "Unknown database '_c296b757cb15d301'")

2023-05-20 10:34:28,279 ERROR scheduler Exception in Enqueue Events for Site MyTrialERP.com
Traceback (most recent call last):
  File "apps/frappe/frappe/utils/scheduler.py", line 70, in enqueue_events_for_site
    if is_scheduler_inactive():
  File "apps/frappe/frappe/utils/scheduler.py", line 105, in is_scheduler_inactive
    if is_scheduler_disabled():
  File "apps/frappe/frappe/utils/scheduler.py", line 115, in is_scheduler_disabled
    return not frappe.utils.cint(frappe.db.get_single_value("System Settings", "enable_scheduler"))
  File "apps/frappe/frappe/database/database.py", line 684, in get_single_value
    val = self.sql(
  File "apps/frappe/frappe/database/database.py", line 161, in sql
    self.connect()
  File "apps/frappe/frappe/database/database.py", line 85, in connect
    self._conn = self.get_connection()
  File "apps/frappe/frappe/database/mariadb/database.py", line 92, in get_connection
    conn.select_db(self.user)
  File "env/lib/python3.8/site-packages/pymysql/connections.py", line 496, in select_db
    self._read_ok_packet()
  File "env/lib/python3.8/site-packages/pymysql/connections.py", line 443, in _read_ok_packet
    pkt = self._read_packet()
  File "env/lib/python3.8/site-packages/pymysql/connections.py", line 725, in _read_packet
    packet.raise_for_error()
  File "env/lib/python3.8/site-packages/pymysql/protocol.py", line 221, in raise_for_error
    err.raise_mysql_exception(self._data)
  File "env/lib/python3.8/site-packages/pymysql/err.py", line 143, in raise_mysql_exception
    raise errorclass(errno, errval)
pymysql.err.OperationalError: (1049, "Unknown database '_c296b757cb15d301'")

2023-05-20 10:35:28,579 ERROR scheduler Exception in Enqueue Events for Site MyTrialERP.com
Traceback (most recent call last):
  File "apps/frappe/frappe/utils/scheduler.py", line 70, in enqueue_events_for_site
    if is_scheduler_inactive():
  File "apps/frappe/frappe/utils/scheduler.py", line 105, in is_scheduler_inactive
    if is_scheduler_disabled():
  File "apps/frappe/frappe/utils/scheduler.py", line 115, in is_scheduler_disabled
    return not frappe.utils.cint(frappe.db.get_single_value("System Settings", "enable_scheduler"))
  File "apps/frappe/frappe/database/database.py", line 684, in get_single_value
    val = self.sql(
  File "apps/frappe/frappe/database/database.py", line 161, in sql
    self.connect()
  File "apps/frappe/frappe/database/database.py", line 85, in connect
    self._conn = self.get_connection()
  File "apps/frappe/frappe/database/mariadb/database.py", line 92, in get_connection
    conn.select_db(self.user)
  File "env/lib/python3.8/site-packages/pymysql/connections.py", line 496, in select_db
    self._read_ok_packet()
  File "env/lib/python3.8/site-packages/pymysql/connections.py", line 443, in _read_ok_packet
    pkt = self._read_packet()
  File "env/lib/python3.8/site-packages/pymysql/connections.py", line 725, in _read_packet
    packet.raise_for_error()
  File "env/lib/python3.8/site-packages/pymysql/protocol.py", line 221, in raise_for_error
    err.raise_mysql_exception(self._data)
  File "env/lib/python3.8/site-packages/pymysql/err.py", line 143, in raise_mysql_exception
    raise errorclass(errno, errval)
pymysql.err.OperationalError: (1049, "Unknown database '_c296b757cb15d301'")

2023-05-20 10:36:28,867 ERROR scheduler Exception in Enqueue Events for Site MyTrialERP.com
Traceback (most recent call last):
  File "apps/frappe/frappe/utils/scheduler.py", line 70, in enqueue_events_for_site
    if is_scheduler_inactive():
  File "apps/frappe/frappe/utils/scheduler.py", line 105, in is_scheduler_inactive
    if is_scheduler_disabled():
  File "apps/frappe/frappe/utils/scheduler.py", line 115, in is_scheduler_disabled
    return not frappe.utils.cint(frappe.db.get_single_value("System Settings", "enable_scheduler"))
  File "apps/frappe/frappe/database/database.py", line 684, in get_single_value
    val = self.sql(
  File "apps/frappe/frappe/database/database.py", line 161, in sql
    self.connect()
  File "apps/frappe/frappe/database/database.py", line 85, in connect
    self._conn = self.get_connection()
  File "apps/frappe/frappe/database/mariadb/database.py", line 92, in get_connection
    conn.select_db(self.user)
  File "env/lib/python3.8/site-packages/pymysql/connections.py", line 496, in select_db
    self._read_ok_packet()
  File "env/lib/python3.8/site-packages/pymysql/connections.py", line 443, in _read_ok_packet
    pkt = self._read_packet()
  File "env/lib/python3.8/site-packages/pymysql/connections.py", line 725, in _read_packet
    packet.raise_for_error()
  File "env/lib/python3.8/site-packages/pymysql/protocol.py", line 221, in raise_for_error
    err.raise_mysql_exception(self._data)
  File "env/lib/python3.8/site-packages/pymysql/err.py", line 143, in raise_mysql_exception
    raise errorclass(errno, errval)
pymysql.err.OperationalError: (1049, "Unknown database '_c296b757cb15d301'")

2023-05-20 10:37:29,230 ERROR scheduler Exception in Enqueue Events for Site MyTrialERP.com
Traceback (most recent call last):
  File "apps/frappe/frappe/utils/scheduler.py", line 70, in enqueue_events_for_site
    if is_scheduler_inactive():
  File "apps/frappe/frappe/utils/scheduler.py", line 105, in is_scheduler_inactive
    if is_scheduler_disabled():
  File "apps/frappe/frappe/utils/scheduler.py", line 115, in is_scheduler_disabled
    return not frappe.utils.cint(frappe.db.get_single_value("System Settings", "enable_scheduler"))
  File "apps/frappe/frappe/database/database.py", line 684, in get_single_value
    val = self.sql(
  File "apps/frappe/frappe/database/database.py", line 161, in sql
    self.connect()
  File "apps/frappe/frappe/database/database.py", line 85, in connect
    self._conn = self.get_connection()
  File "apps/frappe/frappe/database/mariadb/database.py", line 92, in get_connection
    conn.select_db(self.user)
  File "env/lib/python3.8/site-packages/pymysql/connections.py", line 496, in select_db
    self._read_ok_packet()
  File "env/lib/python3.8/site-packages/pymysql/connections.py", line 443, in _read_ok_packet
    pkt = self._read_packet()
  File "env/lib/python3.8/site-packages/pymysql/connections.py", line 725, in _read_packet
    packet.raise_for_error()
  File "env/lib/python3.8/site-packages/pymysql/protocol.py", line 221, in raise_for_error
    err.raise_mysql_exception(self._data)
  File "env/lib/python3.8/site-packages/pymysql/err.py", line 143, in raise_mysql_exception
    raise errorclass(errno, errval)
pymysql.err.OperationalError: (1049, "Unknown database '_c296b757cb15d301'")

2023-05-20 10:38:29,511 ERROR scheduler Exception in Enqueue Events for Site MyTrialERP.com
Traceback (most recent call last):
  File "apps/frappe/frappe/utils/scheduler.py", line 70, in enqueue_events_for_site
    if is_scheduler_inactive():
  File "apps/frappe/frappe/utils/scheduler.py", line 105, in is_scheduler_inactive
    if is_scheduler_disabled():
  File "apps/frappe/frappe/utils/scheduler.py", line 115, in is_scheduler_disabled
    return not frappe.utils.cint(frappe.db.get_single_value("System Settings", "enable_scheduler"))
  File "apps/frappe/frappe/database/database.py", line 684, in get_single_value
    val = self.sql(
  File "apps/frappe/frappe/database/database.py", line 161, in sql
    self.connect()
  File "apps/frappe/frappe/database/database.py", line 85, in connect
    self._conn = self.get_connection()
  File "apps/frappe/frappe/database/mariadb/database.py", line 92, in get_connection
    conn.select_db(self.user)
  File "env/lib/python3.8/site-packages/pymysql/connections.py", line 496, in select_db
    self._read_ok_packet()
  File "env/lib/python3.8/site-packages/pymysql/connections.py", line 443, in _read_ok_packet
    pkt = self._read_packet()
  File "env/lib/python3.8/site-packages/pymysql/connections.py", line 725, in _read_packet
    packet.raise_for_error()
  File "env/lib/python3.8/site-packages/pymysql/protocol.py", line 221, in raise_for_error
    err.raise_mysql_exception(self._data)
  File "env/lib/python3.8/site-packages/pymysql/err.py", line 143, in raise_mysql_exception
    raise errorclass(errno, errval)
pymysql.err.OperationalError: (1049, "Unknown database '_c296b757cb15d301'")

2023-05-20 10:39:29,822 ERROR scheduler Exception in Enqueue Events for Site MyTrialERP.com
Traceback (most recent call last):
  File "apps/frappe/frappe/utils/scheduler.py", line 70, in enqueue_events_for_site
    if is_scheduler_inactive():
  File "apps/frappe/frappe/utils/scheduler.py", line 105, in is_scheduler_inactive
    if is_scheduler_disabled():
  File "apps/frappe/frappe/utils/scheduler.py", line 115, in is_scheduler_disabled
    return not frappe.utils.cint(frappe.db.get_single_value("System Settings", "enable_scheduler"))
  File "apps/frappe/frappe/database/database.py", line 684, in get_single_value
    val = self.sql(
  File "apps/frappe/frappe/database/database.py", line 161, in sql
    self.connect()
  File "apps/frappe/frappe/database/database.py", line 85, in connect
    self._conn = self.get_connection()
  File "apps/frappe/frappe/database/mariadb/database.py", line 92, in get_connection
    conn.select_db(self.user)
  File "env/lib/python3.8/site-packages/pymysql/connections.py", line 496, in select_db
    self._read_ok_packet()
  File "env/lib/python3.8/site-packages/pymysql/connections.py", line 443, in _read_ok_packet
    pkt = self._read_packet()
  File "env/lib/python3.8/site-packages/pymysql/connections.py", line 725, in _read_packet
    packet.raise_for_error()
  File "env/lib/python3.8/site-packages/pymysql/protocol.py", line 221, in raise_for_error
    err.raise_mysql_exception(self._data)
  File "env/lib/python3.8/site-packages/pymysql/err.py", line 143, in raise_mysql_exception
    raise errorclass(errno, errval)
pymysql.err.OperationalError: (1049, "Unknown database '_c296b757cb15d301'")

2023-05-20 10:40:30,178 ERROR scheduler Exception in Enqueue Events for Site MyTrialERP.com
Traceback (most recent call last):
  File "apps/frappe/frappe/utils/scheduler.py", line 70, in enqueue_events_for_site
    if is_scheduler_inactive():
  File "apps/frappe/frappe/utils/scheduler.py", line 105, in is_scheduler_inactive
    if is_scheduler_disabled():
  File "apps/frappe/frappe/utils/scheduler.py", line 115, in is_scheduler_disabled
    return not frappe.utils.cint(frappe.db.get_single_value("System Settings", "enable_scheduler"))
  File "apps/frappe/frappe/database/database.py", line 684, in get_single_value
    val = self.sql(
  File "apps/frappe/frappe/database/database.py", line 161, in sql
    self.connect()
  File "apps/frappe/frappe/database/database.py", line 85, in connect
    self._conn = self.get_connection()
  File "apps/frappe/frappe/database/mariadb/database.py", line 92, in get_connection
    conn.select_db(self.user)
  File "env/lib/python3.8/site-packages/pymysql/connections.py", line 496, in select_db
    self._read_ok_packet()
  File "env/lib/python3.8/site-packages/pymysql/connections.py", line 443, in _read_ok_packet
    pkt = self._read_packet()
  File "env/lib/python3.8/site-packages/pymysql/connections.py", line 725, in _read_packet
    packet.raise_for_error()
  File "env/lib/python3.8/site-packages/pymysql/protocol.py", line 221, in raise_for_error
    err.raise_mysql_exception(self._data)
  File "env/lib/python3.8/site-packages/pymysql/err.py", line 143, in raise_mysql_exception
    raise errorclass(errno, errval)
pymysql.err.OperationalError: (1049, "Unknown database '_c296b757cb15d301'")

2023-05-20 10:41:30,558 ERROR scheduler Exception in Enqueue Events for Site MyTrialERP.com
Traceback (most recent call last):
  File "apps/frappe/frappe/utils/scheduler.py", line 70, in enqueue_events_for_site
    if is_scheduler_inactive():
  File "apps/frappe/frappe/utils/scheduler.py", line 105, in is_scheduler_inactive
    if is_scheduler_disabled():
  File "apps/frappe/frappe/utils/scheduler.py", line 115, in is_scheduler_disabled
    return not frappe.utils.cint(frappe.db.get_single_value("System Settings", "enable_scheduler"))
  File "apps/frappe/frappe/database/database.py", line 684, in get_single_value
    val = self.sql(
  File "apps/frappe/frappe/database/database.py", line 161, in sql
    self.connect()
  File "apps/frappe/frappe/database/database.py", line 85, in connect
    self._conn = self.get_connection()
  File "apps/frappe/frappe/database/mariadb/database.py", line 92, in get_connection
    conn.select_db(self.user)
  File "env/lib/python3.8/site-packages/pymysql/connections.py", line 496, in select_db
    self._read_ok_packet()
  File "env/lib/python3.8/site-packages/pymysql/connections.py", line 443, in _read_ok_packet
    pkt = self._read_packet()
  File "env/lib/python3.8/site-packages/pymysql/connections.py", line 725, in _read_packet
    packet.raise_for_error()
  File "env/lib/python3.8/site-packages/pymysql/protocol.py", line 221, in raise_for_error
    err.raise_mysql_exception(self._data)
  File "env/lib/python3.8/site-packages/pymysql/err.py", line 143, in raise_mysql_exception
    raise errorclass(errno, errval)
pymysql.err.OperationalError: (1049, "Unknown database '_c296b757cb15d301'")

2023-05-20 10:42:30,824 ERROR scheduler Exception in Enqueue Events for Site MyTrialERP.com
Traceback (most recent call last):
  File "apps/frappe/frappe/utils/scheduler.py", line 70, in enqueue_events_for_site
    if is_scheduler_inactive():
  File "apps/frappe/frappe/utils/scheduler.py", line 105, in is_scheduler_inactive
    if is_scheduler_disabled():
  File "apps/frappe/frappe/utils/scheduler.py", line 115, in is_scheduler_disabled
    return not frappe.utils.cint(frappe.db.get_single_value("System Settings", "enable_scheduler"))
  File "apps/frappe/frappe/database/database.py", line 684, in get_single_value
    val = self.sql(
  File "apps/frappe/frappe/database/database.py", line 161, in sql
    self.connect()
  File "apps/frappe/frappe/database/database.py", line 85, in connect
    self._conn = self.get_connection()
  File "apps/frappe/frappe/database/mariadb/database.py", line 92, in get_connection
    conn.select_db(self.user)
  File "env/lib/python3.8/site-packages/pymysql/connections.py", line 496, in select_db
    self._read_ok_packet()
  File "env/lib/python3.8/site-packages/pymysql/connections.py", line 443, in _read_ok_packet
    pkt = self._read_packet()
  File "env/lib/python3.8/site-packages/pymysql/connections.py", line 725, in _read_packet
    packet.raise_for_error()
  File "env/lib/python3.8/site-packages/pymysql/protocol.py", line 221, in raise_for_error
    err.raise_mysql_exception(self._data)
  File "env/lib/python3.8/site-packages/pymysql/err.py", line 143, in raise_mysql_exception
    raise errorclass(errno, errval)
pymysql.err.OperationalError: (1049, "Unknown database '_c296b757cb15d301'")

2023-05-20 10:43:31,092 ERROR scheduler Exception in Enqueue Events for Site MyTrialERP.com
Traceback (most recent call last):
  File "apps/frappe/frappe/utils/scheduler.py", line 70, in enqueue_events_for_site
    if is_scheduler_inactive():
  File "apps/frappe/frappe/utils/scheduler.py", line 105, in is_scheduler_inactive
    if is_scheduler_disabled():
  File "apps/frappe/frappe/utils/scheduler.py", line 115, in is_scheduler_disabled
    return not frappe.utils.cint(frappe.db.get_single_value("System Settings", "enable_scheduler"))
  File "apps/frappe/frappe/database/database.py", line 684, in get_single_value
    val = self.sql(
  File "apps/frappe/frappe/database/database.py", line 161, in sql
    self.connect()
  File "apps/frappe/frappe/database/database.py", line 85, in connect
    self._conn = self.get_connection()
  File "apps/frappe/frappe/database/mariadb/database.py", line 92, in get_connection
    conn.select_db(self.user)
  File "env/lib/python3.8/site-packages/pymysql/connections.py", line 496, in select_db
    self._read_ok_packet()
  File "env/lib/python3.8/site-packages/pymysql/connections.py", line 443, in _read_ok_packet
    pkt = self._read_packet()
  File "env/lib/python3.8/site-packages/pymysql/connections.py", line 725, in _read_packet
    packet.raise_for_error()
  File "env/lib/python3.8/site-packages/pymysql/protocol.py", line 221, in raise_for_error
    err.raise_mysql_exception(self._data)
  File "env/lib/python3.8/site-packages/pymysql/err.py", line 143, in raise_mysql_exception
    raise errorclass(errno, errval)
pymysql.err.OperationalError: (1049, "Unknown database '_c296b757cb15d301'")

2023-05-20 10:44:31,343 ERROR scheduler Exception in Enqueue Events for Site MyTrialERP.com
Traceback (most recent call last):
  File "apps/frappe/frappe/utils/scheduler.py", line 70, in enqueue_events_for_site
    if is_scheduler_inactive():
  File "apps/frappe/frappe/utils/scheduler.py", line 105, in is_scheduler_inactive
    if is_scheduler_disabled():
  File "apps/frappe/frappe/utils/scheduler.py", line 115, in is_scheduler_disabled
    return not frappe.utils.cint(frappe.db.get_single_value("System Settings", "enable_scheduler"))
  File "apps/frappe/frappe/database/database.py", line 684, in get_single_value
    val = self.sql(
  File "apps/frappe/frappe/database/database.py", line 161, in sql
    self.connect()
  File "apps/frappe/frappe/database/database.py", line 85, in connect
    self._conn = self.get_connection()
  File "apps/frappe/frappe/database/mariadb/database.py", line 92, in get_connection
    conn.select_db(self.user)
  File "env/lib/python3.8/site-packages/pymysql/connections.py", line 496, in select_db
    self._read_ok_packet()
  File "env/lib/python3.8/site-packages/pymysql/connections.py", line 443, in _read_ok_packet
    pkt = self._read_packet()
  File "env/lib/python3.8/site-packages/pymysql/connections.py", line 725, in _read_packet
    packet.raise_for_error()
  File "env/lib/python3.8/site-packages/pymysql/protocol.py", line 221, in raise_for_error
    err.raise_mysql_exception(self._data)
  File "env/lib/python3.8/site-packages/pymysql/err.py", line 143, in raise_mysql_exception
    raise errorclass(errno, errval)
pymysql.err.OperationalError: (1049, "Unknown database '_c296b757cb15d301'")

2023-05-20 10:45:31,718 ERROR scheduler Exception in Enqueue Events for Site MyTrialERP.com
Traceback (most recent call last):
  File "apps/frappe/frappe/utils/scheduler.py", line 70, in enqueue_events_for_site
    if is_scheduler_inactive():
  File "apps/frappe/frappe/utils/scheduler.py", line 105, in is_scheduler_inactive
    if is_scheduler_disabled():
  File "apps/frappe/frappe/utils/scheduler.py", line 115, in is_scheduler_disabled
    return not frappe.utils.cint(frappe.db.get_single_value("System Settings", "enable_scheduler"))
  File "apps/frappe/frappe/database/database.py", line 684, in get_single_value
    val = self.sql(
  File "apps/frappe/frappe/database/database.py", line 161, in sql
    self.connect()
  File "apps/frappe/frappe/database/database.py", line 85, in connect
    self._conn = self.get_connection()
  File "apps/frappe/frappe/database/mariadb/database.py", line 92, in get_connection
    conn.select_db(self.user)
  File "env/lib/python3.8/site-packages/pymysql/connections.py", line 496, in select_db
    self._read_ok_packet()
  File "env/lib/python3.8/site-packages/pymysql/connections.py", line 443, in _read_ok_packet
    pkt = self._read_packet()
  File "env/lib/python3.8/site-packages/pymysql/connections.py", line 725, in _read_packet
    packet.raise_for_error()
  File "env/lib/python3.8/site-packages/pymysql/protocol.py", line 221, in raise_for_error
    err.raise_mysql_exception(self._data)
  File "env/lib/python3.8/site-packages/pymysql/err.py", line 143, in raise_mysql_exception
    raise errorclass(errno, errval)
pymysql.err.OperationalError: (1049, "Unknown database '_c296b757cb15d301'")

2023-05-20 10:46:32,049 ERROR scheduler Exception in Enqueue Events for Site MyTrialERP.com
Traceback (most recent call last):
  File "apps/frappe/frappe/utils/scheduler.py", line 70, in enqueue_events_for_site
    if is_scheduler_inactive():
  File "apps/frappe/frappe/utils/scheduler.py", line 105, in is_scheduler_inactive
    if is_scheduler_disabled():
  File "apps/frappe/frappe/utils/scheduler.py", line 115, in is_scheduler_disabled
    return not frappe.utils.cint(frappe.db.get_single_value("System Settings", "enable_scheduler"))
  File "apps/frappe/frappe/database/database.py", line 684, in get_single_value
    val = self.sql(
  File "apps/frappe/frappe/database/database.py", line 161, in sql
    self.connect()
  File "apps/frappe/frappe/database/database.py", line 85, in connect
    self._conn = self.get_connection()
  File "apps/frappe/frappe/database/mariadb/database.py", line 92, in get_connection
    conn.select_db(self.user)
  File "env/lib/python3.8/site-packages/pymysql/connections.py", line 496, in select_db
    self._read_ok_packet()
  File "env/lib/python3.8/site-packages/pymysql/connections.py", line 443, in _read_ok_packet
    pkt = self._read_packet()
  File "env/lib/python3.8/site-packages/pymysql/connections.py", line 725, in _read_packet
    packet.raise_for_error()
  File "env/lib/python3.8/site-packages/pymysql/protocol.py", line 221, in raise_for_error
    err.raise_mysql_exception(self._data)
  File "env/lib/python3.8/site-packages/pymysql/err.py", line 143, in raise_mysql_exception
    raise errorclass(errno, errval)
pymysql.err.OperationalError: (1049, "Unknown database '_c296b757cb15d301'")

2023-05-20 10:47:32,335 ERROR scheduler Exception in Enqueue Events for Site MyTrialERP.com
Traceback (most recent call last):
  File "apps/frappe/frappe/utils/scheduler.py", line 70, in enqueue_events_for_site
    if is_scheduler_inactive():
  File "apps/frappe/frappe/utils/scheduler.py", line 105, in is_scheduler_inactive
    if is_scheduler_disabled():
  File "apps/frappe/frappe/utils/scheduler.py", line 115, in is_scheduler_disabled
    return not frappe.utils.cint(frappe.db.get_single_value("System Settings", "enable_scheduler"))
  File "apps/frappe/frappe/database/database.py", line 684, in get_single_value
    val = self.sql(
  File "apps/frappe/frappe/database/database.py", line 161, in sql
    self.connect()
  File "apps/frappe/frappe/database/database.py", line 85, in connect
    self._conn = self.get_connection()
  File "apps/frappe/frappe/database/mariadb/database.py", line 92, in get_connection
    conn.select_db(self.user)
  File "env/lib/python3.8/site-packages/pymysql/connections.py", line 496, in select_db
    self._read_ok_packet()
  File "env/lib/python3.8/site-packages/pymysql/connections.py", line 443, in _read_ok_packet
    pkt = self._read_packet()
  File "env/lib/python3.8/site-packages/pymysql/connections.py", line 725, in _read_packet
    packet.raise_for_error()
  File "env/lib/python3.8/site-packages/pymysql/protocol.py", line 221, in raise_for_error
    err.raise_mysql_exception(self._data)
  File "env/lib/python3.8/site-packages/pymysql/err.py", line 143, in raise_mysql_exception
    raise errorclass(errno, errval)
pymysql.err.OperationalError: (1049, "Unknown database '_c296b757cb15d301'")

2023-05-20 10:48:32,601 ERROR scheduler Exception in Enqueue Events for Site MyTrialERP.com
Traceback (most recent call last):
  File "apps/frappe/frappe/utils/scheduler.py", line 70, in enqueue_events_for_site
    if is_scheduler_inactive():
  File "apps/frappe/frappe/utils/scheduler.py", line 105, in is_scheduler_inactive
    if is_scheduler_disabled():
  File "apps/frappe/frappe/utils/scheduler.py", line 115, in is_scheduler_disabled
    return not frappe.utils.cint(frappe.db.get_single_value("System Settings", "enable_scheduler"))
  File "apps/frappe/frappe/database/database.py", line 684, in get_single_value
    val = self.sql(
  File "apps/frappe/frappe/database/database.py", line 161, in sql
    self.connect()
  File "apps/frappe/frappe/database/database.py", line 85, in connect
    self._conn = self.get_connection()
  File "apps/frappe/frappe/database/mariadb/database.py", line 92, in get_connection
    conn.select_db(self.user)
  File "env/lib/python3.8/site-packages/pymysql/connections.py", line 496, in select_db
    self._read_ok_packet()
  File "env/lib/python3.8/site-packages/pymysql/connections.py", line 443, in _read_ok_packet
    pkt = self._read_packet()
  File "env/lib/python3.8/site-packages/pymysql/connections.py", line 725, in _read_packet
    packet.raise_for_error()
  File "env/lib/python3.8/site-packages/pymysql/protocol.py", line 221, in raise_for_error
    err.raise_mysql_exception(self._data)
  File "env/lib/python3.8/site-packages/pymysql/err.py", line 143, in raise_mysql_exception
    raise errorclass(errno, errval)
pymysql.err.OperationalError: (1049, "Unknown database '_c296b757cb15d301'")

2023-05-20 10:49:32,985 ERROR scheduler Exception in Enqueue Events for Site MyTrialERP.com
Traceback (most recent call last):
  File "apps/frappe/frappe/utils/scheduler.py", line 70, in enqueue_events_for_site
    if is_scheduler_inactive():
  File "apps/frappe/frappe/utils/scheduler.py", line 105, in is_scheduler_inactive
    if is_scheduler_disabled():
  File "apps/frappe/frappe/utils/scheduler.py", line 115, in is_scheduler_disabled
    return not frappe.utils.cint(frappe.db.get_single_value("System Settings", "enable_scheduler"))
  File "apps/frappe/frappe/database/database.py", line 684, in get_single_value
    val = self.sql(
  File "apps/frappe/frappe/database/database.py", line 161, in sql
    self.connect()
  File "apps/frappe/frappe/database/database.py", line 85, in connect
    self._conn = self.get_connection()
  File "apps/frappe/frappe/database/mariadb/database.py", line 92, in get_connection
    conn.select_db(self.user)
  File "env/lib/python3.8/site-packages/pymysql/connections.py", line 496, in select_db
    self._read_ok_packet()
  File "env/lib/python3.8/site-packages/pymysql/connections.py", line 443, in _read_ok_packet
    pkt = self._read_packet()
  File "env/lib/python3.8/site-packages/pymysql/connections.py", line 725, in _read_packet
    packet.raise_for_error()
  File "env/lib/python3.8/site-packages/pymysql/protocol.py", line 221, in raise_for_error
    err.raise_mysql_exception(self._data)
  File "env/lib/python3.8/site-packages/pymysql/err.py", line 143, in raise_mysql_exception
    raise errorclass(errno, errval)
pymysql.err.OperationalError: (1049, "Unknown database '_c296b757cb15d301'")

2023-05-20 10:50:33,242 ERROR scheduler Exception in Enqueue Events for Site MyTrialERP.com
Traceback (most recent call last):
  File "apps/frappe/frappe/utils/scheduler.py", line 70, in enqueue_events_for_site
    if is_scheduler_inactive():
  File "apps/frappe/frappe/utils/scheduler.py", line 105, in is_scheduler_inactive
    if is_scheduler_disabled():
  File "apps/frappe/frappe/utils/scheduler.py", line 115, in is_scheduler_disabled
    return not frappe.utils.cint(frappe.db.get_single_value("System Settings", "enable_scheduler"))
  File "apps/frappe/frappe/database/database.py", line 684, in get_single_value
    val = self.sql(
  File "apps/frappe/frappe/database/database.py", line 161, in sql
    self.connect()
  File "apps/frappe/frappe/database/database.py", line 85, in connect
    self._conn = self.get_connection()
  File "apps/frappe/frappe/database/mariadb/database.py", line 92, in get_connection
    conn.select_db(self.user)
  File "env/lib/python3.8/site-packages/pymysql/connections.py", line 496, in select_db
    self._read_ok_packet()
  File "env/lib/python3.8/site-packages/pymysql/connections.py", line 443, in _read_ok_packet
    pkt = self._read_packet()
  File "env/lib/python3.8/site-packages/pymysql/connections.py", line 725, in _read_packet
    packet.raise_for_error()
  File "env/lib/python3.8/site-packages/pymysql/protocol.py", line 221, in raise_for_error
    err.raise_mysql_exception(self._data)
  File "env/lib/python3.8/site-packages/pymysql/err.py", line 143, in raise_mysql_exception
    raise errorclass(errno, errval)
pymysql.err.OperationalError: (1049, "Unknown database '_c296b757cb15d301'")

2023-05-20 10:51:33,557 ERROR scheduler Exception in Enqueue Events for Site MyTrialERP.com
Traceback (most recent call last):
  File "apps/frappe/frappe/utils/scheduler.py", line 70, in enqueue_events_for_site
    if is_scheduler_inactive():
  File "apps/frappe/frappe/utils/scheduler.py", line 105, in is_scheduler_inactive
    if is_scheduler_disabled():
  File "apps/frappe/frappe/utils/scheduler.py", line 115, in is_scheduler_disabled
    return not frappe.utils.cint(frappe.db.get_single_value("System Settings", "enable_scheduler"))
  File "apps/frappe/frappe/database/database.py", line 684, in get_single_value
    val = self.sql(
  File "apps/frappe/frappe/database/database.py", line 161, in sql
    self.connect()
  File "apps/frappe/frappe/database/database.py", line 85, in connect
    self._conn = self.get_connection()
  File "apps/frappe/frappe/database/mariadb/database.py", line 92, in get_connection
    conn.select_db(self.user)
  File "env/lib/python3.8/site-packages/pymysql/connections.py", line 496, in select_db
    self._read_ok_packet()
  File "env/lib/python3.8/site-packages/pymysql/connections.py", line 443, in _read_ok_packet
    pkt = self._read_packet()
  File "env/lib/python3.8/site-packages/pymysql/connections.py", line 725, in _read_packet
    packet.raise_for_error()
  File "env/lib/python3.8/site-packages/pymysql/protocol.py", line 221, in raise_for_error
    err.raise_mysql_exception(self._data)
  File "env/lib/python3.8/site-packages/pymysql/err.py", line 143, in raise_mysql_exception
    raise errorclass(errno, errval)
pymysql.err.OperationalError: (1049, "Unknown database '_c296b757cb15d301'")

2023-05-20 10:52:33,818 ERROR scheduler Exception in Enqueue Events for Site MyTrialERP.com
Traceback (most recent call last):
  File "apps/frappe/frappe/utils/scheduler.py", line 70, in enqueue_events_for_site
    if is_scheduler_inactive():
  File "apps/frappe/frappe/utils/scheduler.py", line 105, in is_scheduler_inactive
    if is_scheduler_disabled():
  File "apps/frappe/frappe/utils/scheduler.py", line 115, in is_scheduler_disabled
    return not frappe.utils.cint(frappe.db.get_single_value("System Settings", "enable_scheduler"))
  File "apps/frappe/frappe/database/database.py", line 684, in get_single_value
    val = self.sql(
  File "apps/frappe/frappe/database/database.py", line 161, in sql
    self.connect()
  File "apps/frappe/frappe/database/database.py", line 85, in connect
    self._conn = self.get_connection()
  File "apps/frappe/frappe/database/mariadb/database.py", line 92, in get_connection
    conn.select_db(self.user)
  File "env/lib/python3.8/site-packages/pymysql/connections.py", line 496, in select_db
    self._read_ok_packet()
  File "env/lib/python3.8/site-packages/pymysql/connections.py", line 443, in _read_ok_packet
    pkt = self._read_packet()
  File "env/lib/python3.8/site-packages/pymysql/connections.py", line 725, in _read_packet
    packet.raise_for_error()
  File "env/lib/python3.8/site-packages/pymysql/protocol.py", line 221, in raise_for_error
    err.raise_mysql_exception(self._data)
  File "env/lib/python3.8/site-packages/pymysql/err.py", line 143, in raise_mysql_exception
    raise errorclass(errno, errval)
pymysql.err.OperationalError: (1049, "Unknown database '_c296b757cb15d301'")

2023-05-20 10:53:34,156 ERROR scheduler Exception in Enqueue Events for Site MyTrialERP.com
Traceback (most recent call last):
  File "apps/frappe/frappe/utils/scheduler.py", line 70, in enqueue_events_for_site
    if is_scheduler_inactive():
  File "apps/frappe/frappe/utils/scheduler.py", line 105, in is_scheduler_inactive
    if is_scheduler_disabled():
  File "apps/frappe/frappe/utils/scheduler.py", line 115, in is_scheduler_disabled
    return not frappe.utils.cint(frappe.db.get_single_value("System Settings", "enable_scheduler"))
  File "apps/frappe/frappe/database/database.py", line 684, in get_single_value
    val = self.sql(
  File "apps/frappe/frappe/database/database.py", line 161, in sql
    self.connect()
  File "apps/frappe/frappe/database/database.py", line 85, in connect
    self._conn = self.get_connection()
  File "apps/frappe/frappe/database/mariadb/database.py", line 92, in get_connection
    conn.select_db(self.user)
  File "env/lib/python3.8/site-packages/pymysql/connections.py", line 496, in select_db
    self._read_ok_packet()
  File "env/lib/python3.8/site-packages/pymysql/connections.py", line 443, in _read_ok_packet
    pkt = self._read_packet()
  File "env/lib/python3.8/site-packages/pymysql/connections.py", line 725, in _read_packet
    packet.raise_for_error()
  File "env/lib/python3.8/site-packages/pymysql/protocol.py", line 221, in raise_for_error
    err.raise_mysql_exception(self._data)
  File "env/lib/python3.8/site-packages/pymysql/err.py", line 143, in raise_mysql_exception
    raise errorclass(errno, errval)
pymysql.err.OperationalError: (1049, "Unknown database '_c296b757cb15d301'")

2023-05-20 10:54:34,426 ERROR scheduler Exception in Enqueue Events for Site MyTrialERP.com
Traceback (most recent call last):
  File "apps/frappe/frappe/utils/scheduler.py", line 70, in enqueue_events_for_site
    if is_scheduler_inactive():
  File "apps/frappe/frappe/utils/scheduler.py", line 105, in is_scheduler_inactive
    if is_scheduler_disabled():
  File "apps/frappe/frappe/utils/scheduler.py", line 115, in is_scheduler_disabled
    return not frappe.utils.cint(frappe.db.get_single_value("System Settings", "enable_scheduler"))
  File "apps/frappe/frappe/database/database.py", line 684, in get_single_value
    val = self.sql(
  File "apps/frappe/frappe/database/database.py", line 161, in sql
    self.connect()
  File "apps/frappe/frappe/database/database.py", line 85, in connect
    self._conn = self.get_connection()
  File "apps/frappe/frappe/database/mariadb/database.py", line 92, in get_connection
    conn.select_db(self.user)
  File "env/lib/python3.8/site-packages/pymysql/connections.py", line 496, in select_db
    self._read_ok_packet()
  File "env/lib/python3.8/site-packages/pymysql/connections.py", line 443, in _read_ok_packet
    pkt = self._read_packet()
  File "env/lib/python3.8/site-packages/pymysql/connections.py", line 725, in _read_packet
    packet.raise_for_error()
  File "env/lib/python3.8/site-packages/pymysql/protocol.py", line 221, in raise_for_error
    err.raise_mysql_exception(self._data)
  File "env/lib/python3.8/site-packages/pymysql/err.py", line 143, in raise_mysql_exception
    raise errorclass(errno, errval)
pymysql.err.OperationalError: (1049, "Unknown database '_c296b757cb15d301'")

2023-05-20 10:55:34,690 ERROR scheduler Exception in Enqueue Events for Site MyTrialERP.com
Traceback (most recent call last):
  File "apps/frappe/frappe/utils/scheduler.py", line 70, in enqueue_events_for_site
    if is_scheduler_inactive():
  File "apps/frappe/frappe/utils/scheduler.py", line 105, in is_scheduler_inactive
    if is_scheduler_disabled():
  File "apps/frappe/frappe/utils/scheduler.py", line 115, in is_scheduler_disabled
    return not frappe.utils.cint(frappe.db.get_single_value("System Settings", "enable_scheduler"))
  File "apps/frappe/frappe/database/database.py", line 684, in get_single_value
    val = self.sql(
  File "apps/frappe/frappe/database/database.py", line 161, in sql
    self.connect()
  File "apps/frappe/frappe/database/database.py", line 85, in connect
    self._conn = self.get_connection()
  File "apps/frappe/frappe/database/mariadb/database.py", line 92, in get_connection
    conn.select_db(self.user)
  File "env/lib/python3.8/site-packages/pymysql/connections.py", line 496, in select_db
    self._read_ok_packet()
  File "env/lib/python3.8/site-packages/pymysql/connections.py", line 443, in _read_ok_packet
    pkt = self._read_packet()
  File "env/lib/python3.8/site-packages/pymysql/connections.py", line 725, in _read_packet
    packet.raise_for_error()
  File "env/lib/python3.8/site-packages/pymysql/protocol.py", line 221, in raise_for_error
    err.raise_mysql_exception(self._data)
  File "env/lib/python3.8/site-packages/pymysql/err.py", line 143, in raise_mysql_exception
    raise errorclass(errno, errval)
pymysql.err.OperationalError: (1049, "Unknown database '_c296b757cb15d301'")

2023-05-20 10:56:34,963 ERROR scheduler Exception in Enqueue Events for Site MyTrialERP.com
Traceback (most recent call last):
  File "apps/frappe/frappe/utils/scheduler.py", line 70, in enqueue_events_for_site
    if is_scheduler_inactive():
  File "apps/frappe/frappe/utils/scheduler.py", line 105, in is_scheduler_inactive
    if is_scheduler_disabled():
  File "apps/frappe/frappe/utils/scheduler.py", line 115, in is_scheduler_disabled
    return not frappe.utils.cint(frappe.db.get_single_value("System Settings", "enable_scheduler"))
  File "apps/frappe/frappe/database/database.py", line 684, in get_single_value
    val = self.sql(
  File "apps/frappe/frappe/database/database.py", line 161, in sql
    self.connect()
  File "apps/frappe/frappe/database/database.py", line 85, in connect
    self._conn = self.get_connection()
  File "apps/frappe/frappe/database/mariadb/database.py", line 92, in get_connection
    conn.select_db(self.user)
  File "env/lib/python3.8/site-packages/pymysql/connections.py", line 496, in select_db
    self._read_ok_packet()
  File "env/lib/python3.8/site-packages/pymysql/connections.py", line 443, in _read_ok_packet
    pkt = self._read_packet()
  File "env/lib/python3.8/site-packages/pymysql/connections.py", line 725, in _read_packet
    packet.raise_for_error()
  File "env/lib/python3.8/site-packages/pymysql/protocol.py", line 221, in raise_for_error
    err.raise_mysql_exception(self._data)
  File "env/lib/python3.8/site-packages/pymysql/err.py", line 143, in raise_mysql_exception
    raise errorclass(errno, errval)
pymysql.err.OperationalError: (1049, "Unknown database '_c296b757cb15d301'")

2023-05-20 10:57:35,365 ERROR scheduler Exception in Enqueue Events for Site MyTrialERP.com
Traceback (most recent call last):
  File "apps/frappe/frappe/utils/scheduler.py", line 70, in enqueue_events_for_site
    if is_scheduler_inactive():
  File "apps/frappe/frappe/utils/scheduler.py", line 105, in is_scheduler_inactive
    if is_scheduler_disabled():
  File "apps/frappe/frappe/utils/scheduler.py", line 115, in is_scheduler_disabled
    return not frappe.utils.cint(frappe.db.get_single_value("System Settings", "enable_scheduler"))
  File "apps/frappe/frappe/database/database.py", line 684, in get_single_value
    val = self.sql(
  File "apps/frappe/frappe/database/database.py", line 161, in sql
    self.connect()
  File "apps/frappe/frappe/database/database.py", line 85, in connect
    self._conn = self.get_connection()
  File "apps/frappe/frappe/database/mariadb/database.py", line 92, in get_connection
    conn.select_db(self.user)
  File "env/lib/python3.8/site-packages/pymysql/connections.py", line 496, in select_db
    self._read_ok_packet()
  File "env/lib/python3.8/site-packages/pymysql/connections.py", line 443, in _read_ok_packet
    pkt = self._read_packet()
  File "env/lib/python3.8/site-packages/pymysql/connections.py", line 725, in _read_packet
    packet.raise_for_error()
  File "env/lib/python3.8/site-packages/pymysql/protocol.py", line 221, in raise_for_error
    err.raise_mysql_exception(self._data)
  File "env/lib/python3.8/site-packages/pymysql/err.py", line 143, in raise_mysql_exception
    raise errorclass(errno, errval)
pymysql.err.OperationalError: (1049, "Unknown database '_c296b757cb15d301'")

2023-05-20 10:58:35,655 ERROR scheduler Exception in Enqueue Events for Site MyTrialERP.com
Traceback (most recent call last):
  File "apps/frappe/frappe/utils/scheduler.py", line 70, in enqueue_events_for_site
    if is_scheduler_inactive():
  File "apps/frappe/frappe/utils/scheduler.py", line 105, in is_scheduler_inactive
    if is_scheduler_disabled():
  File "apps/frappe/frappe/utils/scheduler.py", line 115, in is_scheduler_disabled
    return not frappe.utils.cint(frappe.db.get_single_value("System Settings", "enable_scheduler"))
  File "apps/frappe/frappe/database/database.py", line 684, in get_single_value
    val = self.sql(
  File "apps/frappe/frappe/database/database.py", line 161, in sql
    self.connect()
  File "apps/frappe/frappe/database/database.py", line 85, in connect
    self._conn = self.get_connection()
  File "apps/frappe/frappe/database/mariadb/database.py", line 92, in get_connection
    conn.select_db(self.user)
  File "env/lib/python3.8/site-packages/pymysql/connections.py", line 496, in select_db
    self._read_ok_packet()
  File "env/lib/python3.8/site-packages/pymysql/connections.py", line 443, in _read_ok_packet
    pkt = self._read_packet()
  File "env/lib/python3.8/site-packages/pymysql/connections.py", line 725, in _read_packet
    packet.raise_for_error()
  File "env/lib/python3.8/site-packages/pymysql/protocol.py", line 221, in raise_for_error
    err.raise_mysql_exception(self._data)
  File "env/lib/python3.8/site-packages/pymysql/err.py", line 143, in raise_mysql_exception
    raise errorclass(errno, errval)
pymysql.err.OperationalError: (1049, "Unknown database '_c296b757cb15d301'")

2023-05-20 10:59:35,970 ERROR scheduler Exception in Enqueue Events for Site MyTrialERP.com
Traceback (most recent call last):
  File "apps/frappe/frappe/utils/scheduler.py", line 70, in enqueue_events_for_site
    if is_scheduler_inactive():
  File "apps/frappe/frappe/utils/scheduler.py", line 105, in is_scheduler_inactive
    if is_scheduler_disabled():
  File "apps/frappe/frappe/utils/scheduler.py", line 115, in is_scheduler_disabled
    return not frappe.utils.cint(frappe.db.get_single_value("System Settings", "enable_scheduler"))
  File "apps/frappe/frappe/database/database.py", line 684, in get_single_value
    val = self.sql(
  File "apps/frappe/frappe/database/database.py", line 161, in sql
    self.connect()
  File "apps/frappe/frappe/database/database.py", line 85, in connect
    self._conn = self.get_connection()
  File "apps/frappe/frappe/database/mariadb/database.py", line 92, in get_connection
    conn.select_db(self.user)
  File "env/lib/python3.8/site-packages/pymysql/connections.py", line 496, in select_db
    self._read_ok_packet()
  File "env/lib/python3.8/site-packages/pymysql/connections.py", line 443, in _read_ok_packet
    pkt = self._read_packet()
  File "env/lib/python3.8/site-packages/pymysql/connections.py", line 725, in _read_packet
    packet.raise_for_error()
  File "env/lib/python3.8/site-packages/pymysql/protocol.py", line 221, in raise_for_error
    err.raise_mysql_exception(self._data)
  File "env/lib/python3.8/site-packages/pymysql/err.py", line 143, in raise_mysql_exception
    raise errorclass(errno, errval)
pymysql.err.OperationalError: (1049, "Unknown database '_c296b757cb15d301'")

2023-05-21 10:31:18,046 ERROR scheduler Exception in Enqueue Events for Site MyTrialERP.com
Traceback (most recent call last):
  File "apps/frappe/frappe/utils/scheduler.py", line 70, in enqueue_events_for_site
    if is_scheduler_inactive():
  File "apps/frappe/frappe/utils/scheduler.py", line 105, in is_scheduler_inactive
    if is_scheduler_disabled():
  File "apps/frappe/frappe/utils/scheduler.py", line 115, in is_scheduler_disabled
    return not frappe.utils.cint(frappe.db.get_single_value("System Settings", "enable_scheduler"))
  File "apps/frappe/frappe/database/database.py", line 684, in get_single_value
    val = self.sql(
  File "apps/frappe/frappe/database/database.py", line 161, in sql
    self.connect()
  File "apps/frappe/frappe/database/database.py", line 85, in connect
    self._conn = self.get_connection()
  File "apps/frappe/frappe/database/mariadb/database.py", line 92, in get_connection
    conn.select_db(self.user)
  File "env/lib/python3.8/site-packages/pymysql/connections.py", line 496, in select_db
    self._read_ok_packet()
  File "env/lib/python3.8/site-packages/pymysql/connections.py", line 443, in _read_ok_packet
    pkt = self._read_packet()
  File "env/lib/python3.8/site-packages/pymysql/connections.py", line 725, in _read_packet
    packet.raise_for_error()
  File "env/lib/python3.8/site-packages/pymysql/protocol.py", line 221, in raise_for_error
    err.raise_mysql_exception(self._data)
  File "env/lib/python3.8/site-packages/pymysql/err.py", line 143, in raise_mysql_exception
    raise errorclass(errno, errval)
pymysql.err.OperationalError: (1049, "Unknown database '_c296b757cb15d301'")

